Workbook
Name A: #REF!,#REF!,#REF!
Name A: #REF!,#REF!,#REF!
Name AAA: #REF!,#REF!,#REF!
Name AAA: #REF!,#REF!,#REF!
Name ALl: #REF!
Name ALl: #REF!
Name CHFL: #REF!
Name CHFL: #REF!
Name DHFL: #REF!
Name DHFL: #REF!
Name FLCODE: #REF!
Name FLCODE: #REF!
Name JHFL: #REF!
Name JHFL: #REF!
Name LHFL: #REF!
Name LHFL: #REF!
Name LOCATION: #REF!
Name LOCATION: #REF!
Name MHFL: #REF!
Name MHFL: #REF!
Name MM: #REF!,#REF!,#REF!,#REF!,#REF!,#REF!,#REF!,#REF!,#REF!,#REF!,#REF!,#REF!,#REF!,#REF!,#REF!,#REF!,#REF!,#REF!,#REF!,#REF!,#REF!,#REF!,#REF!,#REF!,#REF!,#REF!,#REF!,#REF!,#REF!,#REF!
Name MM: #REF!,#REF!,#REF!,#REF!,#REF!,#REF!,#REF!,#REF!,#REF!,#REF!,#REF!,#REF!,#REF!,#REF!,#REF!,#REF!,#REF!,#REF!,#REF!,#REF!,#REF!,#REF!,#REF!,#REF!,#REF!,#REF!,#REF!,#REF!,#REF!,#REF!
Name PHFL: #REF!
Name PHFL: #REF!
Name PLFL: #REF!
Name PLFL: #REF!
Name Slicer_Level1: #N/A
Name Slicer_Material_Type: #N/A
Name Slicer_Material_Type1: #N/A
Name Slicer_Section1: #N/A
Name Slicer_Sub_Element: #N/A
Name Slicer_Sub_Element1: #N/A
Name Slicer_Sub_Section1: #N/A
Name test: #REF!,#REF!,#REF!,#REF!,#REF!,#REF!,#REF!,#REF!,#REF!,#REF!,#REF!,#REF!,#REF!,#REF!,#REF!,#REF!,#REF!,#REF!,#REF!,#REF!,#REF!,#REF!,#REF!,#REF!,#REF!,#REF!,#REF!,#REF!,#REF!,#REF!,#REF!,#REF!,#REF!
Name test: #REF!,#REF!,#REF!,#REF!,#REF!,#REF!,#REF!,#REF!,#REF!,#REF!,#REF!,#REF!,#REF!,#REF!,#REF!,#REF!,#REF!,#REF!,#REF!,#REF!,#REF!,#REF!,#REF!,#REF!,#REF!,#REF!,#REF!,#REF!,#REF!,#REF!,#REF!,#REF!,#REF!

Sheet Cover
B1: TENDER COST SUMMARY
B2: Structure + Architecture + Preliminaries — For Submission to Client — For Approval
B4: Project Name | C4: 10-Storey School Building
B5: Scope | C5: Structure + Architecture + Preliminaries
B6: Client | C6: ( client name )
B7: Location | C7: Phnom Penh, Cambodia
B8: Contractor | C8: ( your company )
B9: Tender Ref. | C9: SCH-COMB-002
B10: Date | C10: ( dd/mm/yyyy )
B12: 1. ELEMENTAL COST SUMMARY
B13: Code | C13: Description | D13: Amount ($) | E13: Remark
B14: A.00 | C14: Early Work | D14: — | E14: Excluded
B15: B.01 | C15: Piling Work | D15: =SUMIF('Raw Data'!$D:$D,"B.01",'Raw Data'!$Z:$Z) -> 105084.37 | E15: Priced
B16: B.03 | C16: Ground Floor / Foundation | D16: =SUMIF('Raw Data'!$D:$D,"B.03",'Raw Data'!$Z:$Z) -> 95210.475 | E16: Priced
B17: B.04 | C17: Super Structure | D17: =SUMIF('Raw Data'!$D:$D,"B.04",'Raw Data'!$Z:$Z) -> 1124399.7 | E17: Priced
B18: C.01 | C18: Exterior Wall & Partition | D18: =SUMIF('Raw Data'!$D:$D,"C.01",'Raw Data'!$Z:$Z) -> 103864.41 | E18: Priced
B19: C.02 | C19: Exterior Wall Finishes | D19: =SUMIF('Raw Data'!$D:$D,"C.02",'Raw Data'!$Z:$Z) -> 97761.364 | E19: Priced
B20: C.04 | C20: Exterior Window & Louver | D20: =SUMIF('Raw Data'!$D:$D,"C.04",'Raw Data'!$Z:$Z) -> 95868.192 | E20: Priced
B21: C.09 | C21: Interior Wall & Partition | D21: =SUMIF('Raw Data'!$D:$D,"C.09",'Raw Data'!$Z:$Z) -> 100365.77 | E21: Priced
B22: C.10 | C22: Interior Door / Windows | D22: =SUMIF('Raw Data'!$D:$D,"C.10",'Raw Data'!$Z:$Z) -> 44984.8 | E22: Priced
B23: D.01 | C23: Interior Wall Finishes | D23: =SUMIF('Raw Data'!$D:$D,"D.01",'Raw Data'!$Z:$Z) -> 139757.64 | E23: Priced
B24: D.02 | C24: Interior Floor Finishes | D24: =SUMIF('Raw Data'!$D:$D,"D.02",'Raw Data'!$Z:$Z) -> 43665.44 | E24: Priced
B25: D.03 | C25: Ceiling Finishes | D25: =SUMIF('Raw Data'!$D:$D,"D.03",'Raw Data'!$Z:$Z) -> 72072 | E25: Priced
B26: E.04 | C26: Signage | D26: =SUMIF('Raw Data'!$D:$D,"E.04",'Raw Data'!$Z:$Z) -> 6600 | E26: Priced
B27: F.00 | C27: MEP Services | D27: — | E27: Excluded
B28: G.00 | C28: External Works | D28: — | E28: Excluded
B29: X.00 | C29: Authority & Insurance | D29: — | E29: Excluded
B30: DIRECT WORKS COST (A) | D30: =D15+D16+D17+D18+D19+D20+D21+D22+D23+D24+D25+D26 -> 2029634.1
B32: 2. COMMERCIAL BUILD-UP TO TENDER PRICE
B33: Item | C33: % (input) | D33: Amount ($)
B34: Direct Works Cost (A) | D34: =D30 -> 2029634.1
B35: Add: Preliminaries & General (Z) | C35: (itemized, 22 items) | D35: =Preliminaries!$F$27 -> 403700
B36: Subtotal | D36: =D34+D35 -> 2433334.1
B37: Add: Head Office Overhead | C37: 0.05 | D37: =D36*C37 -> 121666.71
B38: Add: Risk & Contingency | C38: 0.03 | D38: =D36*C38 -> 73000.024
B39: Add: Profit | C39: 0.08 | D39: =D36*C39 -> 194666.73
B40: Subtotal before VAT | D40: =D36+D37+D38+D39 -> 2822667.6
B41: Add: VAT | C41: 0.1 | D41: =D40*C41 -> 282266.76
B42: TENDER PRICE (USD) | D42: =D40+D41 -> 3104934.3
B43: Amount in words: ____________________________________________________________
...

Sheet BoQ Breakdown
A1: BILL OF QUANTITIES — STRUCTURE + ARCHITECTURE — DETAILED BREAKDOWN
A2: 10-Storey School Building | Phnom Penh, Cambodia | USD ($)
A3: Quantities & amounts roll up live from Raw Data; rates flow from the Price List (70 items).
A5: Item | B5: Description | C5: Unit | D5: Quantity | E5: Labor Rate ($) | F5: Material Rate ($) | G5: Total Rate ($) | H5: Amount ($)
A6: B.01 — PILING WORK
A7: Bored Pile
A8: B.01.01 | B8: Pile Head Cutting up to required level D1000mm | C8: Nos | D8: =SUMIFS('Raw Data'!$Q:$Q,'Raw Data'!$D:$D,"B.01",'Raw Data'!$H:$H,"Bored Pile",'Raw Data'!$J:$J,"Pile Head Cutting up to required level D1000mm") -> 5 | E8: =IFERROR(INDEX('Price List'!$I$5:$I$74,MATCH("Pile Head Cutting up to required level D1000mm|Nos",'Price List'!$O$5:$O$74,0)),0) -> 66 | F8: =IFERROR(INDEX('Price List'!$L$5:$L$74,MATCH("Pile Head Cutting up to required level D1000mm|Nos",'Price List'!$O$5:$O$74,0)),0) -> 0 | G8: =E8+F8 -> 66 | H8: =SUMIFS('Raw Data'!$Z:$Z,'Raw Data'!$D:$D,"B.01",'Raw Data'!$H:$H,"Bored Pile",'Raw Data'!$J:$J,"Pile Head Cutting up to required level D1000mm") -> 330
A9: B.01.02 | B9: Pile Head Cutting up to required level D800mm | C9: Nos | D9: =SUMIFS('Raw Data'!$Q:$Q,'Raw Data'!$D:$D,"B.01",'Raw Data'!$H:$H,"Bored Pile",'Raw Data'!$J:$J,"Pile Head Cutting up to required level D800mm") -> 17 | E9: =IFERROR(INDEX('Price List'!$I$5:$I$74,MATCH("Pile Head Cutting up to required level D800mm|Nos",'Price List'!$O$5:$O$74,0)),0) -> 48 | F9: =IFERROR(INDEX('Price List'!$L$5:$L$74,MATCH("Pile Head Cutting up to required level D800mm|Nos",'Price List'!$O$5:$O$74,0)),0) -> 0 | G9: =E9+F9 -> 48 | H9: =SUMIFS('Raw Data'!$Z:$Z,'Raw Data'!$D:$D,"B.01",'Raw Data'!$H:$H,"Bored Pile",'Raw Data'!$J:$J,"Pile Head Cutting up to required level D800mm") -> 816
A10: B.01.03 | B10: Sonic Logging Test (SLT) | C10: Nos | D10: =SUMIFS('Raw Data'!$Q:$Q,'Raw Data'!$D:$D,"B.01",'Raw Data'!$H:$H,"Bored Pile",'Raw Data'!$J:$J,"Sonic Logging Test (SLT)") -> 22 | E10: =IFERROR(INDEX('Price List'!$I$5:$I$74,MATCH("Sonic Logging Test (SLT)|Nos",'Price List'!$O$5:$O$74,0)),0) -> 0 | F10: =IFERROR(INDEX('Price List'!$L$5:$L$74,MATCH("Sonic Logging Test (SLT)|Nos",'Price List'!$O$5:$O$74,0)),0) -> 55 | G10: =E10+F10 -> 55 | H10: =SUMIFS('Raw Data'!$Z:$Z,'Raw Data'!$D:$D,"B.01",'Raw Data'!$H:$H,"Bored Pile",'Raw Data'!$J:$J,"Sonic Logging Test (SLT)") -> 1210
A11: B.01.04 | B11: Soil Coring for Bored Pile D1000mm, Depth 30m | C11: Nos | D11: =SUMIFS('Raw Data'!$Q:$Q,'Raw Data'!$D:$D,"B.01",'Raw Data'!$H:$H,"Bored Pile",'Raw Data'!$J:$J,"Soil Coring for Bored Pile D1000mm, Depth 30m") -> 5 | E11: =IFERROR(INDEX('Price List'!$I$5:$I$74,MATCH("Soil Coring for Bored Pile D1000mm, Depth 30m|Nos",'Price List'!$O$5:$O$74,0)),0) -> 0 | F11: =IFERROR(INDEX('Price List'!$L$5:$L$74,MATCH("Soil Coring for Bored Pile D1000mm, Depth 30m|Nos",'Price List'!$O$5:$O$74,0)),0) -> 385 | G11: =E11+F11 -> 385 | H11: =SUMIFS('Raw Data'!$Z:$Z,'Raw Data'!$D:$D,"B.01",'Raw Data'!$H:$H,"Bored Pile",'Raw Data'!$J:$J,"Soil Coring for Bored Pile D1000mm, Depth 30m") -> 1925
A12: B.01.05 | B12: Soil Coring for Bored Pile D800mm, Depth 30m | C12: Nos | D12: =SUMIFS('Raw Data'!$Q:$Q,'Raw Data'!$D:$D,"B.01",'Raw Data'!$H:$H,"Bored Pile",'Raw Data'!$J:$J,"Soil Coring for Bored Pile D800mm, Depth 30m") -> 17 | E12: =IFERROR(INDEX('Price List'!$I$5:$I$74,MATCH("Soil Coring for Bored Pile D800mm, Depth 30m|Nos",'Price List'!$O$5:$O$74,0)),0) -> 0 | F12: =IFERROR(INDEX('Price List'!$L$5:$L$74,MATCH("Soil Coring for Bored Pile D800mm, Depth 30m|Nos",'Price List'!$O$5:$O$74,0)),0) -> 330 | G12: =E12+F12 -> 330 | H12: =SUMIFS('Raw Data'!$Z:$Z,'Raw Data'!$D:$D,"B.01",'Raw Data'!$H:$H,"Bored Pile",'Raw Data'!$J:$J,"Soil Coring for Bored Pile D800mm, Depth 30m") -> 5610
A13: B.01.06 | B13: Normal Concrete, 35Mpa (Cylinder), Slump 15+-2.5 | C13: m3 | D13: =SUMIFS('Raw Data'!$Q:$Q,'Raw Data'!$D:$D,"B.01",'Raw Data'!$H:$H,"Bored Pile",'Raw Data'!$J:$J,"Normal Concrete, 35Mpa (Cylinder), Slump 15+-2.5") -> 374.16369 | E13: =IFERROR(INDEX('Price List'!$I$5:$I$74,MATCH("Normal Concrete, 35Mpa (Cylinder), Slump 15+-2.5|m3",'Price List'!$O$5:$O$74,0)),0) -> 9.6 | F13: =IFERROR(INDEX('Price List'!$L$5:$L$74,MATCH("Normal Concrete, 35Mpa (Cylinder), Slump 15+-2.5|m3",'Price List'!$O$5:$O$74,0)),0) -> 109.76 | G13: =E13+F13 -> 119.36 | H13: =SUMIFS('Raw Data'!$Z:$Z,'Raw Data'!$D:$D,"B.01",'Raw Data'!$H:$H,"Bored Pile",'Raw Data'!$J:$J,"Normal Concrete, 35Mpa (Cylinder), Slump 15+-2.5") -> 44660.177
A14: B.01.07 | B14: Deform Bar, DB10(fy=390 Mpa) | C14: kg | D14: =SUMIFS('Raw Data'!$Q:$Q,'Raw Data'!$D:$D,"B.01",'Raw Data'!$H:$H,"Bored Pile",'Raw Data'!$J:$J,"Deform Bar, DB10(fy=390 Mpa)") -> 2553.8864 | E14: =IFERROR(INDEX('Price List'!$I$5:$I$74,MATCH("Deform Bar, DB10(fy=390 Mpa)|kg",'Price List'!$O$5:$O$74,0)),0) -> 0.144 | F14: =IFERROR(INDEX('Price List'!$L$5:$L$74,MATCH("Deform Bar, DB10(fy=390 Mpa)|kg",'Price List'!$O$5:$O$74,0)),0) -> 0.8736 | G14: =E14+F14 -> 1.0176 | H14: =SUMIFS('Raw Data'!$Z:$Z,'Raw Data'!$D:$D,"B.01",'Raw Data'!$H:$H,"Bored Pile",'Raw Data'!$J:$J,"Deform Bar, DB10(fy=390 Mpa)") -> 2598.8348
A15: B.01.08 | B15: Deform Bar, DB25(fy=390 Mpa) | C15: kg | D15: =SUMIFS('Raw Data'!$Q:$Q,'Raw Data'!$D:$D,"B.01",'Raw Data'!$H:$H,"Bored Pile",'Raw Data'!$J:$J,"Deform Bar, DB25(fy=390 Mpa)") -> 33921.812 | E15: =IFERROR(INDEX('Price List'!$I$5:$I$74,MATCH("Deform Bar, DB25(fy=390 Mpa)|kg",'Price List'!$O$5:$O$74,0)),0) -> 0.096 | F15: =IFERROR(INDEX('Price List'!$L$5:$L$74,MATCH("Deform Bar, DB25(fy=390 Mpa)|kg",'Price List'!$O$5:$O$74,0)),0) -> 0.8064 | G15: =E15+F15 -> 0.9024 | H15: =SUMIFS('Raw Data'!$Z:$Z,'Raw Data'!$D:$D,"B.01",'Raw Data'!$H:$H,"Bored Pile",'Raw Data'!$J:$J,"Deform Bar, DB25(fy=390 Mpa)") -> 30611.043
A16: B.01.09 | B16: Steel Tie Wire 1mm (Estimated 4% of Total Rebar Weight) | C16: kg | D16: =SUMIFS('Raw Data'!$Q:$Q,'Raw Data'!$D:$D,"B.01",'Raw Data'!$H:$H,"Bored Pile",'Raw Data'!$J:$J,"Steel Tie Wire 1mm (Estimated 4% of Total Rebar Weight)") -> 1459.0279 | E16: =IFERROR(INDEX('Price List'!$I$5:$I$74,MATCH("Steel Tie Wire 1mm (Estimated 4% of Total Rebar Weight)|kg",'Price List'!$O$5:$O$74,0)),0) -> 0.06 | F16: =IFERROR(INDEX('Price List'!$L$5:$L$74,MATCH("Steel Tie Wire 1mm (Estimated 4% of Total Rebar Weight)|kg",'Price List'!$O$5:$O$74,0)),0) -> 1.344 | G16: =E16+F16 -> 1.404 | H16: =SUMIFS('Raw Data'!$Z:$Z,'Raw Data'!$D:$D,"B.01",'Raw Data'!$H:$H,"Bored Pile",'Raw Data'!$J:$J,"Steel Tie Wire 1mm (Estimated 4% of Total Rebar Weight)") -> 2048.4752
A17: B.01.10 | B17: Steel Round Pipe (D49x2mm) with rush primer and paint | C17: m | D17: =SUMIFS('Raw Data'!$Q:$Q,'Raw Data'!$D:$D,"B.01",'Raw Data'!$H:$H,"Bored Pile",'Raw Data'!$J:$J,"Steel Round Pipe (D49x2mm) with rush primer and paint") -> 2201 | E17: =IFERROR(INDEX('Price List'!$I$5:$I$74,MATCH("Steel Round Pipe (D49x2mm) with rush primer and paint|m",'Price List'!$O$5:$O$74,0)),0) -> 1.8 | F17: =IFERROR(INDEX('Price List'!$L$5:$L$74,MATCH("Steel Round Pipe (D49x2mm) with rush primer and paint|m",'Price List'!$O$5:$O$74,0)),0) -> 5.04 | G17: =E17+F17 -> 6.84 | H17: =SUMIFS('Raw Data'!$Z:$Z,'Raw Data'!$D:$D,"B.01",'Raw Data'!$H:$H,"Bored Pile",'Raw Data'!$J:$J,"Steel Round Pipe (D49x2mm) with rush primer and paint") -> 15054.84
A18: B.01.11 | B18: Rebar Testing as per Specification | C18: Lot | D18: =SUMIFS('Raw Data'!$Q:$Q,'Raw Data'!$D:$D,"B.01",'Raw Data'!$H:$H,"Bored Pile",'Raw Data'!$J:$J,"Rebar Testing as per Specification") -> 1 | E18: =IFERROR(INDEX('Price List'!$I$5:$I$74,MATCH("Rebar Testing as per Specification|Lot",'Price List'!$O$5:$O$74,0)),0) -> 0 | F18: =IFERROR(INDEX('Price List'!$L$5:$L$74,MATCH("Rebar Testing as per Specification|Lot",'Price List'!$O$5:$O$74,0)),0) -> 220 | G18: =E18+F18 -> 220 | H18: =SUMIFS('Raw Data'!$Z:$Z,'Raw Data'!$D:$D,"B.01",'Raw Data'!$H:$H,"Bored Pile",'Raw Data'!$J:$J,"Rebar Testing as per Specification") -> 220
B19: Subtotal — Bored Pile | H19: =SUM(H8:H18) -> 105084.37
B20: SUBTOTAL B.01 | H20: =SUMIFS('Raw Data'!$Z:$Z,'Raw Data'!$D:$D,"B.01") -> 105084.37
A22: B.03 — GROUND FLOOR / FOUNDATION
A23: Pile Cap & Stump
A24: B.03.01 | B24: Soil Excavation | C24: m3 | D24: =SUMIFS('Raw Data'!$Q:$Q,'Raw Data'!$D:$D,"B.03",'Raw Data'!$H:$H,"Pile Cap & Stump",'Raw Data'!$J:$J,"Soil Excavation") -> 1283.17 | E24: =IFERROR(INDEX('Price List'!$I$5:$I$74,MATCH("Soil Excavation|m3",'Price List'!$O$5:$O$74,0)),0) -> 3.6 | F24: =IFERROR(INDEX('Price List'!$L$5:$L$74,MATCH("Soil Excavation|m3",'Price List'!$O$5:$O$74,0)),0) -> 0 | G24: =E24+F24 -> 3.6 | H24: =SUMIFS('Raw Data'!$Z:$Z,'Raw Data'!$D:$D,"B.03",'Raw Data'!$H:$H,"Pile Cap & Stump",'Raw Data'!$J:$J,"Soil Excavation") -> 4619.412
A25: B.03.02 | B25: Soil Disposal | C25: m3 | D25: =SUMIFS('Raw Data'!$Q:$Q,'Raw Data'!$D:$D,"B.03",'Raw Data'!$H:$H,"Pile Cap & Stump",'Raw Data'!$J:$J,"Soil Disposal") -> 1283.17 | E25: =IFERROR(INDEX('Price List'!$I$5:$I$74,MATCH("Soil Disposal|m3",'Price List'!$O$5:$O$74,0)),0) -> 4.8 | F25: =IFERROR(INDEX('Price List'!$L$5:$L$74,MATCH("Soil Disposal|m3",'Price List'!$O$5:$O$74,0)),0) -> 0 | G25: =E25+F25 -> 4.8 | H25: =SUMIFS('Raw Data'!$Z:$Z,'Raw Data'!$D:$D,"B.03",'Raw Data'!$H:$H,"Pile Cap & Stump",'Raw Data'!$J:$J,"Soil Disposal") -> 6159.216
A26: B.03.03 | B26: Soil Backfill | C26: m3 | D26: =SUMIFS('Raw Data'!$Q:$Q,'Raw Data'!$D:$D,"B.03",'Raw Data'!$H:$H,"Pile Cap & Stump",'Raw Data'!$J:$J,"Soil Backfill") -> 1148.424 | E26: =IFERROR(INDEX('Price List'!$I$5:$I$74,MATCH("Soil Backfill|m3",'Price List'!$O$5:$O$74,0)),0) -> 4.8 | F26: =IFERROR(INDEX('Price List'!$L$5:$L$74,MATCH("Soil Backfill|m3",'Price List'!$O$5:$O$74,0)),0) -> 0 | G26: =E26+F26 -> 4.8 | H26: =SUMIFS('Raw Data'!$Z:$Z,'Raw Data'!$D:$D,"B.03",'Raw Data'!$H:$H,"Pile Cap & Stump",'Raw Data'!$J:$J,"Soil Backfill") -> 5512.4352
A27: B.03.04 | B27: Normal Concrete, 35Mpa (Cylinder), Slump 13+-2.5 | C27: m3 | D27: =SUMIFS('Raw Data'!$Q:$Q,'Raw Data'!$D:$D,"B.03",'Raw Data'!$H:$H,"Pile Cap & Stump",'Raw Data'!$J:$J,"Normal Concrete, 35Mpa (Cylinder), Slump 13+-2.5") -> 134.746 | E27: =IFERROR(INDEX('Price List'!$I$5:$I$74,MATCH("Normal Concrete, 35Mpa (Cylinder), Slump 13+-2.5|m3",'Price List'!$O$5:$O$74,0)),0) -> 12 | F27: =IFERROR(INDEX('Price List'!$L$5:$L$74,MATCH("Normal Concrete, 35Mpa (Cylinder), Slump 13+-2.5|m3",'Price List'!$O$5:$O$74,0)),0) -> 109.76 | G27: =E27+F27 -> 121.76 | H27: =SUMIFS('Raw Data'!$Z:$Z,'Raw Data'!$D:$D,"B.03",'Raw Data'!$H:$H,"Pile Cap & Stump",'Raw Data'!$J:$J,"Normal Concrete, 35Mpa (Cylinder), Slump 13+-2.5") -> 16406.673
A28: B.03.05 | B28: Formwork | C28: m2 | D28: =SUMIFS('Raw Data'!$Q:$Q,'Raw Data'!$D:$D,"B.03",'Raw Data'!$H:$H,"Pile Cap & Stump",'Raw Data'!$J:$J,"Formwork") -> 200.935 | E28: =IFERROR(INDEX('Price List'!$I$5:$I$74,MATCH("Formwork|m2",'Price List'!$O$5:$O$74,0)),0) -> 7.2 | F28: =IFERROR(INDEX('Price List'!$L$5:$L$74,MATCH("Formwork|m2",'Price List'!$O$5:$O$74,0)),0) -> 5.6 | G28: =E28+F28 -> 12.8 | H28: =SUMIFS('Raw Data'!$Z:$Z,'Raw Data'!$D:$D,"B.03",'Raw Data'!$H:$H,"Pile Cap & Stump",'Raw Data'!$J:$J,"Formwork") -> 2571.968
A29: B.03.06 | B29: Deform Bar, DB10(fy=390 Mpa) | C29: kg | D29: =SUMIFS('Raw Data'!$Q:$Q,'Raw Data'!$D:$D,"B.03",'Raw Data'!$H:$H,"Pile Cap & Stump",'Raw Data'!$J:$J,"Deform Bar, DB10(fy=390 Mpa)") -> 34.55 | E29: =IFERROR(INDEX('Price List'!$I$5:$I$74,MATCH("Deform Bar, DB10(fy=390 Mpa)|kg",'Price List'!$O$5:$O$74,0)),0) -> 0.144 | F29: =IFERROR(INDEX('Price List'!$L$5:$L$74,MATCH("Deform Bar, DB10(fy=390 Mpa)|kg",'Price List'!$O$5:$O$74,0)),0) -> 0.8736 | G29: =E29+F29 -> 1.0176 | H29: =SUMIFS('Raw Data'!$Z:$Z,'Raw Data'!$D:$D,"B.03",'Raw Data'!$H:$H,"Pile Cap & Stump",'Raw Data'!$J:$J,"Deform Bar, DB10(fy=390 Mpa)") -> 35.15808
A30: B.03.07 | B30: Deform Bar, DB12(fy=390 Mpa) | C30: kg | D30: =SUMIFS('Raw Data'!$Q:$Q,'Raw Data'!$D:$D,"B.03",'Raw Data'!$H:$H,"Pile Cap & Stump",'Raw Data'!$J:$J,"Deform Bar, DB12(fy=390 Mpa)") -> 2639.1376 | E30: =IFERROR(INDEX('Price List'!$I$5:$I$74,MATCH("Deform Bar, DB12(fy=390 Mpa)|kg",'Price List'!$O$5:$O$74,0)),0) -> 0.132 | F30: =IFERROR(INDEX('Price List'!$L$5:$L$74,MATCH("Deform Bar, DB12(fy=390 Mpa)|kg",'Price List'!$O$5:$O$74,0)),0) -> 0.8512 | G30: =E30+F30 -> 0.9832 | H30: =SUMIFS('Raw Data'!$Z:$Z,'Raw Data'!$D:$D,"B.03",'Raw Data'!$H:$H,"Pile Cap & Stump",'Raw Data'!$J:$J,"Deform Bar, DB12(fy=390 Mpa)") -> 2594.8001
A31: B.03.08 | B31: Deform Bar, DB16(fy=390 Mpa) | C31: kg | D31: =SUMIFS('Raw Data'!$Q:$Q,'Raw Data'!$D:$D,"B.03",'Raw Data'!$H:$H,"Pile Cap & Stump",'Raw Data'!$J:$J,"Deform Bar, DB16(fy=390 Mpa)") -> 1372.388 | E31: =IFERROR(INDEX('Price List'!$I$5:$I$74,MATCH("Deform Bar, DB16(fy=390 Mpa)|kg",'Price List'!$O$5:$O$74,0)),0) -> 0.12 | F31: =IFERROR(INDEX('Price List'!$L$5:$L$74,MATCH("Deform Bar, DB16(fy=390 Mpa)|kg",'Price List'!$O$5:$O$74,0)),0) -> 0.8288 | G31: =E31+F31 -> 0.9488 | H31: =SUMIFS('Raw Data'!$Z:$Z,'Raw Data'!$D:$D,"B.03",'Raw Data'!$H:$H,"Pile Cap & Stump",'Raw Data'!$J:$J,"Deform Bar, DB16(fy=390 Mpa)") -> 1302.1217
A32: B.03.09 | B32: Deform Bar, DB20(fy=390 Mpa) | C32: kg | D32: =SUMIFS('Raw Data'!$Q:$Q,'Raw Data'!$D:$D,"B.03",'Raw Data'!$H:$H,"Pile Cap & Stump",'Raw Data'!$J:$J,"Deform Bar, DB20(fy=390 Mpa)") -> 11795.979 | E32: =IFERROR(INDEX('Price List'!$I$5:$I$74,MATCH("Deform Bar, DB20(fy=390 Mpa)|kg",'Price List'!$O$5:$O$74,0)),0) -> 0.108 | F32: =IFERROR(INDEX('Price List'!$L$5:$L$74,MATCH("Deform Bar, DB20(fy=390 Mpa)|kg",'Price List'!$O$5:$O$74,0)),0) -> 0.8176 | G32: =E32+F32 -> 0.9256 | H32: =SUMIFS('Raw Data'!$Z:$Z,'Raw Data'!$D:$D,"B.03",'Raw Data'!$H:$H,"Pile Cap & Stump",'Raw Data'!$J:$J,"Deform Bar, DB20(fy=390 Mpa)") -> 10918.358
A33: B.03.10 | B33: Deform Bar, DB25(fy=390 Mpa) | C33: kg | D33: =SUMIFS('Raw Data'!$Q:$Q,'Raw Data'!$D:$D,"B.03",'Raw Data'!$H:$H,"Pile Cap & Stump",'Raw Data'!$J:$J,"Deform Bar, DB25(fy=390 Mpa)") -> 1694 | E33: =IFERROR(INDEX('Price List'!$I$5:$I$74,MATCH("Deform Bar, DB25(fy=390 Mpa)|kg",'Price List'!$O$5:$O$74,0)),0) -> 0.096 | F33: =IFERROR(INDEX('Price List'!$L$5:$L$74,MATCH("Deform Bar, DB25(fy=390 Mpa)|kg",'Price List'!$O$5:$O$74,0)),0) -> 0.8064 | G33: =E33+F33 -> 0.9024 | H33: =SUMIFS('Raw Data'!$Z:$Z,'Raw Data'!$D:$D,"B.03",'Raw Data'!$H:$H,"Pile Cap & Stump",'Raw Data'!$J:$J,"Deform Bar, DB25(fy=390 Mpa)") -> 1528.6656
A34: B.03.11 | B34: Deform Bar, DB32(fy=390 Mpa) | C34: kg | D34: =SUMIFS('Raw Data'!$Q:$Q,'Raw Data'!$D:$D,"B.03",'Raw Data'!$H:$H,"Pile Cap & Stump",'Raw Data'!$J:$J,"Deform Bar, DB32(fy=390 Mpa)") -> 10611.798 | E34: =IFERROR(INDEX('Price List'!$I$5:$I$74,MATCH("Deform Bar, DB32(fy=390 Mpa)|kg",'Price List'!$O$5:$O$74,0)),0) -> 0.096 | F34: =IFERROR(INDEX('Price List'!$L$5:$L$74,MATCH("Deform Bar, DB32(fy=390 Mpa)|kg",'Price List'!$O$5:$O$74,0)),0) -> 0.7952 | G34: =E34+F34 -> 0.8912 | H34: =SUMIFS('Raw Data'!$Z:$Z,'Raw Data'!$D:$D,"B.03",'Raw Data'!$H:$H,"Pile Cap & Stump",'Raw Data'!$J:$J,"Deform Bar, DB32(fy=390 Mpa)") -> 9457.2344
A35: B.03.12 | B35: Steel Tie Wire 1mm (Estimated 4% of Total Rebar Weight) | C35: kg | D35: =SUMIFS('Raw Data'!$Q:$Q,'Raw Data'!$D:$D,"B.03",'Raw Data'!$H:$H,"Pile Cap & Stump",'Raw Data'!$J:$J,"Steel Tie Wire 1mm (Estimated 4% of Total Rebar Weight)") -> 1069.6366 | E35: =IFERROR(INDEX('Price List'!$I$5:$I$74,MATCH("Steel Tie Wire 1mm (Estimated 4% of Total Rebar Weight)|kg",'Price List'!$O$5:$O$74,0)),0) -> 0.06 | F35: =IFERROR(INDEX('Price List'!$L$5:$L$74,MATCH("Steel Tie Wire 1mm (Estimated 4% of Total Rebar Weight)|kg",'Price List'!$O$5:$O$74,0)),0) -> 1.344 | G35: =E35+F35 -> 1.404 | H35: =SUMIFS('Raw Data'!$Z:$Z,'Raw Data'!$D:$D,"B.03",'Raw Data'!$H:$H,"Pile Cap & Stump",'Raw Data'!$J:$J,"Steel Tie Wire 1mm (Estimated 4% of Total Rebar Weight)") -> 1501.7698
A36: B.03.13 | B36: Well Soil Compact | C36: m2 | D36: =SUMIFS('Raw Data'!$Q:$Q,'Raw Data'!$D:$D,"B.03",'Raw Data'!$H:$H,"Pile Cap & Stump",'Raw Data'!$J:$J,"Well Soil Compact") -> 131.43 | E36: =IFERROR(INDEX('Price List'!$I$5:$I$74,MATCH("Well Soil Compact|m2",'Price List'!$O$5:$O$74,0)),0) -> 2.4 | F36: =IFERROR(INDEX('Price List'!$L$5:$L$74,MATCH("Well Soil Compact|m2",'Price List'!$O$5:$O$74,0)),0) -> 0 | G36: =E36+F36 -> 2.4 | H36: =SUMIFS('Raw Data'!$Z:$Z,'Raw Data'!$D:$D,"B.03",'Raw Data'!$H:$H,"Pile Cap & Stump",'Raw Data'!$J:$J,"Well Soil Compact") -> 315.432
A37: B.03.14 | B37: Lean Concrete, 15Mpa (Cylinder) | C37: m3 | D37: =SUMIFS('Raw Data'!$Q:$Q,'Raw Data'!$D:$D,"B.03",'Raw Data'!$H:$H,"Pile Cap & Stump",'Raw Data'!$J:$J,"Lean Concrete, 15Mpa (Cylinder)") -> 14.8565 | E37: =IFERROR(INDEX('Price List'!$I$5:$I$74,MATCH("Lean Concrete, 15Mpa (Cylinder)|m3",'Price List'!$O$5:$O$74,0)),0) -> 8.4 | F37: =IFERROR(INDEX('Price List'!$L$5:$L$74,MATCH("Lean Concrete, 15Mpa (Cylinder)|m3",'Price List'!$O$5:$O$74,0)),0) -> 84 | G37: =E37+F37 -> 92.4 | H37: =SUMIFS('Raw Data'!$Z:$Z,'Raw Data'!$D:$D,"B.03",'Raw Data'!$H:$H,"Pile Cap & Stump",'Raw Data'!$J:$J,"Lean Concrete, 15Mpa (Cylinder)") -> 1372.7406
A38: B.03.15 | B38: PVC Waterbar® V VN 20 (Width 200mm) | C38: m | D38: =SUMIFS('Raw Data'!$Q:$Q,'Raw Data'!$D:$D,"B.03",'Raw Data'!$H:$H,"Pile Cap & Stump",'Raw Data'!$J:$J,"PVC Waterbar® V VN 20 (Width 200mm)") -> 18 | E38: =IFERROR(INDEX('Price List'!$I$5:$I$74,MATCH("PVC Waterbar® V VN 20 (Width 200mm)|m",'Price List'!$O$5:$O$74,0)),0) -> 1.8 | F38: =IFERROR(INDEX('Price List'!$L$5:$L$74,MATCH("PVC Waterbar® V VN 20 (Width 200mm)|m",'Price List'!$O$5:$O$74,0)),0) -> 4.48 | G38: =E38+F38 -> 6.28 | H38: =SUMIFS('Raw Data'!$Z:$Z,'Raw Data'!$D:$D,"B.03",'Raw Data'!$H:$H,"Pile Cap & Stump",'Raw Data'!$J:$J,"PVC Waterbar® V VN 20 (Width 200mm)") -> 113.04
A39: B.03.16 | B39: Membrance sheet 2mm thk | C39: m2 | D39: =SUMIFS('Raw Data'!$Q:$Q,'Raw Data'!$D:$D,"B.03",'Raw Data'!$H:$H,"Pile Cap & Stump",'Raw Data'!$J:$J,"Membrance sheet 2mm thk") -> 7.2695 | E39: =IFERROR(INDEX('Price List'!$I$5:$I$74,MATCH("Membrance sheet 2mm thk|m2",'Price List'!$O$5:$O$74,0)),0) -> 2.4 | F39: =IFERROR(INDEX('Price List'!$L$5:$L$74,MATCH("Membrance sheet 2mm thk|m2",'Price List'!$O$5:$O$74,0)),0) -> 7.28 | G39: =E39+F39 -> 9.68 | H39: =SUMIFS('Raw Data'!$Z:$Z,'Raw Data'!$D:$D,"B.03",'Raw Data'!$H:$H,"Pile Cap & Stump",'Raw Data'!$J:$J,"Membrance sheet 2mm thk") -> 70.36876
B40: Subtotal — Pile Cap & Stump | H40: =SUM(H24:H39) -> 64479.393
A41: Septic tank
A42: B.03.17 | B42: Soil Excavation | C42: m3 | D42: =SUMIFS('Raw Data'!$Q:$Q,'Raw Data'!$D:$D,"B.03",'Raw Data'!$H:$H,"Septic tank",'Raw Data'!$J:$J,"Soil Excavation") -> 288 | E42: =IFERROR(INDEX('Price List'!$I$5:$I$74,MATCH("Soil Excavation|m3",'Price List'!$O$5:$O$74,0)),0) -> 3.6 | F42: =IFERROR(INDEX('Price List'!$L$5:$L$74,MATCH("Soil Excavation|m3",'Price List'!$O$5:$O$74,0)),0) -> 0 | G42: =E42+F42 -> 3.6 | H42: =SUMIFS('Raw Data'!$Z:$Z,'Raw Data'!$D:$D,"B.03",'Raw Data'!$H:$H,"Septic tank",'Raw Data'!$J:$J,"Soil Excavation") -> 1036.8
...

Sheet Project Budget
B1: PROJECT BUDGET & PROFIT PLAN
B2: INTERNAL DOCUMENT — FOR COST MANAGEMENT ONLY — NOT FOR CLIENT ISSUE
B3: 10-Storey School Building | Phnom Penh, Cambodia | USD ($) | Linked live to Raw Data, Price List, Preliminaries & Cover
B5: 1. COST PLAN BY ELEMENT (Original Budget vs Selling)
B6: Code | C6: Element | D6: Cost Budget (Net) ($) | E6: Selling / BoQ ($) | F6: Embedded Margin ($) | G6: Margin %
B7: B.01 | C7: Piling Work | D7: =SUMPRODUCT(('Raw Data'!$D$2:$D$832=$B7)*'Raw Data'!$Q$2:$Q$832*('Raw Data'!$T$2:$T$832+'Raw Data'!$W$2:$W$832)) -> 93232.083 | E7: =SUMIF('Raw Data'!$D:$D,$B7,'Raw Data'!$Z:$Z) -> 105084.37 | F7: =E7-D7 -> 11852.288 | G7: =IF(E7=0,0,F7/E7) -> 0.1127883
B8: B.03 | C8: Ground Floor / Foundation | D8: =SUMPRODUCT(('Raw Data'!$D$2:$D$832=$B8)*'Raw Data'!$Q$2:$Q$832*('Raw Data'!$T$2:$T$832+'Raw Data'!$W$2:$W$832)) -> 83049.542 | E8: =SUMIF('Raw Data'!$D:$D,$B8,'Raw Data'!$Z:$Z) -> 95210.475 | F8: =E8-D8 -> 12160.933 | G8: =IF(E8=0,0,F8/E8) -> 0.12772683
B9: B.04 | C9: Super Structure | D9: =SUMPRODUCT(('Raw Data'!$D$2:$D$832=$B9)*'Raw Data'!$Q$2:$Q$832*('Raw Data'!$T$2:$T$832+'Raw Data'!$W$2:$W$832)) -> 989807.64 | E9: =SUMIF('Raw Data'!$D:$D,$B9,'Raw Data'!$Z:$Z) -> 1124399.7 | F9: =E9-D9 -> 134592.02 | G9: =IF(E9=0,0,F9/E9) -> 0.11970123
B10: C.01 | C10: Exterior Wall & Partition | D10: =SUMPRODUCT(('Raw Data'!$D$2:$D$832=$B10)*'Raw Data'!$Q$2:$Q$832*('Raw Data'!$T$2:$T$832+'Raw Data'!$W$2:$W$832)) -> 90902.306 | E10: =SUMIF('Raw Data'!$D:$D,$B10,'Raw Data'!$Z:$Z) -> 103864.41 | F10: =E10-D10 -> 12962.104 | G10: =IF(E10=0,0,F10/E10) -> 0.12479832
B11: C.02 | C11: Exterior Wall Finishes | D11: =SUMPRODUCT(('Raw Data'!$D$2:$D$832=$B11)*'Raw Data'!$Q$2:$Q$832*('Raw Data'!$T$2:$T$832+'Raw Data'!$W$2:$W$832)) -> 84448.333 | E11: =SUMIF('Raw Data'!$D:$D,$B11,'Raw Data'!$Z:$Z) -> 97761.364 | F11: =E11-D11 -> 13313.031 | G11: =IF(E11=0,0,F11/E11) -> 0.13617886
B12: C.04 | C12: Exterior Window & Louver | D12: =SUMPRODUCT(('Raw Data'!$D$2:$D$832=$B12)*'Raw Data'!$Q$2:$Q$832*('Raw Data'!$T$2:$T$832+'Raw Data'!$W$2:$W$832)) -> 85596.6 | E12: =SUMIF('Raw Data'!$D:$D,$B12,'Raw Data'!$Z:$Z) -> 95868.192 | F12: =E12-D12 -> 10271.592 | G12: =IF(E12=0,0,F12/E12) -> 0.10714286
B13: C.09 | C13: Interior Wall & Partition | D13: =SUMPRODUCT(('Raw Data'!$D$2:$D$832=$B13)*'Raw Data'!$Q$2:$Q$832*('Raw Data'!$T$2:$T$832+'Raw Data'!$W$2:$W$832)) -> 87764.899 | E13: =SUMIF('Raw Data'!$D:$D,$B13,'Raw Data'!$Z:$Z) -> 100365.77 | F13: =E13-D13 -> 12600.871 | G13: =IF(E13=0,0,F13/E13) -> 0.12554949
B14: C.10 | C14: Interior Door / Windows | D14: =SUMPRODUCT(('Raw Data'!$D$2:$D$832=$B14)*'Raw Data'!$Q$2:$Q$832*('Raw Data'!$T$2:$T$832+'Raw Data'!$W$2:$W$832)) -> 40165 | E14: =SUMIF('Raw Data'!$D:$D,$B14,'Raw Data'!$Z:$Z) -> 44984.8 | F14: =E14-D14 -> 4819.8 | G14: =IF(E14=0,0,F14/E14) -> 0.10714286
B15: D.01 | C15: Interior Wall Finishes | D15: =SUMPRODUCT(('Raw Data'!$D$2:$D$832=$B15)*'Raw Data'!$Q$2:$Q$832*('Raw Data'!$T$2:$T$832+'Raw Data'!$W$2:$W$832)) -> 120957.16 | E15: =SUMIF('Raw Data'!$D:$D,$B15,'Raw Data'!$Z:$Z) -> 139757.64 | F15: =E15-D15 -> 18800.473 | G15: =IF(E15=0,0,F15/E15) -> 0.13452198
B16: D.02 | C16: Interior Floor Finishes | D16: =SUMPRODUCT(('Raw Data'!$D$2:$D$832=$B16)*'Raw Data'!$Q$2:$Q$832*('Raw Data'!$T$2:$T$832+'Raw Data'!$W$2:$W$832)) -> 38545 | E16: =SUMIF('Raw Data'!$D:$D,$B16,'Raw Data'!$Z:$Z) -> 43665.44 | F16: =E16-D16 -> 5120.44 | G16: =IF(E16=0,0,F16/E16) -> 0.11726528
B17: D.03 | C17: Ceiling Finishes | D17: =SUMPRODUCT(('Raw Data'!$D$2:$D$832=$B17)*'Raw Data'!$Q$2:$Q$832*('Raw Data'!$T$2:$T$832+'Raw Data'!$W$2:$W$832)) -> 63000 | E17: =SUMIF('Raw Data'!$D:$D,$B17,'Raw Data'!$Z:$Z) -> 72072 | F17: =E17-D17 -> 9072 | G17: =IF(E17=0,0,F17/E17) -> 0.12587413
B18: E.04 | C18: Signage | D18: =SUMPRODUCT(('Raw Data'!$D$2:$D$832=$B18)*'Raw Data'!$Q$2:$Q$832*('Raw Data'!$T$2:$T$832+'Raw Data'!$W$2:$W$832)) -> 6000 | E18: =SUMIF('Raw Data'!$D:$D,$B18,'Raw Data'!$Z:$Z) -> 6600 | F18: =E18-D18 -> 600 | G18: =IF(E18=0,0,F18/E18) -> 0.090909091
C19: DIRECT WORKS TOTAL | D19: =SUM(D7:D18) -> 1783468.6 | E19: =SUM(E7:E18) -> 2029634.1 | F19: =E19-D19 -> 246165.55 | G19: =IF(E19=0,0,F19/E19) -> 0.12128568
B20: Z | C20: Preliminaries & General (at cost) | D20: =Preliminaries!$F$27 -> 403700 | E20: =Preliminaries!$F$27 -> 403700 | F20: 0 | G20: 0
B22: 2. PROJECT TOTALS & PROFIT PLAN
B23: CONTRACT VALUE — Tender Price (incl. VAT) | E23: =Cover!$D$42 -> 3104934.3
B24: less: VAT payable to tax authority (pass-through) | E24: =-Cover!$D$41 -> -282266.76
B25: REVENUE (excl. VAT) | E25: =Cover!$D$40 -> 2822667.6
B26: ORIGINAL COST BUDGET (what the project should cost):
B27: Direct works at net cost (labor + material, no margin) | E27: =D19 -> 1783468.6
B28: Preliminaries at cost | E28: =D20 -> 403700
B29: Head office overhead (real cost, per Cover %) | E29: =Cover!$D$37 -> 121666.71
B30: TOTAL ORIGINAL BUDGET | E30: =E27+E28+E29 -> 2308835.3
B31: PROFIT PLAN (where the margin lives):
B32: Embedded margin inside unit rates | E32: =F19 -> 246165.55
B33: Explicit profit line on Cover | E33: =Cover!$D$39 -> 194666.73
B34: Risk & contingency (becomes profit only if unused) | E34: =Cover!$D$38 -> 73000.024
B35: PLANNED GROSS PROFIT (if risk unused) | E35: =E25-E30 -> 513832.31 | F35: =E35/E25 -> 0.18203784
B36: TARGET GROSS PROFIT (risk held in reserve) | E36: =E35-E34 -> 440832.28 | F36: =E36/E25 -> 0.15617577
B38: Check: Revenue − Budget − Embedded − Profit − Risk = $0 → | F38: =E25-E30-E32-E33-E34 -> -6.4028427e-10
B40: 3. HOW TO USE THIS SHEET FOR COST CONTROL
B41: 1. The "Cost Budget (Net)" column is your baseline: every purchase order and subcontract for an element is tracked against it.
B42: 2. Each month, record Committed Cost (orders placed) and Actual Cost (invoices) per code vs this budget — overrun on any code eats the embedded margin first, then profit.
B43: 3. Risk & Contingency is NOT profit yet: hold it against variations, rework and escalation; release to profit only at final account.
B44: 4. VAT is collected from the client and paid to GDT — never count it as project money.
...

Sheet Floor Code (2)
A1: Floor Code
A2: Building Code | B2: Sequence Number | C2: Level Code on Design | D2: Floor Code
A3: BA | B3: 01 | C3: U01 | D3: =CONCATENATE(A3,"-",B3,"-",C3) -> BA-01-U01
A4: BA | B4: 02 | C4: B02 | D4: =CONCATENATE(A4,"-",B4,"-",C4) -> BA-02-B02
A5: BA | B5: 03 | C5: B01 | D5: =CONCATENATE(A5,"-",B5,"-",C5) -> BA-03-B01
A6: BA | B6: 04 | C6: L00 | D6: =CONCATENATE(A6,"-",B6,"-",C6) -> BA-04-L00
A7: BA | B7: 05 | C7: L01 | D7: =CONCATENATE(A7,"-",B7,"-",C7) -> BA-05-L01
A8: BA | B8: 06 | C8: L02 | D8: =CONCATENATE(A8,"-",B8,"-",C8) -> BA-06-L02
A9: BA | B9: 07 | C9: L03 | D9: =CONCATENATE(A9,"-",B9,"-",C9) -> BA-07-L03
A10: BA | B10: 08 | C10: L04 | D10: =CONCATENATE(A10,"-",B10,"-",C10) -> BA-08-L04
A11: BA | B11: 09 | C11: L05 | D11: =CONCATENATE(A11,"-",B11,"-",C11) -> BA-09-L05

Sheet Floor Code
A1: Floor Naming
A2: Building Name | B2: Level | C2: Level Function | D2: CFA (m2) | E2: Building Code | F2: Sequence Number | G2: Level Code | H2: Floor Code

Sheet CS BoQ Level
A1: Civil and Structure Level Breakdown
A2: Discipline | B2: Section | C2: Sub Section | D2: Material Type | E2: Unit
A3: Civil and Structure | B3: Foundation | C3: Pile | D3: D1000 Concrete Grade C30/37 | E3: m
D4: D400 Concrete Grade C30/37 | E4: m
D5: D600 Concrete Grade C30/37 | E5: m
D6: D800 Concrete Grade C30/37 | E6: m
C7: Pile Caps | D7: Anti-Termite | E7: m2
D8: Concrete Grade C40/50 | E8: m3
D9: Rebar DB10 SD390 | E9: kg
D10: Rebar DB12 SD390 | E10: kg
D11: Rebar DB16 SD390 | E11: kg
D12: Rebar DB20 SD390 | E12: kg
D13: Rebar DB25 SD390 | E13: kg
D14: Rebar DB8 SD235 | E14: kg
D15: Excavation | E15: m3
D16: Gravel 4x6cm Compaction 100mm thk. & Concrete Grade C25/30 50mm thk. | E16: m3
D17: Plywood Formwork | E17: m2
C18: Temperary Protection | D18: H-Beam(400x400x13x21)mm, SD365 | E18: kg
D19: Steel sheet piles (6x0.75)m | E19: m
B20: Sub Structure | C20: Sewage Treatment Plant (STP) | D20: Normal Concrete, C35/45 Mpa | E20: m3
D21: Rebar DB10 SD390 | E21: kg
D22: Gravel 4x6cm Compaction 100mm thk. & Concrete Grade C25/30 50mm thk. | E22: m3
D23: Plywood Formwork | E23: m2
C24: Retaining Wall | D24: Concrete Grade C40/50 | E24: m3
D25: Rebar DB10 SD390 | E25: kg
D26: Rebar DB20 SD390 | E26: kg
D27: Rebar DB25 SD390 | E27: kg
D28: Rebar DB8 SD235 | E28: kg
D29: Plywood Formwork | E29: m2
D30: Sika Waterbar | E30: m
C31: Water Tank | D31: Concrete Grade C35/45 | E31: m3
D32: Rebar DB12 SD390 | E32: kg
D33: Plywood Formwork | E33: m2
B34: Super Structure | C34: Beam | D34: Concrete Grade C40/50 | E34: m3
D35: Rebar DB10 SD390 | E35: kg
D36: Rebar DB12 SD390 | E36: kg
D37: Rebar DB16 SD390 | E37: kg
D38: Rebar DB20 SD390 | E38: kg
D39: Rebar DB25 SD390 | E39: kg
D40: Rebar DB8 SD235 | E40: kg
...

Sheet RFQ_Rawdata
A1: Design Data | F1: RFQ DATA | N1: Remark
A2: Sub Section | B2: Sub Element | C2: Material Type | D2: Unit | E2: Designated Brand | F2: Supplier ID | G2: Proposed Brand | H2: Specification | I2: Labor Rate | J2: Material Rate | K2: RQF No | L2: Submit by | M2: Submit Date
A3: Bored Pile | B3: Preliminary Works | C3: Mobilization and Demobilization | D3: lot | I3: 13000 | J3: 0
A4: Bored Pile | B4: Preliminary Works | C4: Management fee and field engineer | D4: lot | I4: 28000 | J4: 0
A5: Bored Pile | B5: Preliminary Works | C5: Survey and setting out & As-Built drawing | D5: lot | I5: 3470 | J5: 0
A6: Bored Pile | B6: Preliminary Works | C6: Casing length 6m and Steel plate | D6: lot
A7: Bored Pile | B7: Coring Works | C7: Bentonite | D7: lot
A8: Bored Pile | B8: Coring Works | C8: Rock Coring for Bored Pile D1500mm | D8: m | I8: 260 | J8: 0
A9: Bored Pile | B9: Coring Works | C9: Soil Coring for Bored Pile D1500mm | D9: m | I9: 60 | J9: 0
A10: Bored Pile | B10: Concrete | C10: Normal Concrete, C35/45 Mpa | D10: m3 | I10: 16 | J10: 63
A11: Bored Pile | B11: Rebar | C11: Deform Bar, DB10 SD500 Mpa | D11: kg | I11: 0.07 | J11: 0.78
A12: Bored Pile | B12: Rebar | C12: Deform Bar, DB16 SD500 Mpa | D12: kg | I12: 0.07 | J12: 0.78
A13: Bored Pile | B13: Rebar | C13: Deform Bar, DB20 SD500 Mpa | D13: kg | I13: 0.07 | J13: 0.78
A14: Bored Pile | B14: Steel Wire | C14: Steel Tie Wire 1mm | D14: kg | I14: 0.12 | J14: 0.908
A15: Bored Pile | B15: Steel Tube | C15: Steel Tube D49x1.9mm with Anti rust and black paint finish | D15: m | I15: 3.7 | J15: 0
A16: Bored Pile | B16: Grouting works | C16: Grouting works after sonic logging test | D16: m | I16: 3.5 | J16: 0
A17: Bored Pile | B17: Pile Load Testing | C17: Mobilization and demobilization | D17: ls | I17: 13000 | J17: 0
A18: Bored Pile | B18: Pile Head Cutting & Preparation | C18: Pile Head Cutting & Preparation for bored pile D1500mm | D18: nos | I18: 150 | J18: 0
A19: Bored Pile | B19: Pile Load Testing | C19: Working Load Test and Ultimate Load Test, TL=2550Tons & 4250Tons, FS=1.5 & 2.5 with Kengledge method. Included : Mobiliztion and crane service | D19: nos | I19: 22000 | J19: 0
... A33: Pile Caps | B33: Base Preparation | C33: Well Soil Compact | D33: m2 | I33: 1.8 | J33: 0
A34: Pile Caps | B34: Polyethylene Sheet | C34: Polyethylene Sheet, 2m width x 100m length | D34: m2
A35: Pile Caps | B35: Crush Stone | C35: Gravel 40x60mm Compaction 150mm thk. | D35: m3 | I35: 11 | J35: 52
A36: Pile Caps | B36: Lean Concrete | C36: Lean Concrete Grade C20/25 50mm thk. | D36: m3 | I36: 11 | J36: 52
A37: Pile Caps | B37: Concrete | C37: Normal Concrete, C35/45 Mpa | D37: m3 | I37: 11 | J37: 63
A38: Pile Caps | B38: Formwork | C38: Formwork | D38: m2 | I38: 14 | J38: 12
A39: Pile Caps | B39: Rebar | C39: Deform Bar, DB10 SD500 Mpa | D39: kg | I39: 0.145 | J39: 0.78
A40: Pile Caps | B40: Rebar | C40: Deform Bar, DB12 SD500 Mpa | D40: kg | I40: 0.145 | J40: 0.78
A41: Pile Caps | B41: Rebar | C41: Deform Bar, DB16 SD500 Mpa | D41: kg | I41: 0.145 | J41: 0.78
A42: Pile Caps | B42: Rebar | C42: Deform Bar, DB20 SD500 Mpa | D42: kg | I42: 0.145 | J42: 0.78
A43: Pile Caps | B43: Rebar | C43: Deform Bar, DB25 SD500 Mpa | D43: kg | I43: 0.145 | J43: 0.78
A44: Pile Caps | B44: Rebar | C44: Deform Bar, DB32 SD500 Mpa | D44: kg | I44: 0.145 | J44: 0.78
A45: Pile Caps | B45: Steel Wire | C45: Steel Tie Wire 1mm | D45: kg | I45: 0.12 | J45: 0.908
A46: Pile Caps | B46: Testing | C46: Rebar Testing as per approved Specification | D46: lot | I46: 0.12 | J46: 0.12
... A49: Sewage Treatment Plant (STP) | B49: Soil Back Fill | C49: Soil Back Fill (Use the existing excavation material) | D49: m3 | I49: 3.5 | J49: 0
A50: Sewage Treatment Plant (STP) | B50: Base Preparation | C50: Well Soil Compact | D50: m2
A51: Sewage Treatment Plant (STP) | B51: Crush Stone | C51: Gravel 40x60mm Compaction 100mm thk. | D51: m3 | I51: 11 | J51: 50
A52: Sewage Treatment Plant (STP) | B52: Lean Concrete | C52: Lean Concrete Grade C20/25 50mm thk. | D52: m3 | I52: 11 | J52: 50
A53: Sewage Treatment Plant (STP) | B53: Concrete | C53: Normal Concrete, C35/45 Mpa | D53: m3 | I53: 11 | J53: 63
A54: Sewage Treatment Plant (STP) | B54: Formwork | C54: Formwork | D54: m2 | I54: 14 | J54: 12
A55: Sewage Treatment Plant (STP) | B55: Rebar | C55: Deform Bar, DB10 SD500 Mpa | D55: kg | I55: 0.145 | J55: 0.78
...

Sheet Preliminaries
A1: PRELIMINARIES & GENERAL (Z)
A2: 10-Storey School Building | Phnom Penh, Cambodia | USD ($). Yellow = input (Qty & Rate). Time items assume ~18-month programme.
A4: Code | B4: Description | C4: Unit | D4: Qty | E4: Rate ($) | F4: Amount ($)
A5: Z.01 | B5: Site office, store & welfare facilities | C5: Month | D5: 18 | E5: 1200 | F5: =D5*E5 -> 21600
A6: Z.02 | B6: Site management & supervision staff | C6: Month | D6: 18 | E6: 5000 | F6: =D6*E6 -> 90000
A7: Z.03 | B7: Temporary fencing & hoarding | C7: Item | D7: 1 | E7: 8000 | F7: =D7*E7 -> 8000
A8: Z.04 | B8: Temporary water supply | C8: Month | D8: 18 | E8: 300 | F8: =D8*E8 -> 5400
A9: Z.05 | B9: Temporary electricity supply | C9: Month | D9: 18 | E9: 800 | F9: =D9*E9 -> 14400
A10: Z.06 | B10: Health, safety & PPE | C10: Month | D10: 18 | E10: 500 | F10: =D10*E10 -> 9000
A11: Z.07 | B11: Site security | C11: Month | D11: 18 | E11: 900 | F11: =D11*E11 -> 16200
A12: Z.08 | B12: Site cleaning & waste removal | C12: Month | D12: 18 | E12: 600 | F12: =D12*E12 -> 10800
A13: Z.09 | B13: Setting out & survey | C13: Month | D13: 18 | E13: 400 | F13: =D13*E13 -> 7200
A14: Z.10 | B14: Material & concrete testing | C14: Item | D14: 1 | E14: 8000 | F14: =D14*E14 -> 8000
A15: Z.11 | B15: Insurance (CAR / third party) | C15: Item | D15: 1 | E15: 12000 | F15: =D15*E15 -> 12000
A16: Z.12 | B16: Performance bond / guarantees | C16: Item | D16: 1 | E16: 6000 | F16: =D16*E16 -> 6000
... A26: Z.22 | B26: Temporary sheet pile length 6m | C26: m | D26: 95 | E26: 180 | F26: =D26*E26 -> 17100
B27: TOTAL PRELIMINARIES (Z) | F27: =SUM(F5:F26) -> 403700
B29: Note: Benchmark inputs for a ~18-month programme — adjust Qty (months/no.) and Rate per your resourcing & quotations.

Sheet Raw Data
A1: Nº | B1: PTB Code | C1: Discipline | D1: Budget Code | E1: Building Code | F1: Level | G1: Section | H1: Sub Section | I1: Sub Element | J1: Material Type | K1: Element group | L1: Element ID | M1: Description | N1: Brand | O1: Supplier | P1: Unit | Q1: Quantity | R1: Actual Q.ty | S1: % | T1: Labor Net Cost ($) | U1: Labor Margin (%) | V1: Labor Rate | W1: Material Net Cost ($) | X1: Material Margin (%) | Y1: Material Rate | Z1: Amount | AA1: Package Name
C2: Civil and Structure | D2: =IFERROR(IF(TRIM($G2)="Sub Structure",IF(TRIM($H2)="Bored Pile","B.01","B.03"),IF(TRIM($G2)="Super Structure","B.04",IF(OR(TRIM($G2)="Exterior Wall and Partition",TRIM($G2)="External Wall and Partition"),"C.01",IF(TRIM($G2)="Exterior Wall Finishes","C.02",IF(TRIM($G2)="Interior Wall and Partition","C.09",IF(TRIM($G2)="Interior Door","C.10",IF(TRIM($G2)="External Windows and Louvers","C.04",IF(OR(TRIM($G2)="Interior Floor Finishes",TRIM($G2)="Internal Floor Finishes"),"D.02",IF(OR(TRIM($G2)="Interior Wall Finishes",TRIM($G2)="Internal Wall Finishes"),"D.01",IF(OR(TRIM($G2)="Ceiling Finshes",TRIM($G2)="Ceiling Finishes"),"D.03",IF(TRIM($G2)="Fittings, furnishings and equipment","E.04","")))))))))))," ") -> B.01 | E2: BA | F2: 01.UG | G2: Sub Structure | H2: Bored Pile | I2: Bored Pile Head Cutting | J2: Pile Head Cutting up to required level D1000mm | P2: Nos | Q2: =R2 -> 5 | R2: 5 | S2: 0 | T2: =IFERROR(INDEX('Price List'!$G$5:$G$74,MATCH(TRIM(J2)&"|"&TRIM(P2),'Price List'!$O$5:$O$74,0)),0) -> 55 | U2: =IFERROR(INDEX('Price List'!$H$5:$H$74,MATCH(TRIM(J2)&"|"&TRIM(P2),'Price List'!$O$5:$O$74,0)),0) -> 0.2 | V2: =T2*(1+U2) -> 66 | W2: =IFERROR(INDEX('Price List'!$J$5:$J$74,MATCH(TRIM(J2)&"|"&TRIM(P2),'Price List'!$O$5:$O$74,0)),0) -> 0 | X2: =IFERROR(INDEX('Price List'!$K$5:$K$74,MATCH(TRIM(J2)&"|"&TRIM(P2),'Price List'!$O$5:$O$74,0)),0) -> 0 | Y2: =W2*(1+X2) -> 0 | Z2: =Q2*(V2+Y2) -> 330
C3: Civil and Structure | D3: =IFERROR(IF(TRIM($G3)="Sub Structure",IF(TRIM($H3)="Bored Pile","B.01","B.03"),IF(TRIM($G3)="Super Structure","B.04",IF(OR(TRIM($G3)="Exterior Wall and Partition",TRIM($G3)="External Wall and Partition"),"C.01",IF(TRIM($G3)="Exterior Wall Finishes","C.02",IF(TRIM($G3)="Interior Wall and Partition","C.09",IF(TRIM($G3)="Interior Door","C.10",IF(TRIM($G3)="External Windows and Louvers","C.04",IF(OR(TRIM($G3)="Interior Floor Finishes",TRIM($G3)="Internal Floor Finishes"),"D.02",IF(OR(TRIM($G3)="Interior Wall Finishes",TRIM($G3)="Internal Wall Finishes"),"D.01",IF(OR(TRIM($G3)="Ceiling Finshes",TRIM($G3)="Ceiling Finishes"),"D.03",IF(TRIM($G3)="Fittings, furnishings and equipment","E.04","")))))))))))," ") -> B.01 | E3: BA | F3: 01.UG | G3: Sub Structure | H3: Bored Pile | I3: Bored Pile Head Cutting | J3: Pile Head Cutting up to required level D800mm | P3: Nos | Q3: =R3 -> 17 | R3: 17 | S3: 0 | T3: =IFERROR(INDEX('Price List'!$G$5:$G$74,MATCH(TRIM(J3)&"|"&TRIM(P3),'Price List'!$O$5:$O$74,0)),0) -> 40 | U3: =IFERROR(INDEX('Price List'!$H$5:$H$74,MATCH(TRIM(J3)&"|"&TRIM(P3),'Price List'!$O$5:$O$74,0)),0) -> 0.2 | V3: =T3*(1+U3) -> 48 | W3: =IFERROR(INDEX('Price List'!$J$5:$J$74,MATCH(TRIM(J3)&"|"&TRIM(P3),'Price List'!$O$5:$O$74,0)),0) -> 0 | X3: =IFERROR(INDEX('Price List'!$K$5:$K$74,MATCH(TRIM(J3)&"|"&TRIM(P3),'Price List'!$O$5:$O$74,0)),0) -> 0 | Y3: =W3*(1+X3) -> 0 | Z3: =Q3*(V3+Y3) -> 816
C4: Civil and Structure | D4: =IFERROR(IF(TRIM($G4)="Sub Structure",IF(TRIM($H4)="Bored Pile","B.01","B.03"),IF(TRIM($G4)="Super Structure","B.04",IF(OR(TRIM($G4)="Exterior Wall and Partition",TRIM($G4)="External Wall and Partition"),"C.01",IF(TRIM($G4)="Exterior Wall Finishes","C.02",IF(TRIM($G4)="Interior Wall and Partition","C.09",IF(TRIM($G4)="Interior Door","C.10",IF(TRIM($G4)="External Windows and Louvers","C.04",IF(OR(TRIM($G4)="Interior Floor Finishes",TRIM($G4)="Internal Floor Finishes"),"D.02",IF(OR(TRIM($G4)="Interior Wall Finishes",TRIM($G4)="Internal Wall Finishes"),"D.01",IF(OR(TRIM($G4)="Ceiling Finshes",TRIM($G4)="Ceiling Finishes"),"D.03",IF(TRIM($G4)="Fittings, furnishings and equipment","E.04","")))))))))))," ") -> B.01 | E4: BA | F4: 01.UG | G4: Sub Structure | H4: Bored Pile | I4: Bored Pile Testing | J4: Sonic Logging Test (SLT) | P4: Nos | Q4: =R4 -> 22 | R4: 22 | S4: 0 | T4: =IFERROR(INDEX('Price List'!$G$5:$G$74,MATCH(TRIM(J4)&"|"&TRIM(P4),'Price List'!$O$5:$O$74,0)),0) -> 0 | U4: =IFERROR(INDEX('Price List'!$H$5:$H$74,MATCH(TRIM(J4)&"|"&TRIM(P4),'Price List'!$O$5:$O$74,0)),0) -> 0 | V4: =T4*(1+U4) -> 0 | W4: =IFERROR(INDEX('Price List'!$J$5:$J$74,MATCH(TRIM(J4)&"|"&TRIM(P4),'Price List'!$O$5:$O$74,0)),0) -> 50 | X4: =IFERROR(INDEX('Price List'!$K$5:$K$74,MATCH(TRIM(J4)&"|"&TRIM(P4),'Price List'!$O$5:$O$74,0)),0) -> 0.1 | Y4: =W4*(1+X4) -> 55 | Z4: =Q4*(V4+Y4) -> 1210
C5: Civil and Structure | D5: =IFERROR(IF(TRIM($G5)="Sub Structure",IF(TRIM($H5)="Bored Pile","B.01","B.03"),IF(TRIM($G5)="Super Structure","B.04",IF(OR(TRIM($G5)="Exterior Wall and Partition",TRIM($G5)="External Wall and Partition"),"C.01",IF(TRIM($G5)="Exterior Wall Finishes","C.02",IF(TRIM($G5)="Interior Wall and Partition","C.09",IF(TRIM($G5)="Interior Door","C.10",IF(TRIM($G5)="External Windows and Louvers","C.04",IF(OR(TRIM($G5)="Interior Floor Finishes",TRIM($G5)="Internal Floor Finishes"),"D.02",IF(OR(TRIM($G5)="Interior Wall Finishes",TRIM($G5)="Internal Wall Finishes"),"D.01",IF(OR(TRIM($G5)="Ceiling Finshes",TRIM($G5)="Ceiling Finishes"),"D.03",IF(TRIM($G5)="Fittings, furnishings and equipment","E.04","")))))))))))," ") -> B.01 | E5: BA | F5: 01.UG | G5: Sub Structure | H5: Bored Pile | I5: Bored Pile Coring | J5: Soil Coring for Bored Pile D1000mm, Depth 30m | P5: Nos | Q5: =R5 -> 5 | R5: 5 | S5: 0 | T5: =IFERROR(INDEX('Price List'!$G$5:$G$74,MATCH(TRIM(J5)&"|"&TRIM(P5),'Price List'!$O$5:$O$74,0)),0) -> 0 | U5: =IFERROR(INDEX('Price List'!$H$5:$H$74,MATCH(TRIM(J5)&"|"&TRIM(P5),'Price List'!$O$5:$O$74,0)),0) -> 0 | V5: =T5*(1+U5) -> 0 | W5: =IFERROR(INDEX('Price List'!$J$5:$J$74,MATCH(TRIM(J5)&"|"&TRIM(P5),'Price List'!$O$5:$O$74,0)),0) -> 350 | X5: =IFERROR(INDEX('Price List'!$K$5:$K$74,MATCH(TRIM(J5)&"|"&TRIM(P5),'Price List'!$O$5:$O$74,0)),0) -> 0.1 | Y5: =W5*(1+X5) -> 385 | Z5: =Q5*(V5+Y5) -> 1925
C6: Civil and Structure | D6: =IFERROR(IF(TRIM($G6)="Sub Structure",IF(TRIM($H6)="Bored Pile","B.01","B.03"),IF(TRIM($G6)="Super Structure","B.04",IF(OR(TRIM($G6)="Exterior Wall and Partition",TRIM($G6)="External Wall and Partition"),"C.01",IF(TRIM($G6)="Exterior Wall Finishes","C.02",IF(TRIM($G6)="Interior Wall and Partition","C.09",IF(TRIM($G6)="Interior Door","C.10",IF(TRIM($G6)="External Windows and Louvers","C.04",IF(OR(TRIM($G6)="Interior Floor Finishes",TRIM($G6)="Internal Floor Finishes"),"D.02",IF(OR(TRIM($G6)="Interior Wall Finishes",TRIM($G6)="Internal Wall Finishes"),"D.01",IF(OR(TRIM($G6)="Ceiling Finshes",TRIM($G6)="Ceiling Finishes"),"D.03",IF(TRIM($G6)="Fittings, furnishings and equipment","E.04","")))))))))))," ") -> B.01 | E6: BA | F6: 01.UG | G6: Sub Structure | H6: Bored Pile | I6: Bored Pile Coring | J6: Soil Coring for Bored Pile D800mm, Depth 30m | P6: Nos | Q6: =R6 -> 17 | R6: 17 | S6: 0 | T6: =IFERROR(INDEX('Price List'!$G$5:$G$74,MATCH(TRIM(J6)&"|"&TRIM(P6),'Price List'!$O$5:$O$74,0)),0) -> 0 | U6: =IFERROR(INDEX('Price List'!$H$5:$H$74,MATCH(TRIM(J6)&"|"&TRIM(P6),'Price List'!$O$5:$O$74,0)),0) -> 0 | V6: =T6*(1+U6) -> 0 | W6: =IFERROR(INDEX('Price List'!$J$5:$J$74,MATCH(TRIM(J6)&"|"&TRIM(P6),'Price List'!$O$5:$O$74,0)),0) -> 300 | X6: =IFERROR(INDEX('Price List'!$K$5:$K$74,MATCH(TRIM(J6)&"|"&TRIM(P6),'Price List'!$O$5:$O$74,0)),0) -> 0.1 | Y6: =W6*(1+X6) -> 330 | Z6: =Q6*(V6+Y6) -> 5610
C7: Civil and Structure | D7: =IFERROR(IF(TRIM($G7)="Sub Structure",IF(TRIM($H7)="Bored Pile","B.01","B.03"),IF(TRIM($G7)="Super Structure","B.04",IF(OR(TRIM($G7)="Exterior Wall and Partition",TRIM($G7)="External Wall and Partition"),"C.01",IF(TRIM($G7)="Exterior Wall Finishes","C.02",IF(TRIM($G7)="Interior Wall and Partition","C.09",IF(TRIM($G7)="Interior Door","C.10",IF(TRIM($G7)="External Windows and Louvers","C.04",IF(OR(TRIM($G7)="Interior Floor Finishes",TRIM($G7)="Internal Floor Finishes"),"D.02",IF(OR(TRIM($G7)="Interior Wall Finishes",TRIM($G7)="Internal Wall Finishes"),"D.01",IF(OR(TRIM($G7)="Ceiling Finshes",TRIM($G7)="Ceiling Finishes"),"D.03",IF(TRIM($G7)="Fittings, furnishings and equipment","E.04","")))))))))))," ") -> B.01 | E7: BA | F7: 01.UG | G7: Sub Structure | H7: Bored Pile | I7: Concrete | J7: Normal Concrete, 35Mpa (Cylinder), Slump 15+-2.5 | P7: m3 | Q7: =R7 -> 374.16369 | R7: =((PI()*0.4^2)*30*17)+((PI()*0.5^2)*30*5) -> 374.16369 | T7: =IFERROR(INDEX('Price List'!$G$5:$G$74,MATCH(TRIM(J7)&"|"&TRIM(P7),'Price List'!$O$5:$O$74,0)),0) -> 8 | U7: =IFERROR(INDEX('Price List'!$H$5:$H$74,MATCH(TRIM(J7)&"|"&TRIM(P7),'Price List'!$O$5:$O$74,0)),0) -> 0.2 | V7: =T7*(1+U7) -> 9.6 | W7: =IFERROR(INDEX('Price List'!$J$5:$J$74,MATCH(TRIM(J7)&"|"&TRIM(P7),'Price List'!$O$5:$O$74,0)),0) -> 98 | X7: =IFERROR(INDEX('Price List'!$K$5:$K$74,MATCH(TRIM(J7)&"|"&TRIM(P7),'Price List'!$O$5:$O$74,0)),0) -> 0.12 | Y7: =W7*(1+X7) -> 109.76 | Z7: =Q7*(V7+Y7) -> 44660.177
C8: Civil and Structure | D8: =IFERROR(IF(TRIM($G8)="Sub Structure",IF(TRIM($H8)="Bored Pile","B.01","B.03"),IF(TRIM($G8)="Super Structure","B.04",IF(OR(TRIM($G8)="Exterior Wall and Partition",TRIM($G8)="External Wall and Partition"),"C.01",IF(TRIM($G8)="Exterior Wall Finishes","C.02",IF(TRIM($G8)="Interior Wall and Partition","C.09",IF(TRIM($G8)="Interior Door","C.10",IF(TRIM($G8)="External Windows and Louvers","C.04",IF(OR(TRIM($G8)="Interior Floor Finishes",TRIM($G8)="Internal Floor Finishes"),"D.02",IF(OR(TRIM($G8)="Interior Wall Finishes",TRIM($G8)="Internal Wall Finishes"),"D.01",IF(OR(TRIM($G8)="Ceiling Finshes",TRIM($G8)="Ceiling Finishes"),"D.03",IF(TRIM($G8)="Fittings, furnishings and equipment","E.04","")))))))))))," ") -> B.01 | E8: BA | F8: 01.UG | G8: Sub Structure | H8: Bored Pile | I8: Rebar | J8: Deform Bar, DB10(fy=390 Mpa) | P8: kg | Q8: =R8 -> 2553.8864 | R8: 2553.8864 | T8: =IFERROR(INDEX('Price List'!$G$5:$G$74,MATCH(TRIM(J8)&"|"&TRIM(P8),'Price List'!$O$5:$O$74,0)),0) -> 0.12 | U8: =IFERROR(INDEX('Price List'!$H$5:$H$74,MATCH(TRIM(J8)&"|"&TRIM(P8),'Price List'!$O$5:$O$74,0)),0) -> 0.2 | V8: =T8*(1+U8) -> 0.144 | W8: =IFERROR(INDEX('Price List'!$J$5:$J$74,MATCH(TRIM(J8)&"|"&TRIM(P8),'Price List'!$O$5:$O$74,0)),0) -> 0.78 | X8: =IFERROR(INDEX('Price List'!$K$5:$K$74,MATCH(TRIM(J8)&"|"&TRIM(P8),'Price List'!$O$5:$O$74,0)),0) -> 0.12 | Y8: =W8*(1+X8) -> 0.8736 | Z8: =Q8*(V8+Y8) -> 2598.8348
C9: Civil and Structure | D9: =IFERROR(IF(TRIM($G9)="Sub Structure",IF(TRIM($H9)="Bored Pile","B.01","B.03"),IF(TRIM($G9)="Super Structure","B.04",IF(OR(TRIM($G9)="Exterior Wall and Partition",TRIM($G9)="External Wall and Partition"),"C.01",IF(TRIM($G9)="Exterior Wall Finishes","C.02",IF(TRIM($G9)="Interior Wall and Partition","C.09",IF(TRIM($G9)="Interior Door","C.10",IF(TRIM($G9)="External Windows and Louvers","C.04",IF(OR(TRIM($G9)="Interior Floor Finishes",TRIM($G9)="Internal Floor Finishes"),"D.02",IF(OR(TRIM($G9)="Interior Wall Finishes",TRIM($G9)="Internal Wall Finishes"),"D.01",IF(OR(TRIM($G9)="Ceiling Finshes",TRIM($G9)="Ceiling Finishes"),"D.03",IF(TRIM($G9)="Fittings, furnishings and equipment","E.04","")))))))))))," ") -> B.01 | E9: BA | F9: 01.UG | G9: Sub Structure | H9: Bored Pile | I9: Rebar | J9: Deform Bar, DB25(fy=390 Mpa) | P9: kg | Q9: =R9 -> 33921.812 | R9: 33921.812 | T9: =IFERROR(INDEX('Price List'!$G$5:$G$74,MATCH(TRIM(J9)&"|"&TRIM(P9),'Price List'!$O$5:$O$74,0)),0) -> 0.08 | U9: =IFERROR(INDEX('Price List'!$H$5:$H$74,MATCH(TRIM(J9)&"|"&TRIM(P9),'Price List'!$O$5:$O$74,0)),0) -> 0.2 | V9: =T9*(1+U9) -> 0.096 | W9: =IFERROR(INDEX('Price List'!$J$5:$J$74,MATCH(TRIM(J9)&"|"&TRIM(P9),'Price List'!$O$5:$O$74,0)),0) -> 0.72 | X9: =IFERROR(INDEX('Price List'!$K$5:$K$74,MATCH(TRIM(J9)&"|"&TRIM(P9),'Price List'!$O$5:$O$74,0)),0) -> 0.12 | Y9: =W9*(1+X9) -> 0.8064 | Z9: =Q9*(V9+Y9) -> 30611.043
C10: Civil and Structure | D10: =IFERROR(IF(TRIM($G10)="Sub Structure",IF(TRIM($H10)="Bored Pile","B.01","B.03"),IF(TRIM($G10)="Super Structure","B.04",IF(OR(TRIM($G10)="Exterior Wall and Partition",TRIM($G10)="External Wall and Partition"),"C.01",IF(TRIM($G10)="Exterior Wall Finishes","C.02",IF(TRIM($G10)="Interior Wall and Partition","C.09",IF(TRIM($G10)="Interior Door","C.10",IF(TRIM($G10)="External Windows and Louvers","C.04",IF(OR(TRIM($G10)="Interior Floor Finishes",TRIM($G10)="Internal Floor Finishes"),"D.02",IF(OR(TRIM($G10)="Interior Wall Finishes",TRIM($G10)="Internal Wall Finishes"),"D.01",IF(OR(TRIM($G10)="Ceiling Finshes",TRIM($G10)="Ceiling Finishes"),"D.03",IF(TRIM($G10)="Fittings, furnishings and equipment","E.04","")))))))))))," ") -> B.01 | E10: BA | F10: 01.UG | G10: Sub Structure | H10: Bored Pile | I10: Steel Tie Wire | J10: Steel Tie Wire 1mm (Estimated 4% of Total Rebar Weight) | P10: kg | Q10: =R10 -> 1459.0279 | R10: =(R8+R9)*4% -> 1459.0279 | T10: =IFERROR(INDEX('Price List'!$G$5:$G$74,MATCH(TRIM(J10)&"|"&TRIM(P10),'Price List'!$O$5:$O$74,0)),0) -> 0.05 | U10: =IFERROR(INDEX('Price List'!$H$5:$H$74,MATCH(TRIM(J10)&"|"&TRIM(P10),'Price List'!$O$5:$O$74,0)),0) -> 0.2 | V10: =T10*(1+U10) -> 0.06 | W10: =IFERROR(INDEX('Price List'!$J$5:$J$74,MATCH(TRIM(J10)&"|"&TRIM(P10),'Price List'!$O$5:$O$74,0)),0) -> 1.2 | X10: =IFERROR(INDEX('Price List'!$K$5:$K$74,MATCH(TRIM(J10)&"|"&TRIM(P10),'Price List'!$O$5:$O$74,0)),0) -> 0.12 | Y10: =W10*(1+X10) -> 1.344 | Z10: =Q10*(V10+Y10) -> 2048.4752
C11: Civil and Structure | D11: =IFERROR(IF(TRIM($G11)="Sub Structure",IF(TRIM($H11)="Bored Pile","B.01","B.03"),IF(TRIM($G11)="Super Structure","B.04",IF(OR(TRIM($G11)="Exterior Wall and Partition",TRIM($G11)="External Wall and Partition"),"C.01",IF(TRIM($G11)="Exterior Wall Finishes","C.02",IF(TRIM($G11)="Interior Wall and Partition","C.09",IF(TRIM($G11)="Interior Door","C.10",IF(TRIM($G11)="External Windows and Louvers","C.04",IF(OR(TRIM($G11)="Interior Floor Finishes",TRIM($G11)="Internal Floor Finishes"),"D.02",IF(OR(TRIM($G11)="Interior Wall Finishes",TRIM($G11)="Internal Wall Finishes"),"D.01",IF(OR(TRIM($G11)="Ceiling Finshes",TRIM($G11)="Ceiling Finishes"),"D.03",IF(TRIM($G11)="Fittings, furnishings and equipment","E.04","")))))))))))," ") -> B.01 | E11: BA | F11: 01.UG | G11: Sub Structure | H11: Bored Pile | I11: Steel Round Pipe | J11: Steel Round Pipe (D49x2mm) with rush primer and paint | P11: m | Q11: =R11 -> 2201 | R11: =(3*17*31)+(4*5*31) -> 2201 | T11: =IFERROR(INDEX('Price List'!$G$5:$G$74,MATCH(TRIM(J11)&"|"&TRIM(P11),'Price List'!$O$5:$O$74,0)),0) -> 1.5 | U11: =IFERROR(INDEX('Price List'!$H$5:$H$74,MATCH(TRIM(J11)&"|"&TRIM(P11),'Price List'!$O$5:$O$74,0)),0) -> 0.2 | V11: =T11*(1+U11) -> 1.8 | W11: =IFERROR(INDEX('Price List'!$J$5:$J$74,MATCH(TRIM(J11)&"|"&TRIM(P11),'Price List'!$O$5:$O$74,0)),0) -> 4.5 | X11: =IFERROR(INDEX('Price List'!$K$5:$K$74,MATCH(TRIM(J11)&"|"&TRIM(P11),'Price List'!$O$5:$O$74,0)),0) -> 0.12 | Y11: =W11*(1+X11) -> 5.04 | Z11: =Q11*(V11+Y11) -> 15054.84
C12: Civil and Structure | D12: =IFERROR(IF(TRIM($G12)="Sub Structure",IF(TRIM($H12)="Bored Pile","B.01","B.03"),IF(TRIM($G12)="Super Structure","B.04",IF(OR(TRIM($G12)="Exterior Wall and Partition",TRIM($G12)="External Wall and Partition"),"C.01",IF(TRIM($G12)="Exterior Wall Finishes","C.02",IF(TRIM($G12)="Interior Wall and Partition","C.09",IF(TRIM($G12)="Interior Door","C.10",IF(TRIM($G12)="External Windows and Louvers","C.04",IF(OR(TRIM($G12)="Interior Floor Finishes",TRIM($G12)="Internal Floor Finishes"),"D.02",IF(OR(TRIM($G12)="Interior Wall Finishes",TRIM($G12)="Internal Wall Finishes"),"D.01",IF(OR(TRIM($G12)="Ceiling Finshes",TRIM($G12)="Ceiling Finishes"),"D.03",IF(TRIM($G12)="Fittings, furnishings and equipment","E.04","")))))))))))," ") -> B.01 | E12: BA | F12: 01.UG | G12: Sub Structure | H12: Bored Pile | I12: Rebar Testing | J12: Rebar Testing as per Specification | P12: Lot | Q12: =R12 -> 1 | R12: 1 | S12: 0 | T12: =IFERROR(INDEX('Price List'!$G$5:$G$74,MATCH(TRIM(J12)&"|"&TRIM(P12),'Price List'!$O$5:$O$74,0)),0) -> 0 | U12: =IFERROR(INDEX('Price List'!$H$5:$H$74,MATCH(TRIM(J12)&"|"&TRIM(P12),'Price List'!$O$5:$O$74,0)),0) -> 0 | V12: =T12*(1+U12) -> 0 | W12: =IFERROR(INDEX('Price List'!$J$5:$J$74,MATCH(TRIM(J12)&"|"&TRIM(P12),'Price List'!$O$5:$O$74,0)),0) -> 200 | X12: =IFERROR(INDEX('Price List'!$K$5:$K$74,MATCH(TRIM(J12)&"|"&TRIM(P12),'Price List'!$O$5:$O$74,0)),0) -> 0.1 | Y12: =W12*(1+X12) -> 220 | Z12: =Q12*(V12+Y12) -> 220
C13: Civil and Structure | D13: =IFERROR(IF(TRIM($G13)="Sub Structure",IF(TRIM($H13)="Bored Pile","B.01","B.03"),IF(TRIM($G13)="Super Structure","B.04",IF(OR(TRIM($G13)="Exterior Wall and Partition",TRIM($G13)="External Wall and Partition"),"C.01",IF(TRIM($G13)="Exterior Wall Finishes","C.02",IF(TRIM($G13)="Interior Wall and Partition","C.09",IF(TRIM($G13)="Interior Door","C.10",IF(TRIM($G13)="External Windows and Louvers","C.04",IF(OR(TRIM($G13)="Interior Floor Finishes",TRIM($G13)="Internal Floor Finishes"),"D.02",IF(OR(TRIM($G13)="Interior Wall Finishes",TRIM($G13)="Internal Wall Finishes"),"D.01",IF(OR(TRIM($G13)="Ceiling Finshes",TRIM($G13)="Ceiling Finishes"),"D.03",IF(TRIM($G13)="Fittings, furnishings and equipment","E.04","")))))))))))," ") -> B.03 | E13: BA | F13: 01.UG | G13: Sub Structure | H13: Pile Cap & Stump | I13: Earthwork | J13: Soil Excavation | P13: m3 | Q13: =R13 -> 1283.17 | R13: 1283.17 | T13: =IFERROR(INDEX('Price List'!$G$5:$G$74,MATCH(TRIM(J13)&"|"&TRIM(P13),'Price List'!$O$5:$O$74,0)),0) -> 3 | U13: =IFERROR(INDEX('Price List'!$H$5:$H$74,MATCH(TRIM(J13)&"|"&TRIM(P13),'Price List'!$O$5:$O$74,0)),0) -> 0.2 | V13: =T13*(1+U13) -> 3.6 | W13: =IFERROR(INDEX('Price List'!$J$5:$J$74,MATCH(TRIM(J13)&"|"&TRIM(P13),'Price List'!$O$5:$O$74,0)),0) -> 0 | X13: =IFERROR(INDEX('Price List'!$K$5:$K$74,MATCH(TRIM(J13)&"|"&TRIM(P13),'Price List'!$O$5:$O$74,0)),0) -> 0 | Y13: =W13*(1+X13) -> 0 | Z13: =Q13*(V13+Y13) -> 4619.412
C14: Civil and Structure | D14: =IFERROR(IF(TRIM($G14)="Sub Structure",IF(TRIM($H14)="Bored Pile","B.01","B.03"),IF(TRIM($G14)="Super Structure","B.04",IF(OR(TRIM($G14)="Exterior Wall and Partition",TRIM($G14)="External Wall and Partition"),"C.01",IF(TRIM($G14)="Exterior Wall Finishes","C.02",IF(TRIM($G14)="Interior Wall and Partition","C.09",IF(TRIM($G14)="Interior Door","C.10",IF(TRIM($G14)="External Windows and Louvers","C.04",IF(OR(TRIM($G14)="Interior Floor Finishes",TRIM($G14)="Internal Floor Finishes"),"D.02",IF(OR(TRIM($G14)="Interior Wall Finishes",TRIM($G14)="Internal Wall Finishes"),"D.01",IF(OR(TRIM($G14)="Ceiling Finshes",TRIM($G14)="Ceiling Finishes"),"D.03",IF(TRIM($G14)="Fittings, furnishings and equipment","E.04","")))))))))))," ") -> B.03 | E14: BA | F14: 01.UG | G14: Sub Structure | H14: Pile Cap & Stump | I14: Earthwork | J14: Soil Disposal | P14: m3 | Q14: =R14 -> 1283.17 | R14: =R13 -> 1283.17 | T14: =IFERROR(INDEX('Price List'!$G$5:$G$74,MATCH(TRIM(J14)&"|"&TRIM(P14),'Price List'!$O$5:$O$74,0)),0) -> 4 | U14: =IFERROR(INDEX('Price List'!$H$5:$H$74,MATCH(TRIM(J14)&"|"&TRIM(P14),'Price List'!$O$5:$O$74,0)),0) -> 0.2 | V14: =T14*(1+U14) -> 4.8 | W14: =IFERROR(INDEX('Price List'!$J$5:$J$74,MATCH(TRIM(J14)&"|"&TRIM(P14),'Price List'!$O$5:$O$74,0)),0) -> 0 | X14: =IFERROR(INDEX('Price List'!$K$5:$K$74,MATCH(TRIM(J14)&"|"&TRIM(P14),'Price List'!$O$5:$O$74,0)),0) -> 0 | Y14: =W14*(1+X14) -> 0 | Z14: =Q14*(V14+Y14) -> 6159.216
C15: Civil and Structure | D15: =IFERROR(IF(TRIM($G15)="Sub Structure",IF(TRIM($H15)="Bored Pile","B.01","B.03"),IF(TRIM($G15)="Super Structure","B.04",IF(OR(TRIM($G15)="Exterior Wall and Partition",TRIM($G15)="External Wall and Partition"),"C.01",IF(TRIM($G15)="Exterior Wall Finishes","C.02",IF(TRIM($G15)="Interior Wall and Partition","C.09",IF(TRIM($G15)="Interior Door","C.10",IF(TRIM($G15)="External Windows and Louvers","C.04",IF(OR(TRIM($G15)="Interior Floor Finishes",TRIM($G15)="Internal Floor Finishes"),"D.02",IF(OR(TRIM($G15)="Interior Wall Finishes",TRIM($G15)="Internal Wall Finishes"),"D.01",IF(OR(TRIM($G15)="Ceiling Finshes",TRIM($G15)="Ceiling Finishes"),"D.03",IF(TRIM($G15)="Fittings, furnishings and equipment","E.04","")))))))))))," ") -> B.03 | E15: BA | F15: 01.UG | G15: Sub Structure | H15: Pile Cap & Stump | I15: Earthwork | J15: Soil Backfill | P15: m3 | Q15: =R15 -> 1148.424 | R15: =R13-R16 -> 1148.424 | T15: =IFERROR(INDEX('Price List'!$G$5:$G$74,MATCH(TRIM(J15)&"|"&TRIM(P15),'Price List'!$O$5:$O$74,0)),0) -> 4 | U15: =IFERROR(INDEX('Price List'!$H$5:$H$74,MATCH(TRIM(J15)&"|"&TRIM(P15),'Price List'!$O$5:$O$74,0)),0) -> 0.2 | V15: =T15*(1+U15) -> 4.8 | W15: =IFERROR(INDEX('Price List'!$J$5:$J$74,MATCH(TRIM(J15)&"|"&TRIM(P15),'Price List'!$O$5:$O$74,0)),0) -> 0 | X15: =IFERROR(INDEX('Price List'!$K$5:$K$74,MATCH(TRIM(J15)&"|"&TRIM(P15),'Price List'!$O$5:$O$74,0)),0) -> 0 | Y15: =W15*(1+X15) -> 0 | Z15: =Q15*(V15+Y15) -> 5512.4352
