Workbook

Sheet Floor Code (2)
A1: Floor Code
A2: Building Code | B2: Sequence Number | C2: Level Code on Design | D2: Floor Code
A3: BA | B3: 01 | C3: U01 | D3: =CONCATENATE(A3,"-",B3,"-",C3) -> BA-01-U01
A4: BA | B4: 02 | C4: B02 | D4: =CONCATENATE(A4,"-",B4,"-",C4) -> BA-02-B02
A5: BA | B5: 03 | C5: B01 | D5: =CONCATENATE(A5,"-",B5,"-",C5) -> BA-03-B01
A6: BA | B6: 04 | C6: L00 | D6: =CONCATENATE(A6,"-",B6,"-",C6) -> BA-04-L00
A7: BA | B7: 05 | C7: L01 | D7: =CONCATENATE(A7,"-",B7,"-",C7) -> BA-05-L01
A8: BA | B8: 06 | C8: L02 | D8: =CONCATENATE(A8,"-",B8,"-",C8) -> BA-06-L02
A9: BA | B9: 07 | C9: L03 | D9: =CONCATENATE(A9,"-",B9,"-",C9) -> BA-07-L03
A10: BA | B10: 08 | C10: L04 | D10: =CONCATENATE(A10,"-",B10,"-",C10) -> BA-08-L04
A11: BA | B11: 09 | C11: L05 | D11: =CONCATENATE(A11,"-",B11,"-",C11) -> BA-09-L05

Sheet Floor Code
A1: Floor Naming
A2: Building Name | B2: Level | C2: Level Function | D2: CFA (m2) | E2: Building Code | F2: Sequence Number | G2: Level Code | H2: Floor Code

Sheet CS BoQ Level
A1: Civil and Structure Level Breakdown
A2: Discipline | B2: Section | C2: Sub Section | D2: Material Type | E2: Unit
A3: Civil and Structure | B3: Foundation | C3: Pile | D3: D1000 Concrete Grade C30/37 | E3: m
D4: D400 Concrete Grade C30/37 | E4: m
D5: D600 Concrete Grade C30/37 | E5: m
D6: D800 Concrete Grade C30/37 | E6: m
C7: Pile Caps | D7: Anti-Termite | E7: m2
D8: Concrete Grade C40/50 | E8: m3
D9: Rebar DB10 SD390 | E9: kg
D10: Rebar DB12 SD390 | E10: kg
D11: Rebar DB16 SD390 | E11: kg
D12: Rebar DB20 SD390 | E12: kg
D13: Rebar DB25 SD390 | E13: kg
D14: Rebar DB8 SD235 | E14: kg
D15: Excavation | E15: m3
D16: Gravel 4x6cm Compaction 100mm thk. & Concrete Grade C25/30 50mm thk. | E16: m3
D17: Plywood Formwork | E17: m2
C18: Temperary Protection | D18: H-Beam(400x400x13x21)mm, SD365 | E18: kg
D19: Steel sheet piles (6x0.75)m | E19: m
B20: Sub Structure | C20: Sewage Treatment Plant (STP) | D20: Normal Concrete, C35/45 Mpa | E20: m3
D21: Rebar DB10 SD390 | E21: kg
D22: Gravel 4x6cm Compaction 100mm thk. & Concrete Grade C25/30 50mm thk. | E22: m3
D23: Plywood Formwork | E23: m2
C24: Retaining Wall | D24: Concrete Grade C40/50 | E24: m3
D25: Rebar DB10 SD390 | E25: kg
D26: Rebar DB20 SD390 | E26: kg
D27: Rebar DB25 SD390 | E27: kg
D28: Rebar DB8 SD235 | E28: kg
D29: Plywood Formwork | E29: m2
D30: Sika Waterbar | E30: m
C31: Water Tank | D31: Concrete Grade C35/45 | E31: m3
D32: Rebar DB12 SD390 | E32: kg
D33: Plywood Formwork | E33: m2
B34: Super Structure | C34: Beam | D34: Concrete Grade C40/50 | E34: m3
D35: Rebar DB10 SD390 | E35: kg
D36: Rebar DB12 SD390 | E36: kg
D37: Rebar DB16 SD390 | E37: kg
D38: Rebar DB20 SD390 | E38: kg
D39: Rebar DB25 SD390 | E39: kg
D40: Rebar DB8 SD235 | E40: kg
...

Sheet RFQ_Rawdata
A1: Design Data | F1: RFQ DATA | N1: Remark
A2: Sub Section | B2: Sub Element | C2: Material Type | D2: Unit | E2: Designated Brand | F2: Supplier ID | G2: Proposed Brand | H2: Specification | I2: Labor Rate | J2: Material Rate | K2: RQF No | L2: Submit by | M2: Submit Date
A3: Bored Pile | B3: Preliminary Works | C3: Mobilization and Demobilization | D3: lot | I3: 13000 | J3: 0
A4: Bored Pile | B4: Preliminary Works | C4: Management fee and field engineer | D4: lot | I4: 28000 | J4: 0
A5: Bored Pile | B5: Preliminary Works | C5: Survey and setting out & As-Built drawing | D5: lot | I5: 3470 | J5: 0
A6: Bored Pile | B6: Preliminary Works | C6: Casing length 6m and Steel plate | D6: lot
A7: Bored Pile | B7: Coring Works | C7: Bentonite | D7: lot
A8: Bored Pile | B8: Coring Works | C8: Rock Coring for Bored Pile D1500mm | D8: m | I8: 260 | J8: 0
A9: Bored Pile | B9: Coring Works | C9: Soil Coring for Bored Pile D1500mm | D9: m | I9: 60 | J9: 0
A10: Bored Pile | B10: Concrete | C10: Normal Concrete, C35/45 Mpa | D10: m3 | I10: 16 | J10: 63
A11: Bored Pile | B11: Rebar | C11: Deform Bar, DB10 SD500 Mpa | D11: kg | I11: 0.07 | J11: 0.78
A12: Bored Pile | B12: Rebar | C12: Deform Bar, DB16 SD500 Mpa | D12: kg | I12: 0.07 | J12: 0.78
A13: Bored Pile | B13: Rebar | C13: Deform Bar, DB20 SD500 Mpa | D13: kg | I13: 0.07 | J13: 0.78
A14: Bored Pile | B14: Steel Wire | C14: Steel Tie Wire 1mm | D14: kg | I14: 0.12 | J14: 0.908
A15: Bored Pile | B15: Steel Tube | C15: Steel Tube D49x1.9mm with Anti rust and black paint finish | D15: m | I15: 3.7 | J15: 0
A16: Bored Pile | B16: Grouting works | C16: Grouting works after sonic logging test | D16: m | I16: 3.5 | J16: 0
A17: Bored Pile | B17: Pile Load Testing | C17: Mobilization and demobilization | D17: ls | I17: 13000 | J17: 0
A18: Bored Pile | B18: Pile Head Cutting & Preparation | C18: Pile Head Cutting & Preparation for bored pile D1500mm | D18: nos | I18: 150 | J18: 0
A19: Bored Pile | B19: Pile Load Testing | C19: Working Load Test and Ultimate Load Test, TL=2550Tons & 4250Tons, FS=1.5 & 2.5 with Kengledge method. Included : Mobiliztion and crane service | D19: nos | I19: 22000 | J19: 0
... A33: Pile Caps | B33: Base Preparation | C33: Well Soil Compact | D33: m2 | I33: 1.8 | J33: 0
A34: Pile Caps | B34: Polyethylene Sheet | C34: Polyethylene Sheet, 2m width x 100m length | D34: m2
A35: Pile Caps | B35: Crush Stone | C35: Gravel 40x60mm Compaction 150mm thk. | D35: m3 | I35: 11 | J35: 52
A36: Pile Caps | B36: Lean Concrete | C36: Lean Concrete Grade C20/25 50mm thk. | D36: m3 | I36: 11 | J36: 52
A37: Pile Caps | B37: Concrete | C37: Normal Concrete, C35/45 Mpa | D37: m3 | I37: 11 | J37: 63
A38: Pile Caps | B38: Formwork | C38: Formwork | D38: m2 | I38: 14 | J38: 12
A39: Pile Caps | B39: Rebar | C39: Deform Bar, DB10 SD500 Mpa | D39: kg | I39: 0.145 | J39: 0.78
A40: Pile Caps | B40: Rebar | C40: Deform Bar, DB12 SD500 Mpa | D40: kg | I40: 0.145 | J40: 0.78
A41: Pile Caps | B41: Rebar | C41: Deform Bar, DB16 SD500 Mpa | D41: kg | I41: 0.145 | J41: 0.78
A42: Pile Caps | B42: Rebar | C42: Deform Bar, DB20 SD500 Mpa | D42: kg | I42: 0.145 | J42: 0.78
A43: Pile Caps | B43: Rebar | C43: Deform Bar, DB25 SD500 Mpa | D43: kg | I43: 0.145 | J43: 0.78
A44: Pile Caps | B44: Rebar | C44: Deform Bar, DB32 SD500 Mpa | D44: kg | I44: 0.145 | J44: 0.78
A45: Pile Caps | B45: Steel Wire | C45: Steel Tie Wire 1mm | D45: kg | I45: 0.12 | J45: 0.908
A46: Pile Caps | B46: Testing | C46: Rebar Testing as per approved Specification | D46: lot | I46: 0.12 | J46: 0.12
... A49: Sewage Treatment Plant (STP) | B49: Soil Back Fill | C49: Soil Back Fill (Use the existing excavation material) | D49: m3 | I49: 3.5 | J49: 0
A50: Sewage Treatment Plant (STP) | B50: Base Preparation | C50: Well Soil Compact | D50: m2
A51: Sewage Treatment Plant (STP) | B51: Crush Stone | C51: Gravel 40x60mm Compaction 100mm thk. | D51: m3 | I51: 11 | J51: 50
A52: Sewage Treatment Plant (STP) | B52: Lean Concrete | C52: Lean Concrete Grade C20/25 50mm thk. | D52: m3 | I52: 11 | J52: 50
A53: Sewage Treatment Plant (STP) | B53: Concrete | C53: Normal Concrete, C35/45 Mpa | D53: m3 | I53: 11 | J53: 63
A54: Sewage Treatment Plant (STP) | B54: Formwork | C54: Formwork | D54: m2 | I54: 14 | J54: 12
A55: Sewage Treatment Plant (STP) | B55: Rebar | C55: Deform Bar, DB10 SD500 Mpa | D55: kg | I55: 0.145 | J55: 0.78
...

Sheet Takeoff_Rawdata
A1: UNIFIED TAKEOFF RAW DATA — One Format for PRE / STR / ARC / MEP
A2: RULE: 1 row = 1 measurement. Unused dimensions = 1. Net Qty = No x L x W x H x Factor - Deduction. BOQ = pivot of this table by Budget Code. Colors: PRE=yellow, STR=blue, ARC=green, MEP=orange (illustration only).
A4: ID | B4: Project | C4: Bldg | D4: Floor Code | E4: Budget Code | F4: Disc | G4: Section | H4: Sub Section | I4: Item Code | J4: Description / Material Type | K4: Dwg Ref | L4: Rev | M4: Location / Grid | N4: No. | O4: L (m) | P4: W (m) | Q4: H/Thk (m) | R4: Factor | S4: Deduct | T4: Net Qty | U4: Waste % | V4: Gross Qty | W4: Unit | X4: Rate ($) | Y4: Amount ($) | Z4: Status | AA4: By | AB4: Date | AC4: Remarks
A5: T-0001 | B5: SCH10 | C5: BA | D5: ALL | E5: Z.01.03.01 | F5: PRE | G5: Preliminaries | H5: Temporary Building | I5: Z.01.03.01 | J5: Site office, store & welfare facilities | K5: - | L5: - | M5: Site wide | N5: 18 | O5: 1 | P5: 1 | Q5: 1 | R5: 1 | S5: 0 | T5: =N5*O5*P5*Q5*R5-S5 -> 18 | U5: 0 | V5: =T5*(1+U5/100) -> 18 | W5: Month | X5: 1200 | Y5: =V5*X5 -> 21600 | Z5: Draft | AA5: QS1 | AB5: 2026-07-09 | AC5: Qty = 18 months. Dims unused = 1. Rate from BU Z.01.03
A6: T-0002 | B6: SCH10 | C6: BA | D6: ALL | E6: Z.01.05.06 | F6: PRE | G6: Preliminaries | H6: Machinery | I6: Z.01.05.06 | J6: External scaffolding to facade | K6: A-201 | L6: P1 | M6: All elevations | N6: 1 | O6: 115 | P6: 1 | Q6: 36 | R6: 1 | S6: 0 | T6: =N6*O6*P6*Q6*R6-S6 -> 4140 | U6: 0 | V6: =T6*(1+U6/100) -> 4140 | W6: m2 | X6: 7.2 | Y6: =V6*X6 -> 29808 | Z6: Draft | AA6: QS1 | AB6: 2026-07-09 | AC6: Perimeter x height = facade area. Rate from BU Z.01.05
A7: T-0003 | B7: SCH10 | C7: BA | D7: BA-04-L00 | E7: B.01 | F7: STR | G7: Sub Structure | H7: Pile Caps | I7: 03-CONC-PC | J7: Normal Concrete C35/45 in pile caps | K7: S-102 | L7: P2 | M7: Grid A1-D4 | N7: 12 | O7: 2.5 | P7: 2.5 | Q7: 1.2 | R7: 1 | S7: 0 | T7: =N7*O7*P7*Q7*R7-S7 -> 90 | U7: 2 | V7: =T7*(1+U7/100) -> 91.8 | W7: m3 | X7: 74 | Y7: =V7*X7 -> 6793.2 | Z7: Draft | AA7: QS1 | AB7: 2026-07-09 | AC7: 12 caps PC-1 type. Waste 2%. Rate from RFQ: 11+63
A8: T-0004 | B8: SCH10 | C8: BA | D8: BA-04-L00 | E8: B.01 | F8: STR | G8: Sub Structure | H8: Pile Caps | I8: 03-REBR-PC | J8: Deform Bar DB20 SD500 in pile caps | K8: S-102 | L8: P2 | M8: Grid A1-D4 | N8: 576 | O8: 3.2 | P8: 1 | Q8: 1 | R8: 2.466 | S8: 0 | T8: =N8*O8*P8*Q8*R8-S8 -> 4545.3312 | U8: 3 | V8: =T8*(1+U8/100) -> 4681.6911 | W8: kg | X8: 0.925 | Y8: =V8*X8 -> 4330.5643 | Z8: Draft | AA8: QS1 | AB8: 2026-07-09 | AC8: 48 bars x 12 caps. Factor = 2.466 kg/m for DB20. Rate = labor+material
A9: T-0005 | B9: SCH10 | C9: BA | D9: BA-05-L01 | E9: B.04 | F9: STR | G9: Super Structure | H9: Column | I9: 03-CONC-COL | J9: Normal Concrete C35/45 in columns | K9: S-201 | L9: P1 | M9: C1-C18 | N9: 18 | O9: 0.6 | P9: 0.6 | Q9: 3.5 | R9: 1 | S9: 0 | T9: =N9*O9*P9*Q9*R9-S9 -> 22.68 | U9: 2 | V9: =T9*(1+U9/100) -> 23.1336 | W9: m3 | X9: 70 | Y9: =V9*X9 -> 1619.352 | Z9: Draft | AA9: QS1 | AB9: 2026-07-09 | AC9: 18 columns 600x600, storey height 3.5m
A10: T-0006 | B10: SCH10 | C10: BA | D10: BA-05-L01 | E10: B.04 | F10: STR | G10: Super Structure | H10: Column | I10: 03-FWRK-COL | J10: Plywood formwork to columns | K10: S-201 | L10: P1 | M10: C1-C18 | N10: 18 | O10: 2.4 | P10: 1 | Q10: 3.5 | R10: 1 | S10: 0 | T10: =N10*O10*P10*Q10*R10-S10 -> 151.2 | U10: 5 | V10: =T10*(1+U10/100) -> 158.76 | W10: m2 | X10: 20 | Y10: =V10*X10 -> 3175.2 | Z10: Draft | AA10: QS1 | AB10: 2026-07-09 | AC10: Girth 4x0.6=2.4m x height. Waste 5%
A11: T-0007 | B11: SCH10 | C11: BA | D11: BA-05-L01 | E11: C.09 | F11: ARC | G11: Architecture | H11: Interior Wall Partition | I11: 04-BLCK-100 | J11: 100mm concrete block wall in cement mortar | K11: A-301 | L11: P1 | M11: Classroom zone | N11: 1 | O11: 25 | P11: 1 | Q11: 3.5 | R11: 1 | S11: 8 | T11: =N11*O11*P11*Q11*R11-S11 -> 79.5 | U11: 5 | V11: =T11*(1+U11/100) -> 83.475 | W11: m2 | X11: 14 | Y11: =V11*X11 -> 1168.65 | Z11: Draft | AA11: QS1 | AB11: 2026-07-09 | AC11: Deduct 8 m2 door/window openings
A12: T-0008 | B12: SCH10 | C12: BA | D12: BA-05-L01 | E12: D.02 | F12: ARC | G12: Interior Finish | H12: Floor Finishes | I12: 04-TILE-600 | J12: Porcelain floor tile 600x600 on screed | K12: A-401 | L12: P1 | M12: Classroom 101 | N12: 1 | O12: 8.4 | P12: 7.2 | Q12: 1 | R12: 1 | S12: 0 | T12: =N12*O12*P12*Q12*R12-S12 -> 60.48 | U12: 7 | V12: =T12*(1+U12/100) -> 64.7136 | W12: m2 | X12: 22 | Y12: =V12*X12 -> 1423.6992 | Z12: Draft | AA12: QS1 | AB12: 2026-07-09 | AC12: Room 8.4 x 7.2m. Tile waste 7%
A13: T-0009 | B13: SCH10 | C13: BA | D13: BA-04-L00 | E13: C.03 | F13: ARC | G13: Architecture | H13: Exterior Door | I13: 04-DOOR-D1 | J13: Aluminum glass double door D1 2.4x2.8m | K13: A-501 | L13: P1 | M13: Main entrance | N13: 2 | O13: 1 | P13: 1 | Q13: 1 | R13: 1 | S13: 0 | T13: =N13*O13*P13*Q13*R13-S13 -> 2 | U13: 0 | V13: =T13*(1+U13/100) -> 2 | W13: nos | X13: 850 | Y13: =V13*X13 -> 1700 | Z13: Draft | AA13: QS1 | AB13: 2026-07-09 | AC13: Count items: dims = 1, No. = count
A14: T-0010 | B14: SCH10 | C14: BA | D14: BA-05-L01 | E14: F.05 | F14: MEP | G14: Services | H14: Electrical System | I14: 05-COND-25 | J14: PVC conduit 25mm incl. draw wire | K14: E-201 | L14: P1 | M14: Level 1 corridor | N14: 1 | O14: 120 | P14: 1 | Q14: 1 | R14: 1 | S14: 0 | T14: =N14*O14*P14*Q14*R14-S14 -> 120 | U14: 5 | V14: =T14*(1+U14/100) -> 126 | W14: m | X14: 3.8 | Y14: =V14*X14 -> 478.8 | Z14: Draft | AA14: QS1 | AB14: 2026-07-09 | AC14: Measured along corridor route
A15: T-0011 | B15: SCH10 | C15: BA | D15: BA-05-L01 | E15: F.01 | F15: MEP | G15: Services | H15: Sanitary Installations | I15: 05-WC-STD | J15: WC suite complete incl. fittings | K15: P-301 | L15: P1 | M15: Toilets L1 | N15: 24 | O15: 1 | P15: 1 | Q15: 1 | R15: 1 | S15: 0 | T15: =N15*O15*P15*Q15*R15-S15 -> 24 | U15: 0 | V15: =T15*(1+U15/100) -> 24 | W15: nos | X15: 185 | Y15: =V15*X15 -> 4440 | Z15: Draft | AA15: QS1 | AB15: 2026-07-09 | AC15: Count from sanitary layout
A16: T-0012 | B16: SCH10 | C16: BA | D16: ALL | E16: F.02 | F16: MEP | G16: Services | H16: AC System | I16: 05-AC-PS | J16: Air conditioning system — PROVISIONAL SUM | K16: - | L16: - | M16: Whole building | N16: 1 | O16: 1 | P16: 1 | Q16: 1 | R16: 1 | S16: 0 | T16: =N16*O16*P16*Q16*R16-S16 -> 1 | U16: 0 | V16: =T16*(1+U16/100) -> 1 | W16: Sum | X16: 120000 | Y16: =V16*X16 -> 120000 | Z16: Draft | AA16: QS1 | AB16: 2026-07-09 | AC16: MEP design not received — provisional sum per RFI-005
B18: FORMAT RULES:
B19: 1. ONE ROW = ONE MEASUREMENT. Never merge locations — measure Level 1 columns and Level 2 columns as separate rows even if identical.
B20: 2. UNUSED DIMENSIONS = 1. A count item (doors, WCs) uses No. only; an area item uses No. x L x H; a volume item uses all four.
B21: 3. FACTOR column converts units: rebar kg/m (DB20 = 2.466), girth multipliers, unit weights. Document the factor in Remarks.
B22: 4. DEDUCT is subtracted AFTER the multiplication — openings in walls, voids in slabs.
B23: 5. BUDGET CODE is mandatory on every row — it is what connects takeoff to BOQ, budget, and cost report.
B24: 6. FLOOR CODE from the Floor Code sheet enables quantity reports per level (concrete per floor, etc.).
B25: 7. PRELIMINARIES use the same format: Qty in No. as months/items, rate linked from BU sheets. One table = one source of truth.
B26: 8. BOQ GENERATION: pivot this table by Budget Code -> Section -> Item Code, summing Gross Qty and Amount. Never type a BOQ quantity manually.
B27: 9. STATUS discipline: Draft (measuring) -> Checked (2nd QS verified) -> Final (locked into BOQ). Only Final rows enter the tender.
B28: 10. This flat format maps 1:1 to the future database table "takeoff_lines" — column names = field names.

Sheet Site Data
A1: SITE DATA — Common Parameters (feeds all build-up sheets)
A2: Yellow = input. Items marked TO VERIFY must be checked against drawings before tender submission.
A4: Ref | B4: Parameter | C4: Value | D4: Unit | E4: Status
A5: P01 | B5: Site perimeter (hoarding line) | C5: 130 | D5: m | E5: TO VERIFY
A6: P02 | B6: Building footprint | C6: 800 | D6: m2 | E6: Given
A7: P03 | B7: Building perimeter | C7: 115 | D7: m | E7: TO VERIFY
A8: P04 | B8: Storeys above ground | C8: 10 | D8: no | E8: Given
A9: P05 | B9: Building height | C9: 36 | D9: m | E9: TO VERIFY
A10: P06 | B10: Facade area (P03 x P05) | C10: =C7*C9 -> 4140 | D10: m2 | E10: Calculated
A11: P07 | B11: Programme duration | C11: 18 | D11: months | E11: Assumed
A12: P08 | B12: Structure phase duration | C12: 10 | D12: months | E12: Assumed
A13: P09 | B13: Scaffold rental duration | C13: 12 | D13: months | E13: Assumed
A14: P10 | B14: Peak workforce | C14: 80 | D14: no | E14: Assumed
A15: P11 | B15: Floors incl. roof (edge protection) | C15: 11 | D15: no | E15: Given
A16: P12 | B16: Gross floor area (P02 x P04) | C16: =C6*C8 -> 8000 | D16: m2 | E16: Calculated

Sheet Preliminaries
A1: PRELIMINARIES & GENERAL (Z) — Fully Built-Up
A2: 10-Storey School, Phnom Penh | USD | 18-month programme | Yellow = input | Green = linked from build-up / Site Data sheets
A4: Code | B4: Description | C4: Unit | D4: Qty | E4: Rate ($) | F4: Amount ($) | G4: Remarks
A5: Z.01 | B5: TEMPORARY WORKS
A6: Z.01.01 | B6: Site Preparation — build-ups in sheet "BU Z.01.01"
A7: Z.01.01.01 | B7: Mobilization | C7: Item | D7: 1 | E7: ='BU Z.01.01'!E12 -> 10500 | F7: =D7*E7 -> 10500 | G7: Trips + setup labor + yard
A8: Z.01.01.02 | B8: Demobilization & site clearance | C8: Item | D8: 1 | E8: ='BU Z.01.01'!E19 -> 6460 | F8: =D8*E8 -> 6460 | G8: Trips out + reinstatement
A9: Z.01.01.03 | B9: Temporary access & roads | C9: Item | D9: 1 | E9: ='BU Z.01.01'!E25 -> 7400 | F9: =D9*E9 -> 7400 | G9: Road + hardstand areas
A10: Z.01.01.04 | B10: Setting out & ongoing survey works | C10: Month | D10: 18 | E10: ='BU Z.01.01'!E32 -> 400 | F10: =D10*E10 -> 7200 | G10: Instrument + consumables + checks
A11: Z.01.01.05 | B11: Site signage & project board | C11: Item | D11: 1 | E11: ='BU Z.01.01'!E38 -> 800 | F11: =D11*E11 -> 800 | G11: Board + safety signage
A12: Z.01.01.06 | B12: Traffic management & road occupation | C12: Item | D12: 1 | E12: ='BU Z.01.01'!E45 -> 3000 | F12: =D12*E12 -> 3000 | G12: Flagmen + permits + equipment
A13: Z.01.02 | B13: General Protection — build-ups in sheet "BU Z.01.02"
A14: Z.01.02.01 | B14: Temporary fencing & hoarding | C14: Item | D14: 1 | E14: ='BU Z.01.02'!E8 -> 7950 | F14: =D14*E14 -> 7950 | G14: Site perimeter x rate/m + gates
A15: Z.01.02.02 | B15: Temporary sheet pile, length 6m | C15: m | D15: 95 | E15: ='BU Z.01.02'!E14 -> 180 | F15: =D15*E15 -> 17100 | G15: Rate/m = drive/extract + rental. DELETE from CS BoQ (double count)
A16: Z.01.02.03 | B16: Safety net to building perimeter | C16: Item | D16: 1 | E16: ='BU Z.01.02'!E20 -> 6000 | F16: =D16*E16 -> 6000 | G16: Net area x rate + labor
A17: Z.01.02.04 | B17: Edge protection & handrails | C17: Floor | D17: ='Site Data'!C15 -> 11 | E17: ='BU Z.01.02'!E26 -> 700 | F17: =D17*E17 -> 7700 | G17: Rate/floor = perimeter x rail rate
A18: Z.01.02.05 | B18: Protection of completed works | C18: Item | D18: 1 | E18: ='BU Z.01.02'!E32 -> 4000 | F18: =D18*E18 -> 4000 | G18: Sheeting area + sundries
A19: Z.01.02.06 | B19: Monsoon protection & site drainage | C19: Month | D19: 18 | E19: ='BU Z.01.02'!E39 -> 250 | F19: =D19*E19 -> 4500 | G19: Pumps + channels + labor
A20: Z.01.02.07 | B20: Dewatering during substructure | C20: Month | D20: 4 | E20: ='BU Z.01.02'!E46 -> 900 | F20: =D20*E20 -> 3600 | G20: Pumps + fuel + attendance
A21: Z.01.03 | B21: Temporary Building — build-ups in sheet "BU Z.01.03"
A22: Z.01.03.01 | B22: Site office, store & welfare facilities | C22: Month | D22: 18 | E22: ='BU Z.01.03'!E10 -> 1200 | F22: =D22*E22 -> 21600 | G22: Containers + furniture + shelter
A23: Z.01.03.02 | B23: Temporary worker toilets & sanitation | C23: Month | D23: 18 | E23: ='BU Z.01.03'!E16 -> 200 | F23: =D23*E23 -> 3600 | G23: Units + servicing
A24: Z.01.03.03 | B24: First aid room & facilities | C24: Item | D24: 1 | E24: ='BU Z.01.03'!E22 -> 1500 | F24: =D24*E24 -> 1500 | G24: Fit-out + supplies
A25: Z.01.03.04 | B25: Washing bay / wheel wash | C25: Item | D25: 1 | E25: ='BU Z.01.03'!E30 -> 10100 | F25: =D25*E25 -> 10100 | G25: Pad + pump + maintenance
A26: Z.01.04 | B26: Temporary Site Labor — build-ups in sheet "BU Z.01.04"
A27: Z.01.04.01 | B27: Site cleaning & waste removal | C27: Month | D27: 18 | E27: ='BU Z.01.04'!E9 -> 602 | F27: =D27*E27 -> 10836 | G27: Crew + skips + tipping
A28: Z.01.04.02 | B28: Final builder's clean at handover | C28: Item | D28: 1 | E28: ='BU Z.01.04'!E15 -> 3500 | F28: =D28*E28 -> 3500 | G28: GFA x rate + facade clean
A29: Z.01.05 | B29: Machinery & Vertical Transport — build-ups in sheet "BU Z.01.05"
A30: Z.01.05.01 | B30: Tower crane rental | C30: Month | D30: 16 | E30: ='BU Z.01.05'!E9 -> 3500 | F30: =D30*E30 -> 56000 | G30: Rental + operator + maintenance
A31: Z.01.05.02 | B31: Tower crane foundation, erection, dismantle & test | C31: Item | D31: 1 | E31: ='BU Z.01.05'!E17 -> 18000 | F31: =D31*E31 -> 18000 | G31: Base + erect + dismantle + test
A32: Z.01.05.03 | B32: Passenger / material hoist rental | C32: Month | D32: 12 | E32: ='BU Z.01.05'!E23 -> 1500 | F32: =D32*E32 -> 18000 | G32: Rental + operator
A33: Z.01.05.04 | B33: Hoist erection & dismantling | C33: Item | D33: 1 | E33: ='BU Z.01.05'!E30 -> 4000 | F33: =D33*E33 -> 4000 | G33: Erect + dismantle + cert
A34: Z.01.05.05 | B34: Concrete pump provision | C34: Item | F34: 0 | G34: DECISION: included in concrete unit rates — do NOT price here
A35: Z.01.05.06 | B35: External scaffolding to facade | C35: m2 | D35: ='Site Data'!C10 -> 4140 | E35: ='BU Z.01.05'!E36 -> 7.2 | F35: =D35*E35 -> 29808 | G35: Qty = facade area (Site Data). Rate/m2 = E&D + rental
A36: Z.01.05.07 | B36: Back-propping / falsework for PT slabs | C36: Floor | D36: 10 | E36: ='BU Z.01.05'!E42 -> 1200 | F36: =D36*E36 -> 12000 | G36: Props rental + labor per floor
A37: Z.01.06 | B37: Light Equipment & Hand Tools — build-up in sheet "BU Z.01.06"
A38: Z.01.06.01 | B38: Small plant, light equipment & hand tools | C38: Month | D38: 18 | E38: ='BU Z.01.06'!E10 -> 350 | F38: =D38*E38 -> 6300 | G38: Mixers + tools + consumables
A39: Z.01.07 | B39: Temporary Electrical / Plumbing / Drainage — build-ups in sheet "Temp Utilities"
A40: Z.01.07.01 | B40: Temporary electricity — installation, connection & removal | C40: Item | D40: 1 | E40: ='Temp Utilities'!B34 -> 5500 | F40: =D40*E40 -> 5500 | G40: One-time — Temp Utilities A3
A41: Z.01.07.02 | B41: Temporary electricity — consumption & maintenance | C41: Month | D41: 18 | E41: ='Temp Utilities'!B23 -> 1258.2624 | F41: =D41*E41 -> 22648.723 | G41: Load schedule — Temp Utilities A1/A2
...

Sheet Staff Schedule
A1: SITE STAFF SCHEDULE — Feeds Z.30.01 / Z.30.02 in Preliminaries
A2: 10-Storey School Building, Phnom Penh — 18-month programme. Yellow = input.
A4: No. | B4: Position | C4: Origin | D4: Persons | E4: Months | F4: Monthly Rate ($) | G4: Total ($)
A5: 1 | B5: Project Manager | C5: Foreign | D5: 1 | E5: 18 | F5: 3500 | G5: =D5*E5*F5 -> 63000
A6: 2 | B6: Site Engineer | C6: Local | D6: 2 | E6: 18 | F6: 1200 | G6: =D6*E6*F6 -> 43200
A7: 3 | B7: Quantity Surveyor | C7: Local | D7: 1 | E7: 18 | F7: 1000 | G7: =D7*E7*F7 -> 18000
A8: 4 | B8: Safety Officer | C8: Local | D8: 1 | E8: 18 | F8: 800 | G8: =D8*E8*F8 -> 14400
A9: 5 | B9: Surveyor (incl. assistant) | C9: Local | D9: 1 | E9: 18 | F9: 900 | G9: =D9*E9*F9 -> 16200
A10: 6 | B10: General Foreman | C10: Local | D10: 2 | E10: 18 | F10: 700 | G10: =D10*E10*F10 -> 25200
A11: 7 | B11: Site Admin / Storekeeper | C11: Local | D11: 1 | E11: 18 | F11: 500 | G11: =D11*E11*F11 -> 9000
A12: 8 | B12: Document Controller | C12: Local | D12: 1 | E12: 12 | F12: 500 | G12: =D12*E12*F12 -> 6000
B14: Subtotal — Foreign staff (→ Z.30.01) | G14: =SUMIF(C5:C12,"Foreign",G5:G12) -> 63000
B15: Subtotal — Local staff (→ Z.30.02) | G15: =SUMIF(C5:C12,"Local",G5:G12) -> 132000
B16: TOTAL SITE STAFF | G16: =G14+G15 -> 195000

Sheet Temp Utilities
A1: TEMPORARY UTILITIES BUILD-UP — Feeds Z.01.07 in Preliminaries
A2: Yellow = input. Change any input and the Preliminaries rates update automatically.
A4: A. TEMPORARY ELECTRICITY
A5: A1. Monthly Load Schedule (peak structure months)
A6: Equipment | B6: kW | C6: Hrs/day | D6: Days/month | E6: kWh/month
A7: Tower crane | B7: 30 | C7: 6 | D7: 26 | E7: =B7*C7*D7 -> 4680
A8: Passenger / material hoist | B8: 15 | C8: 5 | D8: 26 | E8: =B8*C8*D8 -> 1950
A9: Bar bender & cutter | B9: 6 | C9: 5 | D9: 26 | E9: =B9*C9*D9 -> 780
A10: Concrete vibrators (4 no.) | B10: 6 | C10: 3 | D10: 20 | E10: =B10*C10*D10 -> 360
A11: Welding sets (2 no.) | B11: 10 | C11: 3 | D11: 20 | E11: =B11*C11*D11 -> 600
A12: Water pumps | B12: 3 | C12: 4 | D12: 26 | E12: =B12*C12*D12 -> 312
A13: Site office (AC, IT, lighting) | B13: 5 | C13: 9 | D13: 26 | E13: =B13*C13*D13 -> 1170
A14: Site & tower lighting | B14: 4 | C14: 11 | D14: 30 | E14: =B14*C14*D14 -> 1320
A15: Total peak consumption | E15: =SUM(E7:E14) -> 11172
A17: A2. Monthly Cost Calculation
A18: EDC tariff ($/kWh) | B18: 0.16
A19: Peak monthly cost | B19: =E15*B18 -> 1787.52
A20: Diversity factor (programme average / peak) | B20: 0.62
A21: Average monthly consumption cost | B21: =B19*B20 -> 1108.2624
A22: Electrician maintenance ($/month) | B22: 150
A23: MONTHLY RATE → Z.01.07.02 | B23: =B21+B22 -> 1258.2624
A25: A3. One-Time Installation & Removal
A26: Description | B26: Amount ($)
A27: EDC connection fee & deposit | B27: 1500
A28: Main distribution board (MDB) & meter | B28: 800
A29: Sub-distribution boards (1 per 2 floors × 5) | B29: 750
A30: Cabling & rising mains distribution | B30: 1200
A31: Earthing & protection | B31: 400
A32: Site lighting installation | B32: 600
A33: Removal at completion | B33: 250
A34: ONE-TIME TOTAL → Z.01.07.01 | B34: =SUM(B27:B33) -> 5500
A36: B. TEMPORARY WATER
A37: B1. One-Time Installation & Removal
A38: Description | B38: Amount ($)
A39: PPWSA connection & meter | B39: 600
A40: Storage tanks 2 × 5 m³ | B40: 500
A41: Booster pump & piping to floors | B41: 700
A42: Removal at completion | B42: 100
A43: ONE-TIME TOTAL → Z.01.07.03 | B43: =SUM(B39:B42) -> 1900
A45: B2. Monthly Demand & Cost
...

Sheet BU Z.01.01
A1: Z.01.01 SITE PREPARATION — Build-Ups
A2: Yellow = input (Phnom Penh benchmarks — replace with quotations). Green = linked from Site Data.
A4: Z.01.01.01 | B4: Mobilization (total per Item)
A5: Component | B5: Qty | C5: Unit | D5: Rate ($) | E5: Amount ($)
A6: Low-bed & truck transport trips (plant in) | B6: 12 | C6: trip | D6: 400 | E6: =B6*D6 -> 4800
A7: Crane lifts for site establishment | B7: 4 | C7: lift | D7: 300 | E7: =B7*D7 -> 1200
A8: Site setup labor | B8: 100 | C8: man-day | D8: 12 | E8: =B8*D8 -> 1200
A9: Utility applications & administration | B9: 1 | C9: lot | D9: 1000 | E9: =B9*D9 -> 1000
A10: Storage yard & hardstand setup | B10: 1 | C10: lot | D10: 1500 | E10: =B10*D10 -> 1500
A11: Survey control points establishment | B11: 1 | C11: lot | D11: 800 | E11: =B11*D11 -> 800
B12: Build-up total → Z.01.01.01 | E12: =SUM(E6:E11) -> 10500
A14: Z.01.01.02 | B14: Demobilization & site clearance (total per Item)
A15: Component | B15: Qty | C15: Unit | D15: Rate ($) | E15: Amount ($)
A16: Transport trips out (plant removal) | B16: 10 | C16: trip | D16: 400 | E16: =B16*D16 -> 4000
A17: Dismantling labor | B17: 80 | C17: man-day | D17: 12 | E17: =B17*D17 -> 960
A18: Site reinstatement & final clearance | B18: 1 | C18: lot | D18: 1500 | E18: =B18*D18 -> 1500
B19: Build-up total → Z.01.01.02 | E19: =SUM(E16:E18) -> 6460
A21: Z.01.01.03 | B21: Temporary access & roads (total per Item)
A22: Component | B22: Qty | C22: Unit | D22: Rate ($) | E22: Amount ($)
A23: Laterite/gravel access road | B23: 300 | C23: m2 | D23: 18 | E23: =B23*D23 -> 5400
A24: Hardstand at loading/unloading area | B24: 100 | C24: m2 | D24: 20 | E24: =B24*D24 -> 2000
B25: Build-up total → Z.01.01.03 | E25: =SUM(E23:E24) -> 7400
A27: Z.01.01.04 | B27: Setting out & ongoing survey works (rate per Month)
A28: Component | B28: Qty | C28: Unit | D28: Rate ($) | E28: Amount ($)
A29: Total station & level rental | B29: 1 | C29: mo | D29: 250 | E29: =B29*D29 -> 250
A30: Pegs, paint, consumables | B30: 1 | C30: mo | D30: 60 | E30: =B30*D30 -> 60
A31: Periodic verification survey | B31: 1 | C31: mo | D31: 90 | E31: =B31*D31 -> 90
B32: Build-up total → Z.01.01.04 | E32: =SUM(E29:E31) -> 400
A34: Z.01.01.05 | B34: Site signage & project board (total per Item)
A35: Component | B35: Qty | C35: Unit | D35: Rate ($) | E35: Amount ($)
A36: Project board 3m x 2m incl. frame | B36: 1 | C36: no | D36: 500 | E36: =B36*D36 -> 500
A37: Safety & directional signage | B37: 1 | C37: lot | D37: 300 | E37: =B37*D37 -> 300
B38: Build-up total → Z.01.01.05 | E38: =SUM(E36:E37) -> 800
A40: Z.01.01.06 | B40: Traffic management & road occupation (total per Item)
A41: Component | B41: Qty | C41: Unit | D41: Rate ($) | E41: Amount ($)
A42: Flagmen during concrete pours | B42: 60 | C42: man-day | D42: 15 | E42: =B42*D42 -> 900
A43: Road occupation permits | B43: 6 | C43: no | D43: 250 | E43: =B43*D43 -> 1500
A44: Cones, barriers, warning lights | B44: 1 | C44: lot | D44: 600 | E44: =B44*D44 -> 600
B45: Build-up total → Z.01.01.06 | E45: =SUM(E42:E44) -> 3000

Sheet BU Z.01.02
A1: Z.01.02 GENERAL PROTECTION — Build-Ups
A2: Yellow = input (Phnom Penh benchmarks — replace with quotations). Green = linked from Site Data.
A4: Z.01.02.01 | B4: Temporary fencing & hoarding (total per Item)
A5: Component | B5: Qty | C5: Unit | D5: Rate ($) | E5: Amount ($)
A6: Corrugated hoarding 2.4m high on site perimeter | B6: ='Site Data'!C5 -> 130 | C6: m | D6: 55 | E6: =B6*D6 -> 7150
A7: Double gates | B7: 2 | C7: no | D7: 400 | E7: =B7*D7 -> 800
B8: Build-up total → Z.01.02.01 | E8: =SUM(E6:E7) -> 7950
A10: Z.01.02.02 | B10: Temporary sheet pile, length 6m (rate per m)
A11: Component | B11: Qty | C11: Unit | D11: Rate ($) | E11: Amount ($)
A12: Drive & extract (subcontract) | B12: 1 | C12: m | D12: 140 | E12: =B12*D12 -> 140
A13: Rental during excavation (4 months) | B13: 4 | C13: m-mo | D13: 10 | E13: =B13*D13 -> 40
B14: Build-up total → Z.01.02.02 | E14: =SUM(E12:E13) -> 180
A16: Z.01.02.03 | B16: Safety net to building perimeter (total per Item)
A17: Component | B17: Qty | C17: Unit | D17: Rate ($) | E17: Amount ($)
A18: Net band, 2 lifts rotating up building | B18: 1400 | C18: m2 | D18: 4 | E18: =B18*D18 -> 5600
A19: Installation & shifting labor | B19: 1 | C19: lot | D19: 400 | E19: =B19*D19 -> 400
B20: Build-up total → Z.01.02.03 | E20: =SUM(E18:E19) -> 6000
A22: Z.01.02.04 | B22: Edge protection & handrails (rate per Floor)
A23: Component | B23: Qty | C23: Unit | D23: Rate ($) | E23: Amount ($)
A24: Guardrail to slab edge (building perimeter) | B24: ='Site Data'!C7 -> 115 | C24: m | D24: 5 | E24: =B24*D24 -> 575
A25: Posts, fixing & shifting labor | B25: 1 | C25: floor | D25: 125 | E25: =B25*D25 -> 125
B26: Build-up total → Z.01.02.04 | E26: =SUM(E24:E25) -> 700
A28: Z.01.02.05 | B28: Protection of completed works (total per Item)
A29: Component | B29: Qty | C29: Unit | D29: Rate ($) | E29: Amount ($)
A30: Floor/lobby/stair protection sheeting | B30: 600 | C30: m2 | D30: 5 | E30: =B30*D30 -> 3000
A31: Corner guards, tapes, miscellaneous | B31: 1 | C31: lot | D31: 1000 | E31: =B31*D31 -> 1000
B32: Build-up total → Z.01.02.05 | E32: =SUM(E30:E31) -> 4000
A34: Z.01.02.06 | B34: Monsoon protection & site drainage (rate per Month)
A35: Component | B35: Qty | C35: Unit | D35: Rate ($) | E35: Amount ($)
A36: Submersible pumps rental | B36: 2 | C36: no | D36: 60 | E36: =B36*D36 -> 120
A37: Sandbags & drainage channels | B37: 1 | C37: mo | D37: 80 | E37: =B37*D37 -> 80
A38: Attendance labor | B38: 1 | C38: mo | D38: 50 | E38: =B38*D38 -> 50
B39: Build-up total → Z.01.02.06 | E39: =SUM(E36:E38) -> 250
A41: Z.01.02.07 | B41: Dewatering during substructure (rate per Month)
A42: Component | B42: Qty | C42: Unit | D42: Rate ($) | E42: Amount ($)
A43: Dewatering pumps rental | B43: 2 | C43: no | D43: 150 | E43: =B43*D43 -> 300
A44: Fuel / power | B44: 1 | C44: mo | D44: 300 | E44: =B44*D44 -> 300
A45: Standby attendance | B45: 1 | C45: mo | D45: 300 | E45: =B45*D45 -> 300
B46: Build-up total → Z.01.02.07 | E46: =SUM(E43:E45) -> 900

Sheet BU Z.01.03
A1: Z.01.03 TEMPORARY BUILDING — Build-Ups
A2: Yellow = input (Phnom Penh benchmarks — replace with quotations). Green = linked from Site Data.
A4: Z.01.03.01 | B4: Site office, store & welfare (rate per Month)
A5: Component | B5: Qty | C5: Unit | D5: Rate ($) | E5: Amount ($)
A6: Office containers | B6: 3 | C6: no | D6: 250 | E6: =B6*D6 -> 750
A7: Store container | B7: 1 | C7: no | D7: 150 | E7: =B7*D7 -> 150
A8: Furniture, AC, IT (amortized) | B8: 1 | C8: mo | D8: 200 | E8: =B8*D8 -> 200
A9: Workers shelter / canteen | B9: 1 | C9: mo | D9: 100 | E9: =B9*D9 -> 100
B10: Build-up total → Z.01.03.01 | E10: =SUM(E6:E9) -> 1200
A12: Z.01.03.02 | B12: Temporary worker toilets (rate per Month)
A13: Component | B13: Qty | C13: Unit | D13: Rate ($) | E13: Amount ($)
A14: Portable toilet units | B14: 4 | C14: no | D14: 35 | E14: =B14*D14 -> 140
A15: Servicing & consumables | B15: 1 | C15: mo | D15: 60 | E15: =B15*D15 -> 60
B16: Build-up total → Z.01.03.02 | E16: =SUM(E14:E15) -> 200
A18: Z.01.03.03 | B18: First aid room & facilities (total per Item)
A19: Component | B19: Qty | C19: Unit | D19: Rate ($) | E19: Amount ($)
A20: Room fit-out | B20: 1 | C20: lot | D20: 800 | E20: =B20*D20 -> 800
A21: Equipment & initial supplies | B21: 1 | C21: lot | D21: 700 | E21: =B21*D21 -> 700
B22: Build-up total → Z.01.03.03 | E22: =SUM(E20:E21) -> 1500
A24: Z.01.03.04 | B24: Washing bay / wheel wash (total per Item)
A25: Component | B25: Qty | C25: Unit | D25: Rate ($) | E25: Amount ($)
A26: RC pad & sediment pit | B26: 1 | C26: lot | D26: 4500 | E26: =B26*D26 -> 4500
A27: Pump & water recycling system | B27: 1 | C27: lot | D27: 1500 | E27: =B27*D27 -> 1500
A28: Hoses & equipment | B28: 1 | C28: lot | D28: 500 | E28: =B28*D28 -> 500
A29: Maintenance & desilting over programme | B29: 18 | C29: mo | D29: 200 | E29: =B29*D29 -> 3600
B30: Build-up total → Z.01.03.04 | E30: =SUM(E26:E29) -> 10100

Sheet BU Z.01.04
A1: Z.01.04 TEMPORARY SITE LABOR — Build-Ups
A2: Yellow = input (Phnom Penh benchmarks — replace with quotations). Green = linked from Site Data.
A4: Z.01.04.01 | B4: Site cleaning & waste removal (rate per Month)
A5: Component | B5: Qty | C5: Unit | D5: Rate ($) | E5: Amount ($)
A6: Cleaning laborers | B6: 26 | C6: man-day | D6: 12 | E6: =B6*D6 -> 312
A7: Waste skip hire | B7: 2 | C7: no | D7: 120 | E7: =B7*D7 -> 240
A8: Tipping fees | B8: 1 | C8: mo | D8: 50 | E8: =B8*D8 -> 50
B9: Build-up total → Z.01.04.01 | E9: =SUM(E6:E8) -> 602
A11: Z.01.04.02 | B11: Final builder's clean at handover (total per Item)
A12: Component | B12: Qty | C12: Unit | D12: Rate ($) | E12: Amount ($)
A13: Builder's clean on GFA | B13: ='Site Data'!C16 -> 8000 | C13: m2 | D13: 0.35 | E13: =B13*D13 -> 2800
A14: Glass & facade cleaning | B14: 1 | C14: lot | D14: 700 | E14: =B14*D14 -> 700
B15: Build-up total → Z.01.04.02 | E15: =SUM(E13:E14) -> 3500

Sheet BU Z.01.05
A1: Z.01.05 MACHINERY & VERTICAL TRANSPORT — Build-Ups
A2: Yellow = input (Phnom Penh benchmarks — replace with quotations). Green = linked from Site Data.
A4: Z.01.05.01 | B4: Tower crane rental (rate per Month)
A5: Component | B5: Qty | C5: Unit | D5: Rate ($) | E5: Amount ($)
A6: Tower crane rental | B6: 1 | C6: mo | D6: 2800 | E6: =B6*D6 -> 2800
A7: Operator & rigger | B7: 1 | C7: mo | D7: 600 | E7: =B7*D7 -> 600
A8: Maintenance & spares | B8: 1 | C8: mo | D8: 100 | E8: =B8*D8 -> 100
B9: Build-up total → Z.01.05.01 | E9: =SUM(E6:E8) -> 3500
A11: Z.01.05.02 | B11: Tower crane foundation, erection, dismantle & test (total per Item)
A12: Component | B12: Qty | C12: Unit | D12: Rate ($) | E12: Amount ($)
A13: RC foundation base | B13: 25 | C13: m3 | D13: 220 | E13: =B13*D13 -> 5500
A14: Erection incl. mobile crane hire | B14: 1 | C14: lot | D14: 6000 | E14: =B14*D14 -> 6000
A15: Dismantling | B15: 1 | C15: lot | D15: 4500 | E15: =B15*D15 -> 4500
A16: Load test & certification | B16: 1 | C16: lot | D16: 2000 | E16: =B16*D16 -> 2000
B17: Build-up total → Z.01.05.02 | E17: =SUM(E13:E16) -> 18000
A19: Z.01.05.03 | B19: Passenger / material hoist rental (rate per Month)
A20: Component | B20: Qty | C20: Unit | D20: Rate ($) | E20: Amount ($)
A21: Hoist rental | B21: 1 | C21: mo | D21: 1200 | E21: =B21*D21 -> 1200
A22: Operator | B22: 1 | C22: mo | D22: 300 | E22: =B22*D22 -> 300
B23: Build-up total → Z.01.05.03 | E23: =SUM(E21:E22) -> 1500
A25: Z.01.05.04 | B25: Hoist erection & dismantling (total per Item)
A26: Component | B26: Qty | C26: Unit | D26: Rate ($) | E26: Amount ($)
A27: Erection & base | B27: 1 | C27: lot | D27: 2200 | E27: =B27*D27 -> 2200
A28: Dismantling | B28: 1 | C28: lot | D28: 1300 | E28: =B28*D28 -> 1300
A29: Test & certification | B29: 1 | C29: lot | D29: 500 | E29: =B29*D29 -> 500
B30: Build-up total → Z.01.05.04 | E30: =SUM(E27:E29) -> 4000
A32: Z.01.05.06 | B32: External scaffolding to facade (rate per m2)
A33: Component | B33: Qty | C33: Unit | D33: Rate ($) | E33: Amount ($)
A34: Erection & dismantling | B34: 1 | C34: m2 | D34: 3 | E34: =B34*D34 -> 3
A35: Rental over scaffold duration (P09 months) | B35: ='Site Data'!C13 -> 12 | C35: m2-mo | D35: 0.35 | E35: =B35*D35 -> 4.2
B36: Build-up total → Z.01.05.06 | E36: =SUM(E34:E35) -> 7.2
A38: Z.01.05.07 | B38: Back-propping / falsework for PT slabs (rate per Floor)
A39: Component | B39: Qty | C39: Unit | D39: Rate ($) | E39: Amount ($)
A40: Adjustable props rental (400 no x 2-month cycle) | B40: 800 | C40: prop-mo | D40: 1.2 | E40: =B40*D40 -> 960
A41: Install & strike labor | B41: 20 | C41: man-day | D41: 12 | E41: =B41*D41 -> 240
B42: Build-up total → Z.01.05.07 | E42: =SUM(E40:E41) -> 1200

Sheet BU Z.01.06
A1: Z.01.06 LIGHT EQUIPMENT & HAND TOOLS — Build-Up
A2: Yellow = input (Phnom Penh benchmarks — replace with quotations). Green = linked from Site Data.
A4: Z.01.06.01 | B4: Small plant, light equipment & hand tools (rate per Month)
A5: Component | B5: Qty | C5: Unit | D5: Rate ($) | E5: Amount ($)
A6: Concrete mixers | B6: 2 | C6: no | D6: 50 | E6: =B6*D6 -> 100
A7: Cutting & grinding equipment | B7: 1 | C7: mo | D7: 80 | E7: =B7*D7 -> 80
A8: Power tools replacement allowance | B8: 1 | C8: mo | D8: 100 | E8: =B8*D8 -> 100
A9: Consumables (discs, bits, blades) | B9: 1 | C9: mo | D9: 70 | E9: =B9*D9 -> 70
B10: Build-up total → Z.01.06.01 | E10: =SUM(E6:E9) -> 350

Sheet BU Z.01.08
A1: Z.01.08 SAFETY & ENVIRONMENT CONTROL — Build-Ups
A2: Yellow = input (Phnom Penh benchmarks — replace with quotations). Green = linked from Site Data.
A4: Z.01.08.01 | B4: Health, safety provisions & PPE (rate per Month)
A5: Component | B5: Qty | C5: Unit | D5: Rate ($) | E5: Amount ($)
A6: PPE issue & replacement (per peak workforce) | B6: ='Site Data'!C14 -> 80 | C6: worker | D6: 4 | E6: =B6*D6 -> 320
A7: First-aid consumables | B7: 1 | C7: mo | D7: 30 | E7: =B7*D7 -> 30
A8: Toolbox training & safety officer support | B8: 1 | C8: mo | D8: 100 | E8: =B8*D8 -> 100
A9: Safety signage & miscellaneous | B9: 1 | C9: mo | D9: 50 | E9: =B9*D9 -> 50
B10: Build-up total → Z.01.08.01 | E10: =SUM(E6:E9) -> 500
A12: Z.01.08.02 | B12: Site security incl. guards & CCTV (rate per Month)
A13: Component | B13: Qty | C13: Unit | D13: Rate ($) | E13: Amount ($)
A14: Security guards (day/night rotation) | B14: 3 | C14: no | D14: 250 | E14: =B14*D14 -> 750
A15: CCTV system (amortized) | B15: 1 | C15: mo | D15: 100 | E15: =B15*D15 -> 100
A16: Security lighting power | B16: 1 | C16: mo | D16: 50 | E16: =B16*D16 -> 50
B17: Build-up total → Z.01.08.02 | E17: =SUM(E14:E16) -> 900
A19: Z.01.08.03 | B19: Material & concrete testing (QA/QC) (total per Item)
A20: Component | B20: Qty | C20: Unit | D20: Rate ($) | E20: Amount ($)
A21: Concrete cube test sets | B21: 300 | C21: set | D21: 15 | E21: =B21*D21 -> 4500
A22: Rebar tensile tests | B22: 40 | C22: no | D22: 30 | E22: =B22*D22 -> 1200
A23: Soil / compaction tests | B23: 1 | C23: lot | D23: 800 | E23: =B23*D23 -> 800
A24: Other / miscellaneous tests | B24: 1 | C24: lot | D24: 1500 | E24: =B24*D24 -> 1500
B25: Build-up total → Z.01.08.03 | E25: =SUM(E21:E24) -> 8000

Sheet BU Z.50
A1: Z.50 DESIGN EXPENSES — Build-Ups
A2: Yellow = input (Phnom Penh benchmarks — replace with quotations). Green = linked from Site Data.
A4: Z.50.01 | B4: Shop drawings (total per Item)
A5: Component | B5: Qty | C5: Unit | D5: Rate ($) | E5: Amount ($)
A6: Draftsmen (2 no. x 10 months) | B6: 20 | C6: man-mo | D6: 450 | E6: =B6*D6 -> 9000
A7: Plotting & printing | B7: 1 | C7: lot | D7: 1000 | E7: =B7*D7 -> 1000
B8: Build-up total → Z.50.01 | E8: =SUM(E6:E7) -> 10000
A10: Z.50.02 | B10: As-built drawings (total per Item)
A11: Component | B11: Qty | C11: Unit | D11: Rate ($) | E11: Amount ($)
A12: Draftsman (1 no. x 10 months) | B12: 10 | C12: man-mo | D12: 500 | E12: =B12*D12 -> 5000
A13: Printing & binding | B13: 1 | C13: lot | D13: 1000 | E13: =B13*D13 -> 1000
B14: Build-up total → Z.50.02 | E14: =SUM(E12:E13) -> 6000
A16: Z.50.03 | B16: Temporary works design (total per Item)
A17: Component | B17: Qty | C17: Unit | D17: Rate ($) | E17: Amount ($)
A18: Crane base design & check | B18: 1 | C18: lot | D18: 1500 | E18: =B18*D18 -> 1500
A19: Sheet pile / shoring design | B19: 1 | C19: lot | D19: 1500 | E19: =B19*D19 -> 1500
A20: Back-propping & formwork scheme | B20: 1 | C20: lot | D20: 1500 | E20: =B20*D20 -> 1500
A21: Documentation & submissions | B21: 1 | C21: lot | D21: 500 | E21: =B21*D21 -> 500
B22: Build-up total → Z.50.03 | E22: =SUM(E18:E21) -> 5000

Sheet Budget Code
A1: BUDGET CODE
A2: Section | B2: Code | D2: Description
A3: Early Work | B3: A.00 | C3: A.Early Work
A4: Topography Survey | B4: A.01 | C4: A.01.Topography Survey
A5: Soil Investigation | B5: A.02 | C5: A.02.Soil Investigation
A6: Mine / UXO Clearance | B6: A.03 | C6: A.03.Mine / UXO Clearance
A7: Soil Leveling | B7: A.04 | C7: A.04.Soil Leveling
A8: Demolition | B8: A.05 | C8: A.05.Demolition
A9: Cleaning | B9: A.06 | C9: A.06.Cleaning
A10: Repair exiting services | B10: A.07 | C10: A.07.Repair exiting services
A11: Renovation | B11: A.08 | C11: A.08.Renovation
A12: Sub Structure | B12: B.00 | C12: B.0.Sub Structure
A13: Piling Work | B13: B.01 | C13: B.01.Piling Work
A14: Basement | B14: B.02 | C14: B.02.Basement
... A17: Architecture | B17: C.00 | C17: C.0.Architecture
A18: Exterior Wall and Partition | B18: C.01 | C18: C.01.Exterior Wall and Partition | D18: Masonry Wall, Dry Wall, Glass partition
A19: Exterior Wall Finishes | B19: C.02 | C19: C.02.Exterior Wall Finishes | D19: Plastering, painting, cladding, molding
A20: Exterior Door | B20: C.03 | C20: C.03.Exterior Door | D20: Wooden door, Glass door, Steel door
A21: Exterior Window and Louver | B21: C.04 | C21: C.04.Exterior Window and Louver | D21: Glass window, window fence, steel louver
A22: Exterior floor | B22: C.05 | C22: C.05.Exterior floor | D22: Screeding, floor tiling, hardening, Waterproofing
A23: Exterior soffit | B23: C.06 | C23: C.06.Exterior soffit | D23: Soffit slab finish
A24: Exterior Stair Ramp | B24: C.07 | C24: C.07.Exterior Stair Ramp | D24: Barrier, ramp
A25: Roofing | B25: C.08 | C25: C.08.Roofing
A26: Interior Wall and Partition | B26: C.09 | C26: C.09.Interior Wall Partition | D26: Masonry Wall, Dry Wall, Glass partition
A27: Interior Doors | B27: C.10 | C27: C.10.Interior Door /Windows and Louvers | D27: Steel door, wooden door, glass door
A28: Special installation | B28: C.11 | C28: C.11.Special installation | D28: LPG Gas
A29: Exterior Finishes | B29: C.12 | C29: C.12.Exterior Finishes | D29: Plastering, painting, cladding, molding
A30: Interior Finish | B30: D.00 | C30: D.0.Interior Finish
A31: Interior Wall Finishes | B31: D.01 | C31: D.01.Interior Wall Finishes | D31: Wall tiling, Plastering, Painting, Skirting, Wall Marble
A32: Interior Floor Finishes | B32: D.02 | C32: D.02.Interior Floor Finishes | D32: Screeding, floor tiling, Wooden Flooring, Marble flooring, Carpet Flooring, Epoxy Flooring, waterproofing, Floor strip divider
A33: Ceiling Finishes | B33: D.03 | C33: D.03.Ceiling Finish | D33: Suspended Ceiling
A34: Fittings, furnishings and equipment | B34: E.00 | C34: E.0.Fitting, furnishings and equipment
A35: General Fitting | B35: E.01 | C35: E.01.General Fitting
A36: Domestic Kitchen Fitting | B36: E.02 | C36: E.02.Domestic Kitchen Fitting
A37: Special purpose Fitting | B37: E.03 | C37: E.03.Special purpose Fitting
A38: Signage | B38: E.04 | C38: E.04.Signage
A39: Art | B39: E.05 | C39: E.05.Art
A40: Non-Mechanical and Non Electrical Equipement | B40: E.06 | C40: E.06.Non-Mechanical and Non Electrical Equipement
A41: Internal Planting | B41: E.07 | C41: E.07.Internal Planting
A42: Bird and Vermin Control | B42: E.08 | C42: E.08.Bird and Vermin Control
...

Sheet Sheet1
A2: slab | B2: 68 | C2: 0.2 | D2: =B2*C2 -> 13.6 | E2: 2 | F2: =D2*E2 -> 27.2
A3: wall | B3: =60*3.2 -> 192 | C3: 0.2 | D3: =B3*C3 -> 38.4 | E3: 1 | F3: =D3*E3 -> 38.4
F4: =SUM(F2:F3) -> 65.6
A5: wall | B5: 60 | C5: 3.2 | D5: 2 | E5: =B5*C5*D5 -> 384
A6: slab | E6: =86*2 -> 172
E7: =E5+E6 -> 556

Sheet main truss
A1: ID | B1: Truss Name | C1: Number of Truss (pcs) | D1: Steel section Name | E1: Number of steel (pcs) | F1: Length per pcs (m) | G1: Total Length (m)
A2: 1 | B2: Truss 01 | C2: 3 | D2: U-50*100*5mm | E2: 2 | F2: 9.33 | G2: =F2*E2*C2 -> 55.98
A3: 2 | B3: Truss 01 | C3: 3 | D3: U-50*100*5mm | E3: 2 | F3: 5.57 | G3: =F3*E3*C3 -> 33.42
A4: 3 | B4: Truss 01 | C4: 3 | D4: U-50*100*5mm | E4: 1 | F4: 5.55 | G4: =F4*E4*C4 -> 16.65
A5: 4 | B5: Truss 01 | C5: 3 | D5: U-50*100*5mm | E5: 2 | F5: 1.38 | G5: =F5*E5*C5 -> 8.28
A6: 5 | B6: Truss 01 | C6: 3 | D6: U-50*100*5mm | E6: 2 | F6: 0.139 | G6: =F6*E6*C6 -> 0.834
A7: 6 | B7: Truss 01 | C7: 3 | D7: U-50*100*5mm | E7: 1 | F7: 1.93 | G7: =F7*E7*C7 -> 5.79
A8: 7 | B8: Truss 01 | C8: 3 | D8: U-50*100*5mm | E8: 2 | F8: 1.64 | G8: =F8*E8*C8 -> 9.84
A9: 8 | B9: Truss 01 | C9: 3 | D9: U-50*100*5mm | E9: 2 | F9: 1.42 | G9: =F9*E9*C9 -> 8.52
A10: 9 | B10: Truss 01 | C10: 3 | D10: U-50*100*5mm | E10: 2 | F10: 1.27 | G10: =F10*E10*C10 -> 7.62
A11: 10 | B11: Truss 01 | C11: 3 | D11: U-50*100*5mm | E11: 2 | F11: 1.1 | G11: =F11*E11*C11 -> 6.6
A12: 11 | B12: Truss 01 | C12: 3 | D12: U-50*100*5mm | E12: 2 | F12: 0.95 | G12: =F12*E12*C12 -> 5.7
A13: 12 | B13: Truss 01 | C13: 3 | D13: U-50*100*5mm | E13: 2 | F13: 0.63 | G13: =F13*E13*C13 -> 3.78
... A77: 76 | B77: Purlin | C77: 1 | D77: Tub-50*100*2mm | E77: 1 | F77: 83.6 | G77: =F77*E77*C77 -> 83.6
J82: U-50*100*5mm | K82: =SUM(G2:G65) -> 775.88
J83: Tub-50*100*2mm | K83: =SUM(G66:G77) -> 691.58

Sheet Level
A1: Code | B1: Name | C1: Combine
A2: 01.UG | B2: Under Ground | C2: =_xlfn.CONCAT(A2,"-",B2) -> 01.UG-Under Ground
A3: 02.GF | B3: Ground Floor | C3: =_xlfn.CONCAT(A3,"-",B3) -> 02.GF-Ground Floor
A4: 03.MZ | B4: Mezzanine Floor | C4: =_xlfn.CONCAT(A4,"-",B4) -> 03.MZ-Mezzanine Floor
A5: 04.L01 | B5: L01 Floor | C5: =_xlfn.CONCAT(A5,"-",B5) -> 04.L01-L01 Floor
A6: 05.L02 | B6: L02 Floor | C6: =_xlfn.CONCAT(A6,"-",B6) -> 05.L02-L02 Floor
A7: 06.L03 | B7: L03 Floor | C7: =_xlfn.CONCAT(A7,"-",B7) -> 06.L03-L03 Floor
A8: 07.L04 | B8: L04 Floor | C8: =_xlfn.CONCAT(A8,"-",B8) -> 07.L04-L04 Floor
A9: 08.L05 | B9: L05 Floor | C9: =_xlfn.CONCAT(A9,"-",B9) -> 08.L05-L05 Floor
A10: 09.L06 | B10: L06 Floor | C10: =_xlfn.CONCAT(A10,"-",B10) -> 09.L06-L06 Floor
A11: 10.L07 | B11: L07 Floor | C11: =_xlfn.CONCAT(A11,"-",B11) -> 10.L07-L07 Floor
A12: 11.L08 | B12: L08 Floor | C12: =_xlfn.CONCAT(A12,"-",B12) -> 11.L08-L08 Floor
A13: 12.L09 | B13: L09 Floor | C13: =_xlfn.CONCAT(A13,"-",B13) -> 12.L09-L09 Floor
... A16: 05.LRF | B16: Roof Floor | C16: =_xlfn.CONCAT(A16,"-",B16) -> 05.LRF-Roof Floor

Sheet ground beam
A1: level | B1: Beam Name | C1: Beam width (m) | D1: Beam Height (m) | E1: Beam Length (m) | F1: Slab thickness (m) | G1: Formwork (m2) | H1: Concrete (m3) | I1: lean (m3) | J1: crush stone | K1: area | L1: Main bar dia | M1: Main bar (amount) | N1: weight (kg) | O1: stirrup | P1: length(m) | Q1: amount stirrup(pcs) | R1: weight (kg) | S1: side bar dia | T1: side bar (amount) | U1: weight (kg)
A2: GF | B2: B1(250x400) | C2: 0.25 | D2: 0.4 | E2: 56 | F2: 0.15 | G2: =((C2+0.2)+(D2-F2)*2)*E2 -> 53.2 | H2: =C2*(D2-F2)*E2 -> 3.5 | I2: =(C2+0.2)*E2*0.05 -> 1.26 | J2: =(C2+0.2)*E2*0.1 -> 2.52 | K2: =(C2+0.2)*E2 -> 25.2 | L2: 16 | M2: 6 | N2: =1.578*M2*E2 -> 530.208 | O2: 8 | P2: 1.2 | Q2: =E2/0.15 -> 373.33333 | R2: =0.395*P2*Q2 -> 176.96
A3: GF | B3: B2(250x500) | C3: 0.25 | D3: 0.5 | E3: 10.3 | F3: 0.2 | G3: =((C3+0.2)+(D3-F3)*2)*E3 -> 10.815 | H3: =C3*(D3-F3)*E3 -> 0.7725 | I3: =(C3+0.2)*E3*0.05 -> 0.23175 | J3: =(C3+0.2)*E3*0.1 -> 0.4635 | K3: =(C3+0.2)*E3 -> 4.635 | L3: 16 | M3: 8 | N3: =1.578*M3*E3 -> 130.0272 | O3: 8 | P3: =1.4+0.4 -> 1.8 | Q3: =E3/0.15 -> 68.666667 | R3: =0.395*P3*Q3 -> 48.822 | S3: 12 | T3: 2 | U3: =0.888*T3*E3 -> 18.2928
A4: GF | B4: B3(300x500) | C4: 0.3 | D4: 0.5 | E4: 40 | F4: 0.15 | G4: =((C4+0.2)+(D4-F4)*2)*E4 -> 48 | H4: =C4*(D4-F4)*E4 -> 4.2 | I4: =(C4+0.2)*E4*0.05 -> 1 | J4: =(C4+0.2)*E4*0.1 -> 2 | K4: =(C4+0.2)*E4 -> 20 | L4: 20 | M4: 8 | N4: =2.466*M4*E4 -> 789.12 | O4: 8 | P4: =1.4+0.64+0.44 -> 2.48 | Q4: =E4/0.15 -> 266.66667 | R4: =0.395*P4*Q4 -> 261.22667 | S4: 12 | T4: 2 | U4: =0.888*T4*E4 -> 71.04
A5: GF | B5: B4(300x600) | C5: 0.3 | D5: 0.6 | E5: 7.75 | F5: 0.2 | G5: =((C5+0.2)+(D5-F5)*2)*E5 -> 10.075 | H5: =C5*(D5-F5)*E5 -> 0.93 | I5: =(C5+0.2)*E5*0.05 -> 0.19375 | J5: =(C5+0.2)*E5*0.1 -> 0.3875 | K5: =(C5+0.2)*E5 -> 3.875 | L5: 20 | M5: 10 | N5: =2.466*M5*E5 -> 191.115 | O5: 10 | P5: =1.6+0.75+0.5+0.5 -> 3.35 | Q5: =E5/0.15 -> 51.666667 | R5: =0.617*P5*Q5 -> 106.79242 | S5: 12 | T5: 2 | U5: =0.888*T5*E5 -> 13.764
A6: GF | B6: B5(400x600) | C6: 0.4 | D6: 0.6 | E6: 40.1 | F6: 0.2 | G6: =((C6+0.2)+(D6-F6)*2)*E6 -> 56.14 | H6: =C6*(D6-F6)*E6 -> 6.416 | I6: =(C6+0.2)*E6*0.05 -> 1.203 | J6: =(C6+0.2)*E6*0.1 -> 2.406 | K6: =(C6+0.2)*E6 -> 24.06 | L6: 20 | M6: 10 | N6: =2.466*M6*E6 -> 988.866 | O6: 10 | P6: =1.8+1.4+0.6+0.6 -> 4.4 | Q6: =E6/0.15 -> 267.33333 | R6: =0.617*P6*Q6 -> 725.75653 | S6: 12 | T6: 2 | U6: =0.888*T6*E6 -> 71.2176
A7: GF | B7: B6(400x700) | C7: 0.4 | D7: 0.7 | E7: 113 | F7: 0.2 | G7: =((C7+0.2)+(D7-F7)*2)*E7 -> 180.8 | H7: =C7*(D7-F7)*E7 -> 22.6 | I7: =(C7+0.2)*E7*0.05 -> 3.39 | J7: =(C7+0.2)*E7*0.1 -> 6.78 | K7: =(C7+0.2)*E7 -> 67.8 | L7: 20 | M7: 12 | N7: =2.466*M7*E7 -> 3343.896 | O7: 10 | P7: =1.8+1.4+0.6+0.6 -> 4.4 | Q7: =E7/0.15 -> 753.33333 | R7: =0.617*P7*Q7 -> 2045.1493 | S7: 16 | T7: 2 | U7: =1.578*T7*E7 -> 356.628
A8: GF | B8: B7(200x400) | C8: 0.2 | D8: 0.4 | E8: 0 | F8: 0.2 | G8: =((C8+0.2)+(D8-F8)*2)*E9 -> 0 | H8: =C8*(D8-F8)*E9 -> 0 | I8: =(C8+0.2)*E8*0.05 -> 0 | J8: =(C8+0.2)*E8*0.1 -> 0 | K8: =(C8+0.2)*E8 -> 0
A9: GF | B9: B8(400x700) | C9: 0.4 | D9: 0.7 | E9: 0 | F9: 0.2 | G9: =((C9+0.2)+(D9-F9)*2)*E10 -> 0 | H9: =C9*(D9-F9)*E10 -> 0 | I9: =(C9+0.2)*E9*0.05 -> 0 | J9: =(C9+0.2)*E9*0.1 -> 0 | K9: =(C9+0.2)*E9 -> 0
G10: =SUM(G2:G9) -> 359.03 | H10: =SUM(H2:H9) -> 38.4185 | I10: =SUM(I2:I9) -> 7.2785 | J10: =SUM(J2:J9) -> 14.557 | K10: =SUM(K2:K9) -> 145.57
L13: 8 | M13: =R2+R3+R4 -> 487.00867 | O13: =M13/$H$10 -> 12.67641
L14: 10 | M14: =Q5+Q6+Q7 -> 1072.3333 | O14: =M14/$H$10 -> 27.9119
L15: 12 | M15: =U3+U4+U5+U6 -> 174.3144 | O15: =M15/$H$10 -> 4.5372516
L16: 16 | M16: =U7+N2+N3 -> 1016.8632 | O16: =M16/$H$10 -> 26.468061
L17: 20 | M17: =N4+N5+N6+N7 -> 5312.997 | O17: =M17/$H$10 -> 138.29267

Sheet mz beam
A1: Beam information
A2: level | B2: Beam Name | C2: Beam width (m) | D2: Beam Height (m) | E2: Beam Length (m) | F2: Slab thickness (m) | G2: Formwork (m2) | H2: Concrete (m3) | I2: Main bar dia | J2: Main bar (amount) | K2: weight (kg) | L2: stirrup | M2: length(m) | N2: amount stirrup(pcs) | O2: weight (kg) | P2: hook | Q2: length(m) | R2: amount stirrup(pcs) | S2: weight (kg) | T2: side bar dia | U2: side bar (amount) | V2: weight (kg)
A3: MZ | B3: B1(250x400) | C3: 0.25 | D3: 0.4 | E3: 79 | F3: 0.15 | G3: =((C3+0.2)+(D3-F3)*2)*E3 -> 75.05 | H3: =C3*(D3-F3)*E3 -> 4.9375 | I3: 16 | J3: 6 | K3: =J3*E3*'rebar weight'!G4 -> 747.972 | L3: 8 | M3: 1.2 | N3: =E3/0.15 -> 526.66667 | O3: =M3*N3*'rebar weight'!C4 -> 249.64 | P3: 0 | Q3: 0 | R3: =E3/0.15 -> 526.66667 | S3: =0.395*Q3*R3 -> 0 | T3: 0 | U3: 0 | V3: ='rebar weight'!E3*U3*E3 -> 0
A4: MZ | B4: B2(250x500) | C4: 0.25 | D4: 0.5 | E4: 28 | F4: 0.15 | G4: =((C4+0.2)+(D4-F4)*2)*E4 -> 32.2 | H4: =C4*(D4-F4)*E4 -> 2.45 | I4: 16 | J4: 10 | K4: ='rebar weight'!G4*J4*E4 -> 441.84 | L4: 8 | M4: =1.4 -> 1.4 | N4: =E4/0.15 -> 186.66667 | O4: =0.395*M4*N4 -> 103.22667 | P4: 8 | Q4: =0.4 -> 0.4 | R4: =E4/0.15 -> 186.66667 | S4: =0.395*Q4*R4 -> 29.493333 | T4: 12 | U4: 2 | V4: ='rebar weight'!E4*U4*E4 -> 49.728
A5: MZ | B5: B3(300x500) | C5: 0.3 | D5: 0.5 | E5: 12 | F5: 0.15 | G5: =((C5+0.2)+(D5-F5)*2)*E5 -> 14.4 | H5: =C5*(D5-F5)*E5 -> 1.26 | I5: 20 | J5: 10 | K5: ='rebar weight'!H4*J5*E5 -> 295.92 | L5: 8 | M5: =1.5 -> 1.5 | N5: =E5/0.15 -> 80 | O5: ='rebar weight'!C4*M5*N5 -> 47.4 | P5: 8 | Q5: =0.64+0.5 -> 1.14 | R5: =E5/0.15 -> 80 | S5: =0.395*Q5*R5 -> 36.024 | T5: 12 | U5: 2 | V5: =0.888*U5*E5 -> 21.312
A6: MZ | B6: B4(300x600) | C6: 0 | D6: 0 | E6: 0 | F6: 0.15 | G6: =((C6+0.2)+(D6-F6)*2)*E6 -> 0 | H6: =C6*(D6-F6)*E6 -> 0 | I6: 20 | J6: 10 | K6: =2.466*J6*E6 -> 0 | L6: 10 | M6: =1.6+0.75+0.5+0.5 -> 3.35 | N6: =E6/0.15 -> 0 | O6: =0.617*M6*N6 -> 0 | P6: 10 | Q6: =1.6+0.75+0.5+0.5 -> 3.35 | R6: =E6/0.15 -> 0 | S6: =0.617*Q6*R6 -> 0 | T6: 12 | U6: 2 | V6: =0.888*U6*E6 -> 0
A7: MZ | B7: B5(400x600) | C7: 0.4 | D7: 0.6 | E7: 42 | F7: 0.15 | G7: =((C7+0.2)+(D7-F7)*2)*E7 -> 63 | H7: =C7*(D7-F7)*E7 -> 7.56 | I7: 20 | J7: 16 | K7: ='rebar weight'!H4*J7*E7 -> 1657.152 | L7: 10 | M7: =2+1.5 -> 3.5 | N7: =E7/0.15 -> 280 | O7: =0.617*M7*N7 -> 604.66 | P7: 10 | Q7: =0.6+0.6 -> 1.2 | R7: =E7/0.3 -> 140 | S7: =0.617*Q7*R7 -> 103.656 | T7: 16 | U7: 2 | V7: ='rebar weight'!G4*U7*E7 -> 132.552
A8: MZ | B8: B6(400x700) | C8: 0.4 | D8: 0.7 | E8: 70 | F8: 0.15 | G8: =((C8+0.2)+(D8-F8)*2)*E8 -> 119 | H8: =C8*(D8-F8)*E8 -> 15.4 | I8: 25 | J8: 16 | K8: ='rebar weight'!I4*J8*E8 -> 4315.36 | L8: 10 | M8: =2+1.5 -> 3.5 | N8: =E8/0.15 -> 466.66667 | O8: =0.617*M8*N8 -> 1007.7667 | P8: 10 | Q8: =0.6+0.6 -> 1.2 | R8: =E8/0.3 -> 233.33333 | S8: =0.617*Q8*R8 -> 172.76 | T8: 16 | U8: 2 | V8: ='rebar weight'!G4*U8*E8 -> 220.92
A9: MZ | B9: B7(200x400) | C9: 0.2 | D9: 0.4 | E9: 0 | F9: 0.15 | G9: =((C9+0.2)+(D9-F9)*2)*E9 -> 0 | H9: =C9*(D9-F9)*E9 -> 0 | I9: 0 | J9: 0 | K9: =2.466*J9*E9 -> 0 | N9: =E9/0.15 -> 0 | O9: =0.617*M9*N9 -> 0 | R9: =E9/0.15 -> 0 | S9: =0.617*Q9*R9 -> 0 | V9: =1.578*U9*E9 -> 0
A10: MZ | B10: B8(400x700) | C10: 0.4 | D10: 0.7 | E10: 9.1 | F10: 0.15 | G10: =((C10+0.2)+(D10-F10)*2)*E10 -> 15.47 | H10: =C10*(D10-F10)*E10 -> 2.002 | I10: 25 | J10: 16 | K10: ='rebar weight'!I4*J10*E10 -> 560.9968 | L10: 12 | M10: =2.2+1.7 -> 3.9 | N10: =E10/0.15 -> 60.666667 | O10: ='rebar weight'!E4*M10*N10 -> 210.1008 | P10: 10 | Q10: =0.55+0.55+0.55 -> 1.65 | R10: =E10/0.3 -> 30.333333 | S10: ='rebar weight'!D4*Q10*R10 -> 30.88085 | T10: 16 | U10: 4 | V10: ='rebar weight'!G4*U10*E10 -> 57.4392
G11: =SUM(G3:G10) -> 319.12 | H11: =SUM(H3:H10) -> 33.6095
I14: 8 | J14: =O3+O4+O5+S3+S4+S5 -> 465.784 | K14: =J14/$H$11 -> 13.858701
I15: 10 | J15: =O6+O7+O8+R6+R7+R8+R9+R10 -> 2016.0933 | K15: =J15/$H$11 -> 59.985818
I16: 12 | J16: =O10+V4+V5+V6 -> 281.1408 | K16: =J16/$H$11 -> 8.3649206
I17: 16 | J17: =K3+K4+V7+V8+V10 -> 1600.7232 | K17: =J17/$H$11 -> 47.627105
I18: 20 | J18: =K5+K6+K7 -> 1953.072 | K18: =J18/$H$11 -> 58.110713
I19: 25 | J19: =K8+K10 -> 4876.3568 | K19: =J19/$H$11 -> 145.08864

Sheet rebar weight
A1: Grade of Rebar | B1: SD240 | D1: SD390
A2: Diametre ø (mm) | B2: 6 | C2: 8 | D2: 10 | E2: 12 | F2: 14 | G2: 16 | H2: 20 | I2: 25 | J2: 28 | K2: 32
A3: Area As (cm²) | B3: 0.28274334 | C3: 0.50265482 | D3: 0.78539816 | E3: 1.1309734 | F3: 1.5393804 | G3: 2.0106193 | H3: 3.1415927 | I3: 4.9087385 | J3: 6.1575216 | K3: 8.0424772
A4: Weight G (kg/m) | B4: 0.222 | C4: 0.395 | D4: 0.617 | E4: 0.888 | F4: 1.208 | G4: 1.578 | H4: 2.466 | I4: 3.853 | J4: 4.834 | K4: 6.313

Sheet 1F,2F beam
A1: Beam information
A2: level | B2: Beam Name | C2: Beam width (m) | D2: Beam Height (m) | E2: Beam Length (m) | F2: Slab thickness (m) | G2: Formwork (m2) | H2: Concrete (m3) | I2: Main bar dia | J2: Main bar (amount) | K2: weight (kg) | L2: stirrup | M2: length(m) | N2: amount stirrup(pcs) | O2: weight (kg) | P2: hook | Q2: length(m) | R2: amount stirrup(pcs) | S2: weight (kg) | T2: side bar dia | U2: side bar (amount) | V2: weight (kg)
A3: MZ | B3: B1(250x400) | C3: 0.25 | D3: 0.4 | E3: 125 | F3: 0.15 | G3: =((C3+0.2)+(D3-F3)*2)*E3 -> 118.75 | H3: =C3*(D3-F3)*E3 -> 7.8125 | I3: 16 | J3: 6 | K3: =J3*E3*'rebar weight'!G4 -> 1183.5 | L3: 8 | M3: 1.2 | N3: =E3/0.15 -> 833.33333 | O3: =M3*N3*'rebar weight'!C4 -> 395 | P3: 0 | Q3: 0 | R3: =E3/0.15 -> 833.33333 | S3: =0.395*Q3*R3 -> 0 | T3: 0 | U3: 0 | V3: ='rebar weight'!E3*U3*E3 -> 0
A4: MZ | B4: B2(250x500) | C4: 0.25 | D4: 0.5 | E4: 43 | F4: 0.15 | G4: =((C4+0.2)+(D4-F4)*2)*E4 -> 49.45 | H4: =C4*(D4-F4)*E4 -> 3.7625 | I4: 16 | J4: 10 | K4: ='rebar weight'!G4*J4*E4 -> 678.54 | L4: 8 | M4: =1.4 -> 1.4 | N4: =E4/0.15 -> 286.66667 | O4: =0.395*M4*N4 -> 158.52667 | P4: 8 | Q4: =0.4 -> 0.4 | R4: =E4/0.15 -> 286.66667 | S4: =0.395*Q4*R4 -> 45.293333 | T4: 12 | U4: 2 | V4: ='rebar weight'!E4*U4*E4 -> 76.368
A5: MZ | B5: B3(300x500) | C5: 0.3 | D5: 0.5 | E5: 3.65 | F5: 0.15 | G5: =((C5+0.2)+(D5-F5)*2)*E5 -> 4.38 | H5: =C5*(D5-F5)*E5 -> 0.38325 | I5: 20 | J5: 10 | K5: ='rebar weight'!H4*J5*E5 -> 90.009 | L5: 8 | M5: =1.5 -> 1.5 | N5: =E5/0.15 -> 24.333333 | O5: ='rebar weight'!C4*M5*N5 -> 14.4175 | P5: 8 | Q5: =0.64+0.5 -> 1.14 | R5: =E5/0.15 -> 24.333333 | S5: =0.395*Q5*R5 -> 10.9573 | T5: 12 | U5: 2 | V5: =0.888*U5*E5 -> 6.4824
A6: MZ | B6: B4(300x600) | C6: 0.3 | D6: 0.6 | E6: 1.34 | F6: 0.15 | G6: =((C6+0.2)+(D6-F6)*2)*E6 -> 1.876 | H6: =C6*(D6-F6)*E6 -> 0.1809 | I6: 20 | J6: 10 | K6: =2.466*J6*E6 -> 33.0444 | L6: 10 | M6: =1.6+0.75+0.5+0.5 -> 3.35 | N6: =E6/0.15 -> 8.9333333 | O6: =0.617*M6*N6 -> 18.464753 | P6: 10 | Q6: =1.6+0.75+0.5+0.5 -> 3.35 | R6: =E6/0.15 -> 8.9333333 | S6: =0.617*Q6*R6 -> 18.464753 | T6: 12 | U6: 2 | V6: =0.888*U6*E6 -> 2.37984
A7: MZ | B7: B5(400x600) | C7: 0.4 | D7: 0.6 | E7: 43 | F7: 0.15 | G7: =((C7+0.2)+(D7-F7)*2)*E7 -> 64.5 | H7: =C7*(D7-F7)*E7 -> 7.74 | I7: 20 | J7: 16 | K7: ='rebar weight'!H4*J7*E7 -> 1696.608 | L7: 10 | M7: =2+1.5 -> 3.5 | N7: =E7/0.15 -> 286.66667 | O7: =0.617*M7*N7 -> 619.05667 | P7: 10 | Q7: =0.6+0.6 -> 1.2 | R7: =E7/0.3 -> 143.33333 | S7: =0.617*Q7*R7 -> 106.124 | T7: 16 | U7: 2 | V7: ='rebar weight'!G4*U7*E7 -> 135.708
A8: MZ | B8: B6(400x700) | C8: 0.4 | D8: 0.7 | E8: 113 | F8: 0.15 | G8: =((C8+0.2)+(D8-F8)*2)*E8 -> 192.1 | H8: =C8*(D8-F8)*E8 -> 24.86 | I8: 25 | J8: 16 | K8: ='rebar weight'!I4*J8*E8 -> 6966.224 | L8: 10 | M8: =2+1.5 -> 3.5 | N8: =E8/0.15 -> 753.33333 | O8: =0.617*M8*N8 -> 1626.8233 | P8: 10 | Q8: =0.6+0.6 -> 1.2 | R8: =E8/0.3 -> 376.66667 | S8: =0.617*Q8*R8 -> 278.884 | T8: 16 | U8: 2 | V8: ='rebar weight'!G4*U8*E8 -> 356.628
A9: MZ | B9: B7(200x400) | C9: 0.2 | D9: 0.4 | E9: 0 | F9: 0.15 | G9: =((C9+0.2)+(D9-F9)*2)*E9 -> 0 | H9: =C9*(D9-F9)*E9 -> 0 | I9: 0 | J9: 0 | K9: =2.466*J9*E9 -> 0 | N9: =E9/0.15 -> 0 | O9: =0.617*M9*N9 -> 0 | R9: =E9/0.15 -> 0 | S9: =0.617*Q9*R9 -> 0 | V9: =1.578*U9*E9 -> 0
A10: MZ | B10: B8(400x700) | C10: 0.4 | D10: 0.7 | E10: 9.1 | F10: 0.15 | G10: =((C10+0.2)+(D10-F10)*2)*E10 -> 15.47 | H10: =C10*(D10-F10)*E10 -> 2.002 | I10: 25 | J10: 16 | K10: ='rebar weight'!I4*J10*E10 -> 560.9968 | L10: 12 | M10: =2.2+1.7 -> 3.9 | N10: =E10/0.15 -> 60.666667 | O10: ='rebar weight'!E4*M10*N10 -> 210.1008 | P10: 10 | Q10: =0.55+0.55+0.55 -> 1.65 | R10: =E10/0.3 -> 30.333333 | S10: ='rebar weight'!D4*Q10*R10 -> 30.88085 | T10: 16 | U10: 4 | V10: ='rebar weight'!G4*U10*E10 -> 57.4392
G11: =SUM(G3:G10) -> 446.526 | H11: =SUM(H3:H10) -> 46.74115
I14: 8 | J14: =O3+O4+O5+S3+S4+S5 -> 624.1948 | K14: =J14/$H$11 -> 13.354288
I15: 10 | J15: =O6+O7+O8+R6+R7+R8+R9+R10 -> 2823.6114 | K15: =J15/$H$11 -> 60.409541
I16: 12 | J16: =O10+V4+V5+V6 -> 295.33104 | K16: =J16/$H$11 -> 6.3184376
I17: 16 | J17: =K3+K4+V7+V8+V10 -> 2411.8152 | K17: =J17/$H$11 -> 51.599398
I18: 20 | J18: =K5+K6+K7 -> 1819.6614 | K18: =J18/$H$11 -> 38.930608
I19: 25 | J19: =K8+K10 -> 7527.2208 | K19: =J19/$H$11 -> 161.04056

Sheet 3F beam
A1: Beam information
