Workbook
Name A: #REF!,#REF!,#REF!
Name AAA: #REF!,#REF!,#REF!
Name ALl: #REF!
Name CHFL: #REF!
Name DHFL: #REF!
Name FLCODE: #REF!
Name JHFL: #REF!
Name LHFL: #REF!
Name LOCATION: #REF!
Name MHFL: #REF!
Name MM: #REF!,#REF!,#REF!,#REF!,#REF!,#REF!,#REF!,#REF!,#REF!,#REF!,#REF!,#REF!,#REF!,#REF!,#REF!,#REF!,#REF!,#REF!,#REF!,#REF!,#REF!,#REF!,#REF!,#REF!,#REF!,#REF!,#REF!,#REF!,#REF!,#REF!
Name PHFL: #REF!
Name PLFL: #REF!
Name Slicer_Level1: #N/A
Name Slicer_Material_Type: #N/A
Name Slicer_Material_Type1: #N/A
Name Slicer_Section1: #N/A
Name Slicer_Sub_Element: #N/A
Name Slicer_Sub_Element1: #N/A
Name Slicer_Sub_Section1: #N/A
Name test: #REF!,#REF!,#REF!,#REF!,#REF!,#REF!,#REF!,#REF!,#REF!,#REF!,#REF!,#REF!,#REF!,#REF!,#REF!,#REF!,#REF!,#REF!,#REF!,#REF!,#REF!,#REF!,#REF!,#REF!,#REF!,#REF!,#REF!,#REF!,#REF!,#REF!,#REF!,#REF!,#REF!

Sheet Site Data
A1: SITE DATA — Common Parameters (feeds all build-up sheets)
A2: Yellow = input. Items marked TO VERIFY must be checked against drawings before tender submission.
A4: Ref | B4: Parameter | C4: Value | D4: Unit | E4: Status
A5: P01 | B5: Site perimeter (hoarding line) | C5: 130 | D5: m | E5: TO VERIFY
A6: P02 | B6: Building footprint | C6: 800 | D6: m2 | E6: Given
A7: P03 | B7: Building perimeter | C7: 115 | D7: m | E7: TO VERIFY
A8: P04 | B8: Storeys above ground | C8: 10 | D8: no | E8: Given
A9: P05 | B9: Building height | C9: 36 | D9: m | E9: TO VERIFY
A10: P06 | B10: Facade area (P03 x P05) | C10: =C7*C9 -> 4140 | D10: m2 | E10: Calculated
A11: P07 | B11: Programme duration | C11: 18 | D11: months | E11: Assumed
A12: P08 | B12: Structure phase duration | C12: 10 | D12: months | E12: Assumed
A13: P09 | B13: Scaffold rental duration | C13: 12 | D13: months | E13: Assumed
A14: P10 | B14: Peak workforce | C14: 80 | D14: no | E14: Assumed
A15: P11 | B15: Floors incl. roof (edge protection) | C15: 11 | D15: no | E15: Given
A16: P12 | B16: Gross floor area (P02 x P04) | C16: =C6*C8 -> 8000 | D16: m2 | E16: Calculated

Sheet Preliminaries
A1: PRELIMINARIES & GENERAL (Z) — Fully Built-Up
A2: 10-Storey School, Phnom Penh | USD | 18-month programme | Yellow = input | Green = linked from build-up / Site Data sheets
A4: Code | B4: Description | C4: Unit | D4: Qty | E4: Rate ($) | F4: Amount ($) | G4: Remarks
A5: Z.01 | B5: TEMPORARY WORKS
A6: Z.01.01 | B6: Site Preparation — build-ups in sheet "BU Z.01.01"
A7: Z.01.01.01 | B7: Mobilization | C7: Item | D7: 1 | E7: ='BU Z.01.01'!E12 -> 10500 | F7: =D7*E7 -> 10500 | G7: Trips + setup labor + yard
A8: Z.01.01.02 | B8: Demobilization & site clearance | C8: Item | D8: 1 | E8: ='BU Z.01.01'!E19 -> 6460 | F8: =D8*E8 -> 6460 | G8: Trips out + reinstatement
A9: Z.01.01.03 | B9: Temporary access & roads | C9: Item | D9: 1 | E9: ='BU Z.01.01'!E25 -> 7400 | F9: =D9*E9 -> 7400 | G9: Road + hardstand areas
A10: Z.01.01.04 | B10: Setting out & ongoing survey works | C10: Month | D10: 18 | E10: ='BU Z.01.01'!E32 -> 400 | F10: =D10*E10 -> 7200 | G10: Instrument + consumables + checks
A11: Z.01.01.05 | B11: Site signage & project board | C11: Item | D11: 1 | E11: ='BU Z.01.01'!E38 -> 800 | F11: =D11*E11 -> 800 | G11: Board + safety signage
A12: Z.01.01.06 | B12: Traffic management & road occupation | C12: Item | D12: 1 | E12: ='BU Z.01.01'!E45 -> 3000 | F12: =D12*E12 -> 3000 | G12: Flagmen + permits + equipment
A13: Z.01.02 | B13: General Protection — build-ups in sheet "BU Z.01.02"
A14: Z.01.02.01 | B14: Temporary fencing & hoarding | C14: Item | D14: 1 | E14: ='BU Z.01.02'!E8 -> 7950 | F14: =D14*E14 -> 7950 | G14: Site perimeter x rate/m + gates
A15: Z.01.02.02 | B15: Temporary sheet pile, length 6m | C15: m | D15: 95 | E15: ='BU Z.01.02'!E14 -> 180 | F15: =D15*E15 -> 17100 | G15: Rate/m = drive/extract + rental. DELETE from CS BoQ (double count)
A16: Z.01.02.03 | B16: Safety net to building perimeter | C16: Item | D16: 1 | E16: ='BU Z.01.02'!E20 -> 6000 | F16: =D16*E16 -> 6000 | G16: Net area x rate + labor
A17: Z.01.02.04 | B17: Edge protection & handrails | C17: Floor | D17: ='Site Data'!C15 -> 11 | E17: ='BU Z.01.02'!E26 -> 700 | F17: =D17*E17 -> 7700 | G17: Rate/floor = perimeter x rail rate
A18: Z.01.02.05 | B18: Protection of completed works | C18: Item | D18: 1 | E18: ='BU Z.01.02'!E32 -> 4000 | F18: =D18*E18 -> 4000 | G18: Sheeting area + sundries
A19: Z.01.02.06 | B19: Monsoon protection & site drainage | C19: Month | D19: 18 | E19: ='BU Z.01.02'!E39 -> 250 | F19: =D19*E19 -> 4500 | G19: Pumps + channels + labor
A20: Z.01.02.07 | B20: Dewatering during substructure | C20: Month | D20: 4 | E20: ='BU Z.01.02'!E46 -> 900 | F20: =D20*E20 -> 3600 | G20: Pumps + fuel + attendance
A21: Z.01.03 | B21: Temporary Building — build-ups in sheet "BU Z.01.03"
A22: Z.01.03.01 | B22: Site office, store & welfare facilities | C22: Month | D22: 18 | E22: ='BU Z.01.03'!E10 -> 1200 | F22: =D22*E22 -> 21600 | G22: Containers + furniture + shelter
A23: Z.01.03.02 | B23: Temporary worker toilets & sanitation | C23: Month | D23: 18 | E23: ='BU Z.01.03'!E16 -> 200 | F23: =D23*E23 -> 3600 | G23: Units + servicing
A24: Z.01.03.03 | B24: First aid room & facilities | C24: Item | D24: 1 | E24: ='BU Z.01.03'!E22 -> 1500 | F24: =D24*E24 -> 1500 | G24: Fit-out + supplies
A25: Z.01.03.04 | B25: Washing bay / wheel wash | C25: Item | D25: 1 | E25: ='BU Z.01.03'!E30 -> 10100 | F25: =D25*E25 -> 10100 | G25: Pad + pump + maintenance
A26: Z.01.04 | B26: Temporary Site Labor — build-ups in sheet "BU Z.01.04"
A27: Z.01.04.01 | B27: Site cleaning & waste removal | C27: Month | D27: 18 | E27: ='BU Z.01.04'!E9 -> 602 | F27: =D27*E27 -> 10836 | G27: Crew + skips + tipping
A28: Z.01.04.02 | B28: Final builder's clean at handover | C28: Item | D28: 1 | E28: ='BU Z.01.04'!E15 -> 3500 | F28: =D28*E28 -> 3500 | G28: GFA x rate + facade clean
A29: Z.01.05 | B29: Machinery & Vertical Transport — build-ups in sheet "BU Z.01.05"
A30: Z.01.05.01 | B30: Tower crane rental | C30: Month | D30: 16 | E30: ='BU Z.01.05'!E9 -> 3500 | F30: =D30*E30 -> 56000 | G30: Rental + operator + maintenance
A31: Z.01.05.02 | B31: Tower crane foundation, erection, dismantle & test | C31: Item | D31: 1 | E31: ='BU Z.01.05'!E17 -> 18000 | F31: =D31*E31 -> 18000 | G31: Base + erect + dismantle + test
A32: Z.01.05.03 | B32: Passenger / material hoist rental | C32: Month | D32: 12 | E32: ='BU Z.01.05'!E23 -> 1500 | F32: =D32*E32 -> 18000 | G32: Rental + operator
A33: Z.01.05.04 | B33: Hoist erection & dismantling | C33: Item | D33: 1 | E33: ='BU Z.01.05'!E30 -> 4000 | F33: =D33*E33 -> 4000 | G33: Erect + dismantle + cert
A34: Z.01.05.05 | B34: Concrete pump provision | C34: Item | F34: 0 | G34: DECISION: included in concrete unit rates — do NOT price here
A35: Z.01.05.06 | B35: External scaffolding to facade | C35: m2 | D35: ='Site Data'!C10 -> 4140 | E35: ='BU Z.01.05'!E36 -> 7.2 | F35: =D35*E35 -> 29808 | G35: Qty = facade area (Site Data). Rate/m2 = E&D + rental
A36: Z.01.05.07 | B36: Back-propping / falsework for PT slabs | C36: Floor | D36: 10 | E36: ='BU Z.01.05'!E42 -> 1200 | F36: =D36*E36 -> 12000 | G36: Props rental + labor per floor
A37: Z.01.06 | B37: Light Equipment & Hand Tools — build-up in sheet "BU Z.01.06"
A38: Z.01.06.01 | B38: Small plant, light equipment & hand tools | C38: Month | D38: 18 | E38: ='BU Z.01.06'!E10 -> 350 | F38: =D38*E38 -> 6300 | G38: Mixers + tools + consumables
A39: Z.01.07 | B39: Temporary Electrical / Plumbing / Drainage — build-ups in sheet "Temp Utilities"
A40: Z.01.07.01 | B40: Temporary electricity — installation, connection & removal | C40: Item | D40: 1 | E40: ='Temp Utilities'!B34 -> 5500 | F40: =D40*E40 -> 5500 | G40: One-time — Temp Utilities A3
A41: Z.01.07.02 | B41: Temporary electricity — consumption & maintenance | C41: Month | D41: 18 | E41: ='Temp Utilities'!B23 -> 1258.2624 | F41: =D41*E41 -> 22648.723 | G41: Load schedule — Temp Utilities A1/A2
...

Sheet Staff Schedule
A1: SITE STAFF SCHEDULE — Feeds Z.30.01 / Z.30.02 in Preliminaries
A2: 10-Storey School Building, Phnom Penh — 18-month programme. Yellow = input.
A4: No. | B4: Position | C4: Origin | D4: Persons | E4: Months | F4: Monthly Rate ($) | G4: Total ($)
A5: 1 | B5: Project Manager | C5: Foreign | D5: 1 | E5: 18 | F5: 3500 | G5: =D5*E5*F5 -> 63000
A6: 2 | B6: Site Engineer | C6: Local | D6: 2 | E6: 18 | F6: 1200 | G6: =D6*E6*F6 -> 43200
A7: 3 | B7: Quantity Surveyor | C7: Local | D7: 1 | E7: 18 | F7: 1000 | G7: =D7*E7*F7 -> 18000
A8: 4 | B8: Safety Officer | C8: Local | D8: 1 | E8: 18 | F8: 800 | G8: =D8*E8*F8 -> 14400
A9: 5 | B9: Surveyor (incl. assistant) | C9: Local | D9: 1 | E9: 18 | F9: 900 | G9: =D9*E9*F9 -> 16200
A10: 6 | B10: General Foreman | C10: Local | D10: 2 | E10: 18 | F10: 700 | G10: =D10*E10*F10 -> 25200
A11: 7 | B11: Site Admin / Storekeeper | C11: Local | D11: 1 | E11: 18 | F11: 500 | G11: =D11*E11*F11 -> 9000
A12: 8 | B12: Document Controller | C12: Local | D12: 1 | E12: 12 | F12: 500 | G12: =D12*E12*F12 -> 6000
B14: Subtotal — Foreign staff (→ Z.30.01) | G14: =SUMIF(C5:C12,"Foreign",G5:G12) -> 63000
B15: Subtotal — Local staff (→ Z.30.02) | G15: =SUMIF(C5:C12,"Local",G5:G12) -> 132000
B16: TOTAL SITE STAFF | G16: =G14+G15 -> 195000

Sheet Temp Utilities
A1: TEMPORARY UTILITIES BUILD-UP — Feeds Z.01.07 in Preliminaries
A2: Yellow = input. Change any input and the Preliminaries rates update automatically.
A4: A. TEMPORARY ELECTRICITY
A5: A1. Monthly Load Schedule (peak structure months)
A6: Equipment | B6: kW | C6: Hrs/day | D6: Days/month | E6: kWh/month
A7: Tower crane | B7: 30 | C7: 6 | D7: 26 | E7: =B7*C7*D7 -> 4680
A8: Passenger / material hoist | B8: 15 | C8: 5 | D8: 26 | E8: =B8*C8*D8 -> 1950
A9: Bar bender & cutter | B9: 6 | C9: 5 | D9: 26 | E9: =B9*C9*D9 -> 780
A10: Concrete vibrators (4 no.) | B10: 6 | C10: 3 | D10: 20 | E10: =B10*C10*D10 -> 360
A11: Welding sets (2 no.) | B11: 10 | C11: 3 | D11: 20 | E11: =B11*C11*D11 -> 600
A12: Water pumps | B12: 3 | C12: 4 | D12: 26 | E12: =B12*C12*D12 -> 312
A13: Site office (AC, IT, lighting) | B13: 5 | C13: 9 | D13: 26 | E13: =B13*C13*D13 -> 1170
A14: Site & tower lighting | B14: 4 | C14: 11 | D14: 30 | E14: =B14*C14*D14 -> 1320
A15: Total peak consumption | E15: =SUM(E7:E14) -> 11172
A17: A2. Monthly Cost Calculation
A18: EDC tariff ($/kWh) | B18: 0.16
A19: Peak monthly cost | B19: =E15*B18 -> 1787.52
A20: Diversity factor (programme average / peak) | B20: 0.62
A21: Average monthly consumption cost | B21: =B19*B20 -> 1108.2624
A22: Electrician maintenance ($/month) | B22: 150
A23: MONTHLY RATE → Z.01.07.02 | B23: =B21+B22 -> 1258.2624
A25: A3. One-Time Installation & Removal
A26: Description | B26: Amount ($)
A27: EDC connection fee & deposit | B27: 1500
A28: Main distribution board (MDB) & meter | B28: 800
A29: Sub-distribution boards (1 per 2 floors × 5) | B29: 750
A30: Cabling & rising mains distribution | B30: 1200
A31: Earthing & protection | B31: 400
A32: Site lighting installation | B32: 600
A33: Removal at completion | B33: 250
A34: ONE-TIME TOTAL → Z.01.07.01 | B34: =SUM(B27:B33) -> 5500
A36: B. TEMPORARY WATER
A37: B1. One-Time Installation & Removal
A38: Description | B38: Amount ($)
A39: PPWSA connection & meter | B39: 600
A40: Storage tanks 2 × 5 m³ | B40: 500
A41: Booster pump & piping to floors | B41: 700
A42: Removal at completion | B42: 100
A43: ONE-TIME TOTAL → Z.01.07.03 | B43: =SUM(B39:B42) -> 1900
A45: B2. Monthly Demand & Cost
...

Sheet BU Z.01.01
A1: Z.01.01 SITE PREPARATION — Build-Ups
A2: Yellow = input (Phnom Penh benchmarks — replace with quotations). Green = linked from Site Data.
A4: Z.01.01.01 | B4: Mobilization (total per Item)
A5: Component | B5: Qty | C5: Unit | D5: Rate ($) | E5: Amount ($)
A6: Low-bed & truck transport trips (plant in) | B6: 12 | C6: trip | D6: 400 | E6: =B6*D6 -> 4800
A7: Crane lifts for site establishment | B7: 4 | C7: lift | D7: 300 | E7: =B7*D7 -> 1200
A8: Site setup labor | B8: 100 | C8: man-day | D8: 12 | E8: =B8*D8 -> 1200
A9: Utility applications & administration | B9: 1 | C9: lot | D9: 1000 | E9: =B9*D9 -> 1000
A10: Storage yard & hardstand setup | B10: 1 | C10: lot | D10: 1500 | E10: =B10*D10 -> 1500
A11: Survey control points establishment | B11: 1 | C11: lot | D11: 800 | E11: =B11*D11 -> 800
B12: Build-up total → Z.01.01.01 | E12: =SUM(E6:E11) -> 10500
A14: Z.01.01.02 | B14: Demobilization & site clearance (total per Item)
A15: Component | B15: Qty | C15: Unit | D15: Rate ($) | E15: Amount ($)
A16: Transport trips out (plant removal) | B16: 10 | C16: trip | D16: 400 | E16: =B16*D16 -> 4000
A17: Dismantling labor | B17: 80 | C17: man-day | D17: 12 | E17: =B17*D17 -> 960
A18: Site reinstatement & final clearance | B18: 1 | C18: lot | D18: 1500 | E18: =B18*D18 -> 1500
B19: Build-up total → Z.01.01.02 | E19: =SUM(E16:E18) -> 6460
A21: Z.01.01.03 | B21: Temporary access & roads (total per Item)
A22: Component | B22: Qty | C22: Unit | D22: Rate ($) | E22: Amount ($)
A23: Laterite/gravel access road | B23: 300 | C23: m2 | D23: 18 | E23: =B23*D23 -> 5400
A24: Hardstand at loading/unloading area | B24: 100 | C24: m2 | D24: 20 | E24: =B24*D24 -> 2000
B25: Build-up total → Z.01.01.03 | E25: =SUM(E23:E24) -> 7400
A27: Z.01.01.04 | B27: Setting out & ongoing survey works (rate per Month)
A28: Component | B28: Qty | C28: Unit | D28: Rate ($) | E28: Amount ($)
A29: Total station & level rental | B29: 1 | C29: mo | D29: 250 | E29: =B29*D29 -> 250
A30: Pegs, paint, consumables | B30: 1 | C30: mo | D30: 60 | E30: =B30*D30 -> 60
A31: Periodic verification survey | B31: 1 | C31: mo | D31: 90 | E31: =B31*D31 -> 90
B32: Build-up total → Z.01.01.04 | E32: =SUM(E29:E31) -> 400
A34: Z.01.01.05 | B34: Site signage & project board (total per Item)
A35: Component | B35: Qty | C35: Unit | D35: Rate ($) | E35: Amount ($)
A36: Project board 3m x 2m incl. frame | B36: 1 | C36: no | D36: 500 | E36: =B36*D36 -> 500
A37: Safety & directional signage | B37: 1 | C37: lot | D37: 300 | E37: =B37*D37 -> 300
B38: Build-up total → Z.01.01.05 | E38: =SUM(E36:E37) -> 800
A40: Z.01.01.06 | B40: Traffic management & road occupation (total per Item)
A41: Component | B41: Qty | C41: Unit | D41: Rate ($) | E41: Amount ($)
A42: Flagmen during concrete pours | B42: 60 | C42: man-day | D42: 15 | E42: =B42*D42 -> 900
A43: Road occupation permits | B43: 6 | C43: no | D43: 250 | E43: =B43*D43 -> 1500
A44: Cones, barriers, warning lights | B44: 1 | C44: lot | D44: 600 | E44: =B44*D44 -> 600
B45: Build-up total → Z.01.01.06 | E45: =SUM(E42:E44) -> 3000

Sheet BU Z.01.02
A1: Z.01.02 GENERAL PROTECTION — Build-Ups
A2: Yellow = input (Phnom Penh benchmarks — replace with quotations). Green = linked from Site Data.
A4: Z.01.02.01 | B4: Temporary fencing & hoarding (total per Item)
A5: Component | B5: Qty | C5: Unit | D5: Rate ($) | E5: Amount ($)
A6: Corrugated hoarding 2.4m high on site perimeter | B6: ='Site Data'!C5 -> 130 | C6: m | D6: 55 | E6: =B6*D6 -> 7150
A7: Double gates | B7: 2 | C7: no | D7: 400 | E7: =B7*D7 -> 800
B8: Build-up total → Z.01.02.01 | E8: =SUM(E6:E7) -> 7950
A10: Z.01.02.02 | B10: Temporary sheet pile, length 6m (rate per m)
A11: Component | B11: Qty | C11: Unit | D11: Rate ($) | E11: Amount ($)
A12: Drive & extract (subcontract) | B12: 1 | C12: m | D12: 140 | E12: =B12*D12 -> 140
A13: Rental during excavation (4 months) | B13: 4 | C13: m-mo | D13: 10 | E13: =B13*D13 -> 40
B14: Build-up total → Z.01.02.02 | E14: =SUM(E12:E13) -> 180
A16: Z.01.02.03 | B16: Safety net to building perimeter (total per Item)
A17: Component | B17: Qty | C17: Unit | D17: Rate ($) | E17: Amount ($)
A18: Net band, 2 lifts rotating up building | B18: 1400 | C18: m2 | D18: 4 | E18: =B18*D18 -> 5600
A19: Installation & shifting labor | B19: 1 | C19: lot | D19: 400 | E19: =B19*D19 -> 400
B20: Build-up total → Z.01.02.03 | E20: =SUM(E18:E19) -> 6000
A22: Z.01.02.04 | B22: Edge protection & handrails (rate per Floor)
A23: Component | B23: Qty | C23: Unit | D23: Rate ($) | E23: Amount ($)
A24: Guardrail to slab edge (building perimeter) | B24: ='Site Data'!C7 -> 115 | C24: m | D24: 5 | E24: =B24*D24 -> 575
A25: Posts, fixing & shifting labor | B25: 1 | C25: floor | D25: 125 | E25: =B25*D25 -> 125
B26: Build-up total → Z.01.02.04 | E26: =SUM(E24:E25) -> 700
A28: Z.01.02.05 | B28: Protection of completed works (total per Item)
A29: Component | B29: Qty | C29: Unit | D29: Rate ($) | E29: Amount ($)
A30: Floor/lobby/stair protection sheeting | B30: 600 | C30: m2 | D30: 5 | E30: =B30*D30 -> 3000
A31: Corner guards, tapes, miscellaneous | B31: 1 | C31: lot | D31: 1000 | E31: =B31*D31 -> 1000
B32: Build-up total → Z.01.02.05 | E32: =SUM(E30:E31) -> 4000
A34: Z.01.02.06 | B34: Monsoon protection & site drainage (rate per Month)
A35: Component | B35: Qty | C35: Unit | D35: Rate ($) | E35: Amount ($)
A36: Submersible pumps rental | B36: 2 | C36: no | D36: 60 | E36: =B36*D36 -> 120
A37: Sandbags & drainage channels | B37: 1 | C37: mo | D37: 80 | E37: =B37*D37 -> 80
A38: Attendance labor | B38: 1 | C38: mo | D38: 50 | E38: =B38*D38 -> 50
B39: Build-up total → Z.01.02.06 | E39: =SUM(E36:E38) -> 250
A41: Z.01.02.07 | B41: Dewatering during substructure (rate per Month)
A42: Component | B42: Qty | C42: Unit | D42: Rate ($) | E42: Amount ($)
A43: Dewatering pumps rental | B43: 2 | C43: no | D43: 150 | E43: =B43*D43 -> 300
A44: Fuel / power | B44: 1 | C44: mo | D44: 300 | E44: =B44*D44 -> 300
A45: Standby attendance | B45: 1 | C45: mo | D45: 300 | E45: =B45*D45 -> 300
B46: Build-up total → Z.01.02.07 | E46: =SUM(E43:E45) -> 900

Sheet BU Z.01.03
A1: Z.01.03 TEMPORARY BUILDING — Build-Ups
A2: Yellow = input (Phnom Penh benchmarks — replace with quotations). Green = linked from Site Data.
A4: Z.01.03.01 | B4: Site office, store & welfare (rate per Month)
A5: Component | B5: Qty | C5: Unit | D5: Rate ($) | E5: Amount ($)
A6: Office containers | B6: 3 | C6: no | D6: 250 | E6: =B6*D6 -> 750
A7: Store container | B7: 1 | C7: no | D7: 150 | E7: =B7*D7 -> 150
A8: Furniture, AC, IT (amortized) | B8: 1 | C8: mo | D8: 200 | E8: =B8*D8 -> 200
A9: Workers shelter / canteen | B9: 1 | C9: mo | D9: 100 | E9: =B9*D9 -> 100
B10: Build-up total → Z.01.03.01 | E10: =SUM(E6:E9) -> 1200
A12: Z.01.03.02 | B12: Temporary worker toilets (rate per Month)
A13: Component | B13: Qty | C13: Unit | D13: Rate ($) | E13: Amount ($)
A14: Portable toilet units | B14: 4 | C14: no | D14: 35 | E14: =B14*D14 -> 140
A15: Servicing & consumables | B15: 1 | C15: mo | D15: 60 | E15: =B15*D15 -> 60
B16: Build-up total → Z.01.03.02 | E16: =SUM(E14:E15) -> 200
A18: Z.01.03.03 | B18: First aid room & facilities (total per Item)
A19: Component | B19: Qty | C19: Unit | D19: Rate ($) | E19: Amount ($)
A20: Room fit-out | B20: 1 | C20: lot | D20: 800 | E20: =B20*D20 -> 800
A21: Equipment & initial supplies | B21: 1 | C21: lot | D21: 700 | E21: =B21*D21 -> 700
B22: Build-up total → Z.01.03.03 | E22: =SUM(E20:E21) -> 1500
A24: Z.01.03.04 | B24: Washing bay / wheel wash (total per Item)
A25: Component | B25: Qty | C25: Unit | D25: Rate ($) | E25: Amount ($)
A26: RC pad & sediment pit | B26: 1 | C26: lot | D26: 4500 | E26: =B26*D26 -> 4500
A27: Pump & water recycling system | B27: 1 | C27: lot | D27: 1500 | E27: =B27*D27 -> 1500
A28: Hoses & equipment | B28: 1 | C28: lot | D28: 500 | E28: =B28*D28 -> 500
A29: Maintenance & desilting over programme | B29: 18 | C29: mo | D29: 200 | E29: =B29*D29 -> 3600
B30: Build-up total → Z.01.03.04 | E30: =SUM(E26:E29) -> 10100

Sheet BU Z.01.04
A1: Z.01.04 TEMPORARY SITE LABOR — Build-Ups
A2: Yellow = input (Phnom Penh benchmarks — replace with quotations). Green = linked from Site Data.
A4: Z.01.04.01 | B4: Site cleaning & waste removal (rate per Month)
A5: Component | B5: Qty | C5: Unit | D5: Rate ($) | E5: Amount ($)
A6: Cleaning laborers | B6: 26 | C6: man-day | D6: 12 | E6: =B6*D6 -> 312
A7: Waste skip hire | B7: 2 | C7: no | D7: 120 | E7: =B7*D7 -> 240
A8: Tipping fees | B8: 1 | C8: mo | D8: 50 | E8: =B8*D8 -> 50
B9: Build-up total → Z.01.04.01 | E9: =SUM(E6:E8) -> 602
A11: Z.01.04.02 | B11: Final builder's clean at handover (total per Item)
A12: Component | B12: Qty | C12: Unit | D12: Rate ($) | E12: Amount ($)
A13: Builder's clean on GFA | B13: ='Site Data'!C16 -> 8000 | C13: m2 | D13: 0.35 | E13: =B13*D13 -> 2800
A14: Glass & facade cleaning | B14: 1 | C14: lot | D14: 700 | E14: =B14*D14 -> 700
B15: Build-up total → Z.01.04.02 | E15: =SUM(E13:E14) -> 3500

Sheet BU Z.01.05
A1: Z.01.05 MACHINERY & VERTICAL TRANSPORT — Build-Ups
A2: Yellow = input (Phnom Penh benchmarks — replace with quotations). Green = linked from Site Data.
A4: Z.01.05.01 | B4: Tower crane rental (rate per Month)
A5: Component | B5: Qty | C5: Unit | D5: Rate ($) | E5: Amount ($)
A6: Tower crane rental | B6: 1 | C6: mo | D6: 2800 | E6: =B6*D6 -> 2800
A7: Operator & rigger | B7: 1 | C7: mo | D7: 600 | E7: =B7*D7 -> 600
A8: Maintenance & spares | B8: 1 | C8: mo | D8: 100 | E8: =B8*D8 -> 100
B9: Build-up total → Z.01.05.01 | E9: =SUM(E6:E8) -> 3500
A11: Z.01.05.02 | B11: Tower crane foundation, erection, dismantle & test (total per Item)
A12: Component | B12: Qty | C12: Unit | D12: Rate ($) | E12: Amount ($)
A13: RC foundation base | B13: 25 | C13: m3 | D13: 220 | E13: =B13*D13 -> 5500
A14: Erection incl. mobile crane hire | B14: 1 | C14: lot | D14: 6000 | E14: =B14*D14 -> 6000
A15: Dismantling | B15: 1 | C15: lot | D15: 4500 | E15: =B15*D15 -> 4500
A16: Load test & certification | B16: 1 | C16: lot | D16: 2000 | E16: =B16*D16 -> 2000
B17: Build-up total → Z.01.05.02 | E17: =SUM(E13:E16) -> 18000
A19: Z.01.05.03 | B19: Passenger / material hoist rental (rate per Month)
A20: Component | B20: Qty | C20: Unit | D20: Rate ($) | E20: Amount ($)
A21: Hoist rental | B21: 1 | C21: mo | D21: 1200 | E21: =B21*D21 -> 1200
A22: Operator | B22: 1 | C22: mo | D22: 300 | E22: =B22*D22 -> 300
B23: Build-up total → Z.01.05.03 | E23: =SUM(E21:E22) -> 1500
A25: Z.01.05.04 | B25: Hoist erection & dismantling (total per Item)
A26: Component | B26: Qty | C26: Unit | D26: Rate ($) | E26: Amount ($)
A27: Erection & base | B27: 1 | C27: lot | D27: 2200 | E27: =B27*D27 -> 2200
A28: Dismantling | B28: 1 | C28: lot | D28: 1300 | E28: =B28*D28 -> 1300
A29: Test & certification | B29: 1 | C29: lot | D29: 500 | E29: =B29*D29 -> 500
B30: Build-up total → Z.01.05.04 | E30: =SUM(E27:E29) -> 4000
A32: Z.01.05.06 | B32: External scaffolding to facade (rate per m2)
A33: Component | B33: Qty | C33: Unit | D33: Rate ($) | E33: Amount ($)
A34: Erection & dismantling | B34: 1 | C34: m2 | D34: 3 | E34: =B34*D34 -> 3
A35: Rental over scaffold duration (P09 months) | B35: ='Site Data'!C13 -> 12 | C35: m2-mo | D35: 0.35 | E35: =B35*D35 -> 4.2
B36: Build-up total → Z.01.05.06 | E36: =SUM(E34:E35) -> 7.2
A38: Z.01.05.07 | B38: Back-propping / falsework for PT slabs (rate per Floor)
A39: Component | B39: Qty | C39: Unit | D39: Rate ($) | E39: Amount ($)
A40: Adjustable props rental (400 no x 2-month cycle) | B40: 800 | C40: prop-mo | D40: 1.2 | E40: =B40*D40 -> 960
A41: Install & strike labor | B41: 20 | C41: man-day | D41: 12 | E41: =B41*D41 -> 240
B42: Build-up total → Z.01.05.07 | E42: =SUM(E40:E41) -> 1200

Sheet BU Z.01.06
A1: Z.01.06 LIGHT EQUIPMENT & HAND TOOLS — Build-Up
A2: Yellow = input (Phnom Penh benchmarks — replace with quotations). Green = linked from Site Data.
A4: Z.01.06.01 | B4: Small plant, light equipment & hand tools (rate per Month)
A5: Component | B5: Qty | C5: Unit | D5: Rate ($) | E5: Amount ($)
A6: Concrete mixers | B6: 2 | C6: no | D6: 50 | E6: =B6*D6 -> 100
A7: Cutting & grinding equipment | B7: 1 | C7: mo | D7: 80 | E7: =B7*D7 -> 80
A8: Power tools replacement allowance | B8: 1 | C8: mo | D8: 100 | E8: =B8*D8 -> 100
A9: Consumables (discs, bits, blades) | B9: 1 | C9: mo | D9: 70 | E9: =B9*D9 -> 70
B10: Build-up total → Z.01.06.01 | E10: =SUM(E6:E9) -> 350

Sheet BU Z.01.08
A1: Z.01.08 SAFETY & ENVIRONMENT CONTROL — Build-Ups
A2: Yellow = input (Phnom Penh benchmarks — replace with quotations). Green = linked from Site Data.
A4: Z.01.08.01 | B4: Health, safety provisions & PPE (rate per Month)
A5: Component | B5: Qty | C5: Unit | D5: Rate ($) | E5: Amount ($)
A6: PPE issue & replacement (per peak workforce) | B6: ='Site Data'!C14 -> 80 | C6: worker | D6: 4 | E6: =B6*D6 -> 320
A7: First-aid consumables | B7: 1 | C7: mo | D7: 30 | E7: =B7*D7 -> 30
A8: Toolbox training & safety officer support | B8: 1 | C8: mo | D8: 100 | E8: =B8*D8 -> 100
A9: Safety signage & miscellaneous | B9: 1 | C9: mo | D9: 50 | E9: =B9*D9 -> 50
B10: Build-up total → Z.01.08.01 | E10: =SUM(E6:E9) -> 500
A12: Z.01.08.02 | B12: Site security incl. guards & CCTV (rate per Month)
A13: Component | B13: Qty | C13: Unit | D13: Rate ($) | E13: Amount ($)
A14: Security guards (day/night rotation) | B14: 3 | C14: no | D14: 250 | E14: =B14*D14 -> 750
A15: CCTV system (amortized) | B15: 1 | C15: mo | D15: 100 | E15: =B15*D15 -> 100
A16: Security lighting power | B16: 1 | C16: mo | D16: 50 | E16: =B16*D16 -> 50
B17: Build-up total → Z.01.08.02 | E17: =SUM(E14:E16) -> 900
A19: Z.01.08.03 | B19: Material & concrete testing (QA/QC) (total per Item)
A20: Component | B20: Qty | C20: Unit | D20: Rate ($) | E20: Amount ($)
A21: Concrete cube test sets | B21: 300 | C21: set | D21: 15 | E21: =B21*D21 -> 4500
A22: Rebar tensile tests | B22: 40 | C22: no | D22: 30 | E22: =B22*D22 -> 1200
A23: Soil / compaction tests | B23: 1 | C23: lot | D23: 800 | E23: =B23*D23 -> 800
A24: Other / miscellaneous tests | B24: 1 | C24: lot | D24: 1500 | E24: =B24*D24 -> 1500
B25: Build-up total → Z.01.08.03 | E25: =SUM(E21:E24) -> 8000

Sheet BU Z.50
A1: Z.50 DESIGN EXPENSES — Build-Ups
A2: Yellow = input (Phnom Penh benchmarks — replace with quotations). Green = linked from Site Data.
A4: Z.50.01 | B4: Shop drawings (total per Item)
A5: Component | B5: Qty | C5: Unit | D5: Rate ($) | E5: Amount ($)
A6: Draftsmen (2 no. x 10 months) | B6: 20 | C6: man-mo | D6: 450 | E6: =B6*D6 -> 9000
A7: Plotting & printing | B7: 1 | C7: lot | D7: 1000 | E7: =B7*D7 -> 1000
B8: Build-up total → Z.50.01 | E8: =SUM(E6:E7) -> 10000
A10: Z.50.02 | B10: As-built drawings (total per Item)
A11: Component | B11: Qty | C11: Unit | D11: Rate ($) | E11: Amount ($)
A12: Draftsman (1 no. x 10 months) | B12: 10 | C12: man-mo | D12: 500 | E12: =B12*D12 -> 5000
A13: Printing & binding | B13: 1 | C13: lot | D13: 1000 | E13: =B13*D13 -> 1000
B14: Build-up total → Z.50.02 | E14: =SUM(E12:E13) -> 6000
A16: Z.50.03 | B16: Temporary works design (total per Item)
A17: Component | B17: Qty | C17: Unit | D17: Rate ($) | E17: Amount ($)
A18: Crane base design & check | B18: 1 | C18: lot | D18: 1500 | E18: =B18*D18 -> 1500
A19: Sheet pile / shoring design | B19: 1 | C19: lot | D19: 1500 | E19: =B19*D19 -> 1500
A20: Back-propping & formwork scheme | B20: 1 | C20: lot | D20: 1500 | E20: =B20*D20 -> 1500
A21: Documentation & submissions | B21: 1 | C21: lot | D21: 500 | E21: =B21*D21 -> 500
B22: Build-up total → Z.50.03 | E22: =SUM(E18:E21) -> 5000

Sheet Budget Code
A1: BUDGET CODE
A2: Section | B2: Code | D2: Description
A3: Early Work | B3: A.00 | C3: A.Early Work
A4: Topography Survey | B4: A.01 | C4: A.01.Topography Survey
A5: Soil Investigation | B5: A.02 | C5: A.02.Soil Investigation
A6: Mine / UXO Clearance | B6: A.03 | C6: A.03.Mine / UXO Clearance
A7: Soil Leveling | B7: A.04 | C7: A.04.Soil Leveling
A8: Demolition | B8: A.05 | C8: A.05.Demolition
A9: Cleaning | B9: A.06 | C9: A.06.Cleaning
A10: Repair exiting services | B10: A.07 | C10: A.07.Repair exiting services
A11: Renovation | B11: A.08 | C11: A.08.Renovation
A12: Sub Structure | B12: B.00 | C12: B.0.Sub Structure
A13: Piling Work | B13: B.01 | C13: B.01.Piling Work
A14: Basement | B14: B.02 | C14: B.02.Basement
... A17: Architecture | B17: C.00 | C17: C.0.Architecture
A18: Exterior Wall and Partition | B18: C.01 | C18: C.01.Exterior Wall and Partition | D18: Masonry Wall, Dry Wall, Glass partition
A19: Exterior Wall Finishes | B19: C.02 | C19: C.02.Exterior Wall Finishes | D19: Plastering, painting, cladding, molding
A20: Exterior Door | B20: C.03 | C20: C.03.Exterior Door | D20: Wooden door, Glass door, Steel door
A21: Exterior Window and Louver | B21: C.04 | C21: C.04.Exterior Window and Louver | D21: Glass window, window fence, steel louver
A22: Exterior floor | B22: C.05 | C22: C.05.Exterior floor | D22: Screeding, floor tiling, hardening, Waterproofing
A23: Exterior soffit | B23: C.06 | C23: C.06.Exterior soffit | D23: Soffit slab finish
A24: Exterior Stair Ramp | B24: C.07 | C24: C.07.Exterior Stair Ramp | D24: Barrier, ramp
A25: Roofing | B25: C.08 | C25: C.08.Roofing
A26: Interior Wall and Partition | B26: C.09 | C26: C.09.Interior Wall Partition | D26: Masonry Wall, Dry Wall, Glass partition
A27: Interior Doors | B27: C.10 | C27: C.10.Interior Door /Windows and Louvers | D27: Steel door, wooden door, glass door
A28: Special installation | B28: C.11 | C28: C.11.Special installation | D28: LPG Gas
A29: Exterior Finishes | B29: C.12 | C29: C.12.Exterior Finishes | D29: Plastering, painting, cladding, molding
A30: Interior Finish | B30: D.00 | C30: D.0.Interior Finish
A31: Interior Wall Finishes | B31: D.01 | C31: D.01.Interior Wall Finishes | D31: Wall tiling, Plastering, Painting, Skirting, Wall Marble
A32: Interior Floor Finishes | B32: D.02 | C32: D.02.Interior Floor Finishes | D32: Screeding, floor tiling, Wooden Flooring, Marble flooring, Carpet Flooring, Epoxy Flooring, waterproofing, Floor strip divider
A33: Ceiling Finishes | B33: D.03 | C33: D.03.Ceiling Finish | D33: Suspended Ceiling
A34: Fittings, furnishings and equipment | B34: E.00 | C34: E.0.Fitting, furnishings and equipment
A35: General Fitting | B35: E.01 | C35: E.01.General Fitting
A36: Domestic Kitchen Fitting | B36: E.02 | C36: E.02.Domestic Kitchen Fitting
A37: Special purpose Fitting | B37: E.03 | C37: E.03.Special purpose Fitting
A38: Signage | B38: E.04 | C38: E.04.Signage
A39: Art | B39: E.05 | C39: E.05.Art
A40: Non-Mechanical and Non Electrical Equipement | B40: E.06 | C40: E.06.Non-Mechanical and Non Electrical Equipement
A41: Internal Planting | B41: E.07 | C41: E.07.Internal Planting
A42: Bird and Vermin Control | B42: E.08 | C42: E.08.Bird and Vermin Control
...
