Workbook

Sheet Element Library
A1: QS ELEMENT LIBRARY — SECTION / SUB SECTION / SUB ELEMENT
A2: Standard coding list for BoQ takeoff — Structure, Architecture, MEP & External Works. Aligned to the project Budget Code framework.
A3: Each Sub Element links to one or more standard Descriptions on the Description Library sheet.
A5: No. | B5: Discipline | C5: Budget Code | D5: Section | E5: Sub Section | F5: Sub Element | G5: Typical Unit | H5: No. of Desc. | I5: Default Description | J5: Key
A6: 1 | B6: Civil and Structure | C6: A.04 | D6: Sub Structure | E6: Site Preparation & Earthwork | F6: Site Clearing | G6: m2 | H6: 1 | I6: Site clearing, grubbing and removal of vegetation and debris off site | J6: Sub Structure|Site Preparation & Earthwork|Site Clearing
A7: 2 | B7: Civil and Structure | C7: A.04 | D7: Sub Structure | E7: Site Preparation & Earthwork | F7: Excavation | G7: m3 | H7: 1 | I7: Bulk excavation by machine incl. trimming and levelling of formation | J7: Sub Structure|Site Preparation & Earthwork|Excavation
A8: 3 | B8: Civil and Structure | C8: A.04 | D8: Sub Structure | E8: Site Preparation & Earthwork | F8: Backfill | G8: m3 | H8: 1 | I8: Backfilling with approved material in 200mm layers incl. compaction to 95% MDD | J8: Sub Structure|Site Preparation & Earthwork|Backfill
A9: 4 | B9: Civil and Structure | C9: A.04 | D9: Sub Structure | E9: Site Preparation & Earthwork | F9: Soil Disposal | G9: m3 | H9: 1 | I9: Cart away surplus excavated material off site incl. tipping fee | J9: Sub Structure|Site Preparation & Earthwork|Soil Disposal
A10: 5 | B10: Civil and Structure | C10: A.04 | D10: Sub Structure | E10: Site Preparation & Earthwork | F10: Compaction | G10: m2 | H10: 1 | I10: Compaction of formation to 95% MDD incl. watering and testing | J10: Sub Structure|Site Preparation & Earthwork|Compaction
A11: 6 | B11: Civil and Structure | C11: A.04 | D11: Sub Structure | E11: Site Preparation & Earthwork | F11: Dewatering | G11: Lot | H11: 1 | I11: Dewatering incl. pumps, sump pits, piping and maintenance during construction | J11: Sub Structure|Site Preparation & Earthwork|Dewatering
A12: 7 | B12: Civil and Structure | C12: A.04 | D12: Sub Structure | E12: Site Preparation & Earthwork | F12: Levelling & Setting Out | G12: m2 | H12: 1 | I12: Setting out, levelling and establishment of benchmarks and grid lines | J12: Sub Structure|Site Preparation & Earthwork|Levelling & Setting Out
A13: 8 | B13: Civil and Structure | C13: B.02 | D13: Sub Structure | E13: Shoring & Sheet Pile | F13: Sheet Pile Supply | G13: m2 | H13: 1 | I13: Supply of steel sheet pile, hot rolled section as per design | J13: Sub Structure|Shoring & Sheet Pile|Sheet Pile Supply
A14: 9 | B14: Civil and Structure | C14: B.02 | D14: Sub Structure | E14: Shoring & Sheet Pile | F14: Sheet Pile Driving | G14: m2 | H14: 1 | I14: Driving of steel sheet pile to required depth incl. plant and equipment | J14: Sub Structure|Shoring & Sheet Pile|Sheet Pile Driving
A15: 10 | B15: Civil and Structure | C15: B.02 | D15: Sub Structure | E15: Shoring & Sheet Pile | F15: Sheet Pile Extraction | G15: m2 | H15: 1 | I15: Extraction of steel sheet pile and making good of voids | J15: Sub Structure|Shoring & Sheet Pile|Sheet Pile Extraction
A16: 11 | B16: Civil and Structure | C16: B.02 | D16: Sub Structure | E16: Shoring & Sheet Pile | F16: Strut & Waler | G16: kg | H16: 1 | I16: Steel strut and waler incl. fabrication, installation and removal | J16: Sub Structure|Shoring & Sheet Pile|Strut & Waler
A17: 12 | B17: Civil and Structure | C17: B.02 | D17: Sub Structure | E17: Shoring & Sheet Pile | F17: Ground Anchor | G17: Nos | H17: 1 | I17: Ground anchor incl. drilling, grouting, stressing and testing | J17: Sub Structure|Shoring & Sheet Pile|Ground Anchor
... A523: 518 | B523: External Works | C523: G.05 | D523: External Work | E523: External fixture | F523: Playground / sport court | G523: Lot | H523: 1 | I523: Playground / sport court incl. surfacing, marking and equipment | J523: External Work|External fixture|Playground / sport court

Sheet Description Library
A1: DESCRIPTION LIBRARY — STANDARD BoQ DESCRIPTIONS (MATERIAL TYPE)
A2: One or more standard descriptions per Sub Element. "In Price List = Yes" means a rate already exists in the current project Price List.
A3: Copy the Description into the Material Type column of Raw Data. Edit sizes / grades to match the specification before pricing.
A5: No. | B5: Discipline | C5: Budget Code | D5: Section | E5: Sub Section | F5: Sub Element | G5: Description (Material Type) | H5: Unit | I5: In Price List | J5: Current Rate ($) | K5: Key
A6: 1 | B6: Civil and Structure | C6: A.04 | D6: Sub Structure | E6: Site Preparation & Earthwork | F6: Site Clearing | G6: Site clearing, grubbing and removal of vegetation and debris off site | H6: m2 | I6: - | K6: Sub Structure|Site Preparation & Earthwork|Site Clearing|Site clearing, grubbing and removal of vegetation and debris off site
A7: 2 | B7: Civil and Structure | C7: A.04 | D7: Sub Structure | E7: Site Preparation & Earthwork | F7: Excavation | G7: Bulk excavation by machine incl. trimming and levelling of formation | H7: m3 | I7: - | K7: Sub Structure|Site Preparation & Earthwork|Excavation|Bulk excavation by machine incl. trimming and levelling of formation
A8: 3 | B8: Civil and Structure | C8: A.04 | D8: Sub Structure | E8: Site Preparation & Earthwork | F8: Backfill | G8: Backfilling with approved material in 200mm layers incl. compaction to 95% MDD | H8: m3 | I8: - | K8: Sub Structure|Site Preparation & Earthwork|Backfill|Backfilling with approved material in 200mm layers incl. compaction to 95% MDD
A9: 4 | B9: Civil and Structure | C9: A.04 | D9: Sub Structure | E9: Site Preparation & Earthwork | F9: Soil Disposal | G9: Cart away surplus excavated material off site incl. tipping fee | H9: m3 | I9: - | K9: Sub Structure|Site Preparation & Earthwork|Soil Disposal|Cart away surplus excavated material off site incl. tipping fee
A10: 5 | B10: Civil and Structure | C10: A.04 | D10: Sub Structure | E10: Site Preparation & Earthwork | F10: Compaction | G10: Compaction of formation to 95% MDD incl. watering and testing | H10: m2 | I10: - | K10: Sub Structure|Site Preparation & Earthwork|Compaction|Compaction of formation to 95% MDD incl. watering and testing
A11: 6 | B11: Civil and Structure | C11: A.04 | D11: Sub Structure | E11: Site Preparation & Earthwork | F11: Dewatering | G11: Dewatering incl. pumps, sump pits, piping and maintenance during construction | H11: Lot | I11: - | K11: Sub Structure|Site Preparation & Earthwork|Dewatering|Dewatering incl. pumps, sump pits, piping and maintenance during construction
A12: 7 | B12: Civil and Structure | C12: A.04 | D12: Sub Structure | E12: Site Preparation & Earthwork | F12: Levelling & Setting Out | G12: Setting out, levelling and establishment of benchmarks and grid lines | H12: m2 | I12: - | K12: Sub Structure|Site Preparation & Earthwork|Levelling & Setting Out|Setting out, levelling and establishment of benchmarks and grid lines
A13: 8 | B13: Civil and Structure | C13: B.02 | D13: Sub Structure | E13: Shoring & Sheet Pile | F13: Sheet Pile Supply | G13: Supply of steel sheet pile, hot rolled section as per design | H13: m2 | I13: - | K13: Sub Structure|Shoring & Sheet Pile|Sheet Pile Supply|Supply of steel sheet pile, hot rolled section as per design
A14: 9 | B14: Civil and Structure | C14: B.02 | D14: Sub Structure | E14: Shoring & Sheet Pile | F14: Sheet Pile Driving | G14: Driving of steel sheet pile to required depth incl. plant and equipment | H14: m2 | I14: - | K14: Sub Structure|Shoring & Sheet Pile|Sheet Pile Driving|Driving of steel sheet pile to required depth incl. plant and equipment
A15: 10 | B15: Civil and Structure | C15: B.02 | D15: Sub Structure | E15: Shoring & Sheet Pile | F15: Sheet Pile Extraction | G15: Extraction of steel sheet pile and making good of voids | H15: m2 | I15: - | K15: Sub Structure|Shoring & Sheet Pile|Sheet Pile Extraction|Extraction of steel sheet pile and making good of voids
A16: 11 | B16: Civil and Structure | C16: B.02 | D16: Sub Structure | E16: Shoring & Sheet Pile | F16: Strut & Waler | G16: Steel strut and waler incl. fabrication, installation and removal | H16: kg | I16: - | K16: Sub Structure|Shoring & Sheet Pile|Strut & Waler|Steel strut and waler incl. fabrication, installation and removal
A17: 12 | B17: Civil and Structure | C17: B.02 | D17: Sub Structure | E17: Shoring & Sheet Pile | F17: Ground Anchor | G17: Ground anchor incl. drilling, grouting, stressing and testing | H17: Nos | I17: - | K17: Sub Structure|Shoring & Sheet Pile|Ground Anchor|Ground anchor incl. drilling, grouting, stressing and testing
... A20: 15 | B20: Civil and Structure | C20: B.01 | D20: Sub Structure | E20: Bored Pile | F20: Bored Pile Boring | G20: Bored piling D800mm incl. boring, casing and disposal of spoil | H20: m | I20: - | K20: Sub Structure|Bored Pile|Bored Pile Boring|Bored piling D800mm incl. boring, casing and disposal of spoil
A21: 16 | B21: Civil and Structure | C21: B.01 | D21: Sub Structure | E21: Bored Pile | F21: Concrete | G21: Normal Concrete, 35Mpa (Cylinder), Slump 13+-2.5 | H21: m3 | I21: Yes | J21: 121.76 | K21: Sub Structure|Bored Pile|Concrete|Normal Concrete, 35Mpa (Cylinder), Slump 13+-2.5
A22: 17 | B22: Civil and Structure | C22: B.01 | D22: Sub Structure | E22: Bored Pile | F22: Concrete | G22: Normal Concrete, 35Mpa (Cylinder), Slump 15+-2.5 | H22: m3 | I22: Yes | J22: 119.36 | K22: Sub Structure|Bored Pile|Concrete|Normal Concrete, 35Mpa (Cylinder), Slump 15+-2.5
A23: 18 | B23: Civil and Structure | C23: B.01 | D23: Sub Structure | E23: Bored Pile | F23: Concrete | G23: Normal Concrete, 25Mpa (Cylinder), Slump 10+-2.5 | H23: m3 | I23: - | K23: Sub Structure|Bored Pile|Concrete|Normal Concrete, 25Mpa (Cylinder), Slump 10+-2.5
A24: 19 | B24: Civil and Structure | C24: B.01 | D24: Sub Structure | E24: Bored Pile | F24: Concrete | G24: Normal Concrete, 30Mpa (Cylinder), Slump 13+-2.5 | H24: m3 | I24: - | K24: Sub Structure|Bored Pile|Concrete|Normal Concrete, 30Mpa (Cylinder), Slump 13+-2.5
A25: 20 | B25: Civil and Structure | C25: B.01 | D25: Sub Structure | E25: Bored Pile | F25: Rebar | G25: Deform Bar, DB10(fy=390 Mpa) | H25: kg | I25: Yes | J25: 1.0176 | K25: Sub Structure|Bored Pile|Rebar|Deform Bar, DB10(fy=390 Mpa)
A26: 21 | B26: Civil and Structure | C26: B.01 | D26: Sub Structure | E26: Bored Pile | F26: Rebar | G26: Deform Bar, DB12(fy=390 Mpa) | H26: kg | I26: Yes | J26: 0.9832 | K26: Sub Structure|Bored Pile|Rebar|Deform Bar, DB12(fy=390 Mpa)
A27: 22 | B27: Civil and Structure | C27: B.01 | D27: Sub Structure | E27: Bored Pile | F27: Rebar | G27: Deform Bar, DB14(fy=390 Mpa) | H27: kg | I27: Yes | J27: 0.96 | K27: Sub Structure|Bored Pile|Rebar|Deform Bar, DB14(fy=390 Mpa)
A28: 23 | B28: Civil and Structure | C28: B.01 | D28: Sub Structure | E28: Bored Pile | F28: Rebar | G28: Deform Bar, DB16(fy=390 Mpa) | H28: kg | I28: Yes | J28: 0.9488 | K28: Sub Structure|Bored Pile|Rebar|Deform Bar, DB16(fy=390 Mpa)
A29: 24 | B29: Civil and Structure | C29: B.01 | D29: Sub Structure | E29: Bored Pile | F29: Rebar | G29: Deform Bar, DB20(fy=390 Mpa) | H29: kg | I29: Yes | J29: 0.9256 | K29: Sub Structure|Bored Pile|Rebar|Deform Bar, DB20(fy=390 Mpa)
A30: 25 | B30: Civil and Structure | C30: B.01 | D30: Sub Structure | E30: Bored Pile | F30: Rebar | G30: Deform Bar, DB25(fy=390 Mpa) | H30: kg | I30: Yes | J30: 0.9024 | K30: Sub Structure|Bored Pile|Rebar|Deform Bar, DB25(fy=390 Mpa)
A31: 26 | B31: Civil and Structure | C31: B.01 | D31: Sub Structure | E31: Bored Pile | F31: Rebar | G31: Deform Bar, DB32(fy=390 Mpa) | H31: kg | I31: Yes | J31: 0.8912 | K31: Sub Structure|Bored Pile|Rebar|Deform Bar, DB32(fy=390 Mpa)
A32: 27 | B32: Civil and Structure | C32: B.01 | D32: Sub Structure | E32: Bored Pile | F32: Rebar | G32: Round Bar, RB8(fy=250 Mpa) | H32: kg | I32: Yes | J32: 1.0064 | K32: Sub Structure|Bored Pile|Rebar|Round Bar, RB8(fy=250 Mpa)
A33: 28 | B33: Civil and Structure | C33: B.01 | D33: Sub Structure | E33: Bored Pile | F33: Rebar | G33: Round Bar, RB6(fy=250 Mpa) | H33: kg | I33: - | K33: Sub Structure|Bored Pile|Rebar|Round Bar, RB6(fy=250 Mpa)
A34: 29 | B34: Civil and Structure | C34: B.01 | D34: Sub Structure | E34: Bored Pile | F34: Steel Tie Wire | G34: Steel Tie Wire 1mm (Estimated 4% of Total Rebar Weight) | H34: kg | I34: Yes | J34: 1.404 | K34: Sub Structure|Bored Pile|Steel Tie Wire|Steel Tie Wire 1mm (Estimated 4% of Total Rebar Weight)
A35: 30 | B35: Civil and Structure | C35: B.01 | D35: Sub Structure | E35: Bored Pile | F35: Steel Round Pipe | G35: Steel Round Pipe (D49x2mm) with rush primer and paint | H35: kg | I35: Yes | J35: 6.84 | K35: Sub Structure|Bored Pile|Steel Round Pipe|Steel Round Pipe (D49x2mm) with rush primer and paint
A36: 31 | B36: Civil and Structure | C36: B.01 | D36: Sub Structure | E36: Bored Pile | F36: Bentonite / Slurry | G36: Bentonite / polymer slurry incl. mixing, circulation and disposal | H36: Lot | I36: - | K36: Sub Structure|Bored Pile|Bentonite / Slurry|Bentonite / polymer slurry incl. mixing, circulation and disposal
A37: 32 | B37: Civil and Structure | C37: B.01 | D37: Sub Structure | E37: Bored Pile | F37: Bored Pile Head Cutting | G37: Pile Head Cutting up to required level D1000mm | H37: Nos | I37: Yes | J37: 66 | K37: Sub Structure|Bored Pile|Bored Pile Head Cutting|Pile Head Cutting up to required level D1000mm
A38: 33 | B38: Civil and Structure | C38: B.01 | D38: Sub Structure | E38: Bored Pile | F38: Bored Pile Head Cutting | G38: Pile Head Cutting up to required level D800mm | H38: Nos | I38: Yes | J38: 48 | K38: Sub Structure|Bored Pile|Bored Pile Head Cutting|Pile Head Cutting up to required level D800mm
A39: 34 | B39: Civil and Structure | C39: B.01 | D39: Sub Structure | E39: Bored Pile | F39: Bored Pile Testing | G39: Sonic Logging Test (SLT) | H39: Nos | I39: Yes | J39: 55 | K39: Sub Structure|Bored Pile|Bored Pile Testing|Sonic Logging Test (SLT)
A40: 35 | B40: Civil and Structure | C40: B.01 | D40: Sub Structure | E40: Bored Pile | F40: Bored Pile Testing | G40: Pile Integrity Test (PIT) | H40: Nos | I40: - | K40: Sub Structure|Bored Pile|Bored Pile Testing|Pile Integrity Test (PIT)
A41: 36 | B41: Civil and Structure | C41: B.01 | D41: Sub Structure | E41: Bored Pile | F41: Bored Pile Coring | G41: Soil Coring for Bored Pile D1000mm, Depth 30m | H41: Nos | I41: Yes | J41: 385 | K41: Sub Structure|Bored Pile|Bored Pile Coring|Soil Coring for Bored Pile D1000mm, Depth 30m
A42: 37 | B42: Civil and Structure | C42: B.01 | D42: Sub Structure | E42: Bored Pile | F42: Bored Pile Coring | G42: Soil Coring for Bored Pile D800mm, Depth 30m | H42: Nos | I42: Yes | J42: 330 | K42: Sub Structure|Bored Pile|Bored Pile Coring|Soil Coring for Bored Pile D800mm, Depth 30m
A43: 38 | B43: Civil and Structure | C43: B.01 | D43: Sub Structure | E43: Bored Pile | F43: Pile Load Test | G43: Dynamic pile load test (PDA) | H43: Nos | I43: - | K43: Sub Structure|Bored Pile|Pile Load Test|Dynamic pile load test (PDA)
...

Sheet Entry Template
A1: BoQ TAKE-OFF ENTRY TEMPLATE — 4-level dependent drop-downs
A2: Pick in order: Section → Sub Section → Sub Element → Description. Budget Code, Unit and existing Rate fill in automatically.
A4: No. | B4: Discipline | C4: Section | D4: Sub Section | E4: Sub Element | F4: Description (Material Type) | G4: Budget Code | H4: Unit | I4: Quantity | J4: In Price List | K4: Current Rate ($) | L4: Amount ($) | M4: h1 | N4: h2 | O4: h3
A5: =IF($C5="","",ROW()-4) | G5: =IFERROR(INDEX('Description Library'!$C$6:$C$808,MATCH($C5&"|"&$D5&"|"&$E5&"|"&$F5,'Description Library'!$K$6:$K$808,0)),"") | H5: =IFERROR(INDEX('Description Library'!$H$6:$H$808,MATCH($C5&"|"&$D5&"|"&$E5&"|"&$F5,'Description Library'!$K$6:$K$808,0)),"") | J5: =IFERROR(INDEX('Description Library'!$I$6:$I$808,MATCH($C5&"|"&$D5&"|"&$E5&"|"&$F5,'Description Library'!$K$6:$K$808,0)),"") | K5: =IFERROR(INDEX('Description Library'!$J$6:$J$808,MATCH($C5&"|"&$D5&"|"&$E5&"|"&$F5,'Description Library'!$K$6:$K$808,0)),"") | L5: =IF(OR($I5="",$K5=""),"",$I5*$K5) | M5: =IFERROR(VLOOKUP($C5,MAP_SEC,2,0),"L_SECTION") -> L_SECTION | N5: =IFERROR(VLOOKUP($C5&"|"&$D5,MAP_SUB,2,0),"L_SECTION") -> L_SECTION | O5: =IFERROR(VLOOKUP($C5&"|"&$D5&"|"&$E5,MAP_SE,2,0),"L_SECTION") -> L_SECTION
A6: =IF($C6="","",ROW()-4) | G6: =IFERROR(INDEX('Description Library'!$C$6:$C$808,MATCH($C6&"|"&$D6&"|"&$E6&"|"&$F6,'Description Library'!$K$6:$K$808,0)),"") | H6: =IFERROR(INDEX('Description Library'!$H$6:$H$808,MATCH($C6&"|"&$D6&"|"&$E6&"|"&$F6,'Description Library'!$K$6:$K$808,0)),"") | J6: =IFERROR(INDEX('Description Library'!$I$6:$I$808,MATCH($C6&"|"&$D6&"|"&$E6&"|"&$F6,'Description Library'!$K$6:$K$808,0)),"") | K6: =IFERROR(INDEX('Description Library'!$J$6:$J$808,MATCH($C6&"|"&$D6&"|"&$E6&"|"&$F6,'Description Library'!$K$6:$K$808,0)),"") | L6: =IF(OR($I6="",$K6=""),"",$I6*$K6) | M6: =IFERROR(VLOOKUP($C6,MAP_SEC,2,0),"L_SECTION") -> L_SECTION | N6: =IFERROR(VLOOKUP($C6&"|"&$D6,MAP_SUB,2,0),"L_SECTION") -> L_SECTION | O6: =IFERROR(VLOOKUP($C6&"|"&$D6&"|"&$E6,MAP_SE,2,0),"L_SECTION") -> L_SECTION
A7: =IF($C7="","",ROW()-4) | G7: =IFERROR(INDEX('Description Library'!$C$6:$C$808,MATCH($C7&"|"&$D7&"|"&$E7&"|"&$F7,'Description Library'!$K$6:$K$808,0)),"") | H7: =IFERROR(INDEX('Description Library'!$H$6:$H$808,MATCH($C7&"|"&$D7&"|"&$E7&"|"&$F7,'Description Library'!$K$6:$K$808,0)),"") | J7: =IFERROR(INDEX('Description Library'!$I$6:$I$808,MATCH($C7&"|"&$D7&"|"&$E7&"|"&$F7,'Description Library'!$K$6:$K$808,0)),"") | K7: =IFERROR(INDEX('Description Library'!$J$6:$J$808,MATCH($C7&"|"&$D7&"|"&$E7&"|"&$F7,'Description Library'!$K$6:$K$808,0)),"") | L7: =IF(OR($I7="",$K7=""),"",$I7*$K7) | M7: =IFERROR(VLOOKUP($C7,MAP_SEC,2,0),"L_SECTION") -> L_SECTION | N7: =IFERROR(VLOOKUP($C7&"|"&$D7,MAP_SUB,2,0),"L_SECTION") -> L_SECTION | O7: =IFERROR(VLOOKUP($C7&"|"&$D7&"|"&$E7,MAP_SE,2,0),"L_SECTION") -> L_SECTION
A8: =IF($C8="","",ROW()-4) | G8: =IFERROR(INDEX('Description Library'!$C$6:$C$808,MATCH($C8&"|"&$D8&"|"&$E8&"|"&$F8,'Description Library'!$K$6:$K$808,0)),"") | H8: =IFERROR(INDEX('Description Library'!$H$6:$H$808,MATCH($C8&"|"&$D8&"|"&$E8&"|"&$F8,'Description Library'!$K$6:$K$808,0)),"") | J8: =IFERROR(INDEX('Description Library'!$I$6:$I$808,MATCH($C8&"|"&$D8&"|"&$E8&"|"&$F8,'Description Library'!$K$6:$K$808,0)),"") | K8: =IFERROR(INDEX('Description Library'!$J$6:$J$808,MATCH($C8&"|"&$D8&"|"&$E8&"|"&$F8,'Description Library'!$K$6:$K$808,0)),"") | L8: =IF(OR($I8="",$K8=""),"",$I8*$K8) | M8: =IFERROR(VLOOKUP($C8,MAP_SEC,2,0),"L_SECTION") -> L_SECTION | N8: =IFERROR(VLOOKUP($C8&"|"&$D8,MAP_SUB,2,0),"L_SECTION") -> L_SECTION | O8: =IFERROR(VLOOKUP($C8&"|"&$D8&"|"&$E8,MAP_SE,2,0),"L_SECTION") -> L_SECTION
A9: =IF($C9="","",ROW()-4) | G9: =IFERROR(INDEX('Description Library'!$C$6:$C$808,MATCH($C9&"|"&$D9&"|"&$E9&"|"&$F9,'Description Library'!$K$6:$K$808,0)),"") | H9: =IFERROR(INDEX('Description Library'!$H$6:$H$808,MATCH($C9&"|"&$D9&"|"&$E9&"|"&$F9,'Description Library'!$K$6:$K$808,0)),"") | J9: =IFERROR(INDEX('Description Library'!$I$6:$I$808,MATCH($C9&"|"&$D9&"|"&$E9&"|"&$F9,'Description Library'!$K$6:$K$808,0)),"") | K9: =IFERROR(INDEX('Description Library'!$J$6:$J$808,MATCH($C9&"|"&$D9&"|"&$E9&"|"&$F9,'Description Library'!$K$6:$K$808,0)),"") | L9: =IF(OR($I9="",$K9=""),"",$I9*$K9) | M9: =IFERROR(VLOOKUP($C9,MAP_SEC,2,0),"L_SECTION") -> L_SECTION | N9: =IFERROR(VLOOKUP($C9&"|"&$D9,MAP_SUB,2,0),"L_SECTION") -> L_SECTION | O9: =IFERROR(VLOOKUP($C9&"|"&$D9&"|"&$E9,MAP_SE,2,0),"L_SECTION") -> L_SECTION
A10: =IF($C10="","",ROW()-4) | G10: =IFERROR(INDEX('Description Library'!$C$6:$C$808,MATCH($C10&"|"&$D10&"|"&$E10&"|"&$F10,'Description Library'!$K$6:$K$808,0)),"") | H10: =IFERROR(INDEX('Description Library'!$H$6:$H$808,MATCH($C10&"|"&$D10&"|"&$E10&"|"&$F10,'Description Library'!$K$6:$K$808,0)),"") | J10: =IFERROR(INDEX('Description Library'!$I$6:$I$808,MATCH($C10&"|"&$D10&"|"&$E10&"|"&$F10,'Description Library'!$K$6:$K$808,0)),"") | K10: =IFERROR(INDEX('Description Library'!$J$6:$J$808,MATCH($C10&"|"&$D10&"|"&$E10&"|"&$F10,'Description Library'!$K$6:$K$808,0)),"") | L10: =IF(OR($I10="",$K10=""),"",$I10*$K10) | M10: =IFERROR(VLOOKUP($C10,MAP_SEC,2,0),"L_SECTION") -> L_SECTION | N10: =IFERROR(VLOOKUP($C10&"|"&$D10,MAP_SUB,2,0),"L_SECTION") -> L_SECTION | O10: =IFERROR(VLOOKUP($C10&"|"&$D10&"|"&$E10,MAP_SE,2,0),"L_SECTION") -> L_SECTION
A11: =IF($C11="","",ROW()-4) | G11: =IFERROR(INDEX('Description Library'!$C$6:$C$808,MATCH($C11&"|"&$D11&"|"&$E11&"|"&$F11,'Description Library'!$K$6:$K$808,0)),"") | H11: =IFERROR(INDEX('Description Library'!$H$6:$H$808,MATCH($C11&"|"&$D11&"|"&$E11&"|"&$F11,'Description Library'!$K$6:$K$808,0)),"") | J11: =IFERROR(INDEX('Description Library'!$I$6:$I$808,MATCH($C11&"|"&$D11&"|"&$E11&"|"&$F11,'Description Library'!$K$6:$K$808,0)),"") | K11: =IFERROR(INDEX('Description Library'!$J$6:$J$808,MATCH($C11&"|"&$D11&"|"&$E11&"|"&$F11,'Description Library'!$K$6:$K$808,0)),"") | L11: =IF(OR($I11="",$K11=""),"",$I11*$K11) | M11: =IFERROR(VLOOKUP($C11,MAP_SEC,2,0),"L_SECTION") -> L_SECTION | N11: =IFERROR(VLOOKUP($C11&"|"&$D11,MAP_SUB,2,0),"L_SECTION") -> L_SECTION | O11: =IFERROR(VLOOKUP($C11&"|"&$D11&"|"&$E11,MAP_SE,2,0),"L_SECTION") -> L_SECTION
A12: =IF($C12="","",ROW()-4) | G12: =IFERROR(INDEX('Description Library'!$C$6:$C$808,MATCH($C12&"|"&$D12&"|"&$E12&"|"&$F12,'Description Library'!$K$6:$K$808,0)),"") | H12: =IFERROR(INDEX('Description Library'!$H$6:$H$808,MATCH($C12&"|"&$D12&"|"&$E12&"|"&$F12,'Description Library'!$K$6:$K$808,0)),"") | J12: =IFERROR(INDEX('Description Library'!$I$6:$I$808,MATCH($C12&"|"&$D12&"|"&$E12&"|"&$F12,'Description Library'!$K$6:$K$808,0)),"") | K12: =IFERROR(INDEX('Description Library'!$J$6:$J$808,MATCH($C12&"|"&$D12&"|"&$E12&"|"&$F12,'Description Library'!$K$6:$K$808,0)),"") | L12: =IF(OR($I12="",$K12=""),"",$I12*$K12) | M12: =IFERROR(VLOOKUP($C12,MAP_SEC,2,0),"L_SECTION") -> L_SECTION | N12: =IFERROR(VLOOKUP($C12&"|"&$D12,MAP_SUB,2,0),"L_SECTION") -> L_SECTION | O12: =IFERROR(VLOOKUP($C12&"|"&$D12&"|"&$E12,MAP_SE,2,0),"L_SECTION") -> L_SECTION
A13: =IF($C13="","",ROW()-4) | G13: =IFERROR(INDEX('Description Library'!$C$6:$C$808,MATCH($C13&"|"&$D13&"|"&$E13&"|"&$F13,'Description Library'!$K$6:$K$808,0)),"") | H13: =IFERROR(INDEX('Description Library'!$H$6:$H$808,MATCH($C13&"|"&$D13&"|"&$E13&"|"&$F13,'Description Library'!$K$6:$K$808,0)),"") | J13: =IFERROR(INDEX('Description Library'!$I$6:$I$808,MATCH($C13&"|"&$D13&"|"&$E13&"|"&$F13,'Description Library'!$K$6:$K$808,0)),"") | K13: =IFERROR(INDEX('Description Library'!$J$6:$J$808,MATCH($C13&"|"&$D13&"|"&$E13&"|"&$F13,'Description Library'!$K$6:$K$808,0)),"") | L13: =IF(OR($I13="",$K13=""),"",$I13*$K13) | M13: =IFERROR(VLOOKUP($C13,MAP_SEC,2,0),"L_SECTION") -> L_SECTION | N13: =IFERROR(VLOOKUP($C13&"|"&$D13,MAP_SUB,2,0),"L_SECTION") -> L_SECTION | O13: =IFERROR(VLOOKUP($C13&"|"&$D13&"|"&$E13,MAP_SE,2,0),"L_SECTION") -> L_SECTION
A14: =IF($C14="","",ROW()-4) | G14: =IFERROR(INDEX('Description Library'!$C$6:$C$808,MATCH($C14&"|"&$D14&"|"&$E14&"|"&$F14,'Description Library'!$K$6:$K$808,0)),"") | H14: =IFERROR(INDEX('Description Library'!$H$6:$H$808,MATCH($C14&"|"&$D14&"|"&$E14&"|"&$F14,'Description Library'!$K$6:$K$808,0)),"") | J14: =IFERROR(INDEX('Description Library'!$I$6:$I$808,MATCH($C14&"|"&$D14&"|"&$E14&"|"&$F14,'Description Library'!$K$6:$K$808,0)),"") | K14: =IFERROR(INDEX('Description Library'!$J$6:$J$808,MATCH($C14&"|"&$D14&"|"&$E14&"|"&$F14,'Description Library'!$K$6:$K$808,0)),"") | L14: =IF(OR($I14="",$K14=""),"",$I14*$K14) | M14: =IFERROR(VLOOKUP($C14,MAP_SEC,2,0),"L_SECTION") -> L_SECTION | N14: =IFERROR(VLOOKUP($C14&"|"&$D14,MAP_SUB,2,0),"L_SECTION") -> L_SECTION | O14: =IFERROR(VLOOKUP($C14&"|"&$D14&"|"&$E14,MAP_SE,2,0),"L_SECTION") -> L_SECTION
A15: =IF($C15="","",ROW()-4) | G15: =IFERROR(INDEX('Description Library'!$C$6:$C$808,MATCH($C15&"|"&$D15&"|"&$E15&"|"&$F15,'Description Library'!$K$6:$K$808,0)),"") | H15: =IFERROR(INDEX('Description Library'!$H$6:$H$808,MATCH($C15&"|"&$D15&"|"&$E15&"|"&$F15,'Description Library'!$K$6:$K$808,0)),"") | J15: =IFERROR(INDEX('Description Library'!$I$6:$I$808,MATCH($C15&"|"&$D15&"|"&$E15&"|"&$F15,'Description Library'!$K$6:$K$808,0)),"") | K15: =IFERROR(INDEX('Description Library'!$J$6:$J$808,MATCH($C15&"|"&$D15&"|"&$E15&"|"&$F15,'Description Library'!$K$6:$K$808,0)),"") | L15: =IF(OR($I15="",$K15=""),"",$I15*$K15) | M15: =IFERROR(VLOOKUP($C15,MAP_SEC,2,0),"L_SECTION") -> L_SECTION | N15: =IFERROR(VLOOKUP($C15&"|"&$D15,MAP_SUB,2,0),"L_SECTION") -> L_SECTION | O15: =IFERROR(VLOOKUP($C15&"|"&$D15&"|"&$E15,MAP_SE,2,0),"L_SECTION") -> L_SECTION
A16: =IF($C16="","",ROW()-4) | G16: =IFERROR(INDEX('Description Library'!$C$6:$C$808,MATCH($C16&"|"&$D16&"|"&$E16&"|"&$F16,'Description Library'!$K$6:$K$808,0)),"") | H16: =IFERROR(INDEX('Description Library'!$H$6:$H$808,MATCH($C16&"|"&$D16&"|"&$E16&"|"&$F16,'Description Library'!$K$6:$K$808,0)),"") | J16: =IFERROR(INDEX('Description Library'!$I$6:$I$808,MATCH($C16&"|"&$D16&"|"&$E16&"|"&$F16,'Description Library'!$K$6:$K$808,0)),"") | K16: =IFERROR(INDEX('Description Library'!$J$6:$J$808,MATCH($C16&"|"&$D16&"|"&$E16&"|"&$F16,'Description Library'!$K$6:$K$808,0)),"") | L16: =IF(OR($I16="",$K16=""),"",$I16*$K16) | M16: =IFERROR(VLOOKUP($C16,MAP_SEC,2,0),"L_SECTION") -> L_SECTION | N16: =IFERROR(VLOOKUP($C16&"|"&$D16,MAP_SUB,2,0),"L_SECTION") -> L_SECTION | O16: =IFERROR(VLOOKUP($C16&"|"&$D16&"|"&$E16,MAP_SE,2,0),"L_SECTION") -> L_SECTION
... A204: =IF($C204="","",ROW()-4) | G204: =IFERROR(INDEX('Description Library'!$C$6:$C$808,MATCH($C204&"|"&$D204&"|"&$E204&"|"&$F204,'Description Library'!$K$6:$K$808,0)),"") | H204: =IFERROR(INDEX('Description Library'!$H$6:$H$808,MATCH($C204&"|"&$D204&"|"&$E204&"|"&$F204,'Description Library'!$K$6:$K$808,0)),"") | J204: =IFERROR(INDEX('Description Library'!$I$6:$I$808,MATCH($C204&"|"&$D204&"|"&$E204&"|"&$F204,'Description Library'!$K$6:$K$808,0)),"") | K204: =IFERROR(INDEX('Description Library'!$J$6:$J$808,MATCH($C204&"|"&$D204&"|"&$E204&"|"&$F204,'Description Library'!$K$6:$K$808,0)),"") | L204: =IF(OR($I204="",$K204=""),"",$I204*$K204) | M204: =IFERROR(VLOOKUP($C204,MAP_SEC,2,0),"L_SECTION") -> L_SECTION | N204: =IFERROR(VLOOKUP($C204&"|"&$D204,MAP_SUB,2,0),"L_SECTION") -> L_SECTION | O204: =IFERROR(VLOOKUP($C204&"|"&$D204&"|"&$E204,MAP_SE,2,0),"L_SECTION") -> L_SECTION

Sheet Validation Lists
A1: VALIDATION SOURCE LISTS — do not delete (drives the drop-downs on Entry Template)
A2: Referenced by defined names. To extend: add to Element Library / Description Library, then add here.
A4: Section | C4: Section | D4: Range | F4: Section|SubSection | G4: Range | I4: Section|SubSection|SubElement | J4: Range | M4: SEC001 | N4: SEC002 | O4: SEC003 | P4: SEC004 | Q4: SEC005 | R4: SEC006 | S4: SEC007 | T4: SEC008 | U4: SEC009 | V4: SEC010 | W4: SEC011 | X4: SEC012 | Y4: SEC013 | Z4: SEC014 | AA4: SEC015 | AB4: SEC016 | AC4: SEC017 | AD4: SEC018 | AE4: SEC019 | AF4: SEC020 | AG4: SEC021 | AH4: SEC022 | AI4: SEC023 | AJ4: SEC024 | AK4: SEC025 | AL4: SEC026 | AM4: SEC027 | AN4: SEC028 | AO4: SEC029 | AP4: SUB001 | AQ4: SUB002 | AR4: SUB003 | AS4: SUB004 | AT4: SUB005 | AU4: SUB006 | AV4: SUB007 | AW4: SUB008 | AX4: SUB009 | AY4: SUB010 | AZ4: SUB011 | BA4: SUB012 | BB4: SUB013 | BC4: SUB014 | BD4: SUB015 | BE4: SUB016 | BF4: SUB017 | BG4: SUB018 | BH4: SUB019 | BI4: SUB020 | BJ4: SUB021 | BK4: SUB022 | BL4: SUB023 | BM4: SUB024 | BN4: SUB025 | BO4: SUB026 | BP4: SUB027 | BQ4: SUB028 | BR4: SUB029 | BS4: SUB030 | BT4: SUB031 | BU4: SUB032 | BV4: SUB033 | BW4: SUB034 | BX4: SUB035 | BY4: SUB036 | BZ4: SUB037 | CA4: SUB038 | CB4: SUB039 | CC4: SUB040 | CD4: SUB041 | CE4: SUB042 | CF4: SUB043 | CG4: SUB044 | CH4: SUB045 | CI4: SUB046 | CJ4: SUB047 | CK4: SUB048 | CL4: SUB049 | CM4: SUB050 | CN4: SUB051 | CO4: SUB052 | CP4: SUB053 | CQ4: SUB054 | CR4: SUB055 | CS4: SUB056 | CT4: SUB057 | CU4: SUB058 | CV4: SUB059 | CW4: SUB060 | CX4: SUB061 | CY4: SUB062 | CZ4: SUB063 | DA4: SUB064 | DB4: SUB065 | DC4: SUB066 | DD4: SUB067 | DE4: SUB068 | DF4: SUB069 | DG4: SUB070 | DH4: SUB071 | DI4: SUB072 | DJ4: SUB073 | DK4: SUB074 | DL4: SUB075 | DM4: SUB076 | DN4: SUB077 | DO4: SUB078 | DP4: SUB079 | DQ4: SUB080 | DR4: SUB081 | DS4: SUB082 | DT4: SUB083 | DU4: SUB084 | DV4: SUB085 | DW4: SUB086 | DX4: SUB087 | DY4: SUB088 | DZ4: SUB089 | EA4: SUB090 | EB4: SUB091 | EC4: SUB092 | ED4: SUB093 | EE4: SUB094 | EF4: SUB095 | EG4: SUB096 | EH4: SUB097 | EI4: SUB098 | EJ4: SUB099 | EK4: SUB100 | EL4: SUB101 | EM4: SUB102 | EN4: SUB103 | EO4: SUB104 | EP4: SUB105 | EQ4: SUB106 | ER4: SUB107 | ES4: SUB108 | ET4: SUB109 | EU4: SUB110 | EV4: SUB111 | EW4: SUB112 | EX4: SUB113 | EY4: SUB114 | EZ4: SUB115 | FA4: SUB116 | FB4: SUB117 | FC4: SUB118 | FD4: SUB119 | FE4: SUB120 | FF4: SUB121 | FG4: SUB122 | FH4: SUB123 | FI4: SUB124 | FJ4: DSC001 | FK4: DSC002 | FL4: DSC003 | FM4: DSC004 | FN4: DSC005 | FO4: DSC006 | FP4: DSC007 | FQ4: DSC008 | FR4: DSC009 | FS4: DSC010 | FT4: DSC011 | FU4: DSC012 | FV4: DSC013 | FW4: DSC014 | FX4: DSC015 | FY4: DSC016 | FZ4: DSC017 | GA4: DSC018 | GB4: DSC019 | GC4: DSC020 | GD4: DSC021 | GE4: DSC022 | GF4: DSC023 | GG4: DSC024 | GH4: DSC025 | GI4: DSC026 | GJ4: DSC027 | GK4: DSC028 | GL4: DSC029 | GM4: DSC030 | GN4: DSC031 | GO4: DSC032 | GP4: DSC033 | GQ4: DSC034 | GR4: DSC035 | GS4: DSC036 | GT4: DSC037 | GU4: DSC038 | GV4: DSC039 | GW4: DSC040 | GX4: DSC041 | GY4: DSC042 | GZ4: DSC043 | HA4: DSC044 | HB4: DSC045 | HC4: DSC046 | HD4: DSC047 | HE4: DSC048 | HF4: DSC049 | HG4: DSC050 | HH4: DSC051 | HI4: DSC052 | HJ4: DSC053 | HK4: DSC054 | HL4: DSC055 | HM4: DSC056 | HN4: DSC057 | HO4: DSC058 | HP4: DSC059 | HQ4: DSC060 | HR4: DSC061 | HS4: DSC062 | HT4: DSC063 | HU4: DSC064 | HV4: DSC065 | HW4: DSC066 | HX4: DSC067 | HY4: DSC068 | HZ4: DSC069 | IA4: DSC070 | IB4: DSC071 | IC4: DSC072 | ID4: DSC073 | IE4: DSC074 | IF4: DSC075 | IG4: DSC076 | IH4: DSC077 | II4: DSC078 | IJ4: DSC079 | IK4: DSC080 | IL4: DSC081 | IM4: DSC082 | IN4: DSC083 | IO4: DSC084 | IP4: DSC085 | IQ4: DSC086 | IR4: DSC087 | IS4: DSC088 | IT4: DSC089 | IU4: DSC090 | IV4: DSC091 | IW4: DSC092 | IX4: DSC093 | IY4: DSC094 | IZ4: DSC095 | JA4: DSC096 | JB4: DSC097 | JC4: DSC098 | JD4: DSC099 | JE4: DSC100 | JF4: DSC101 | JG4: DSC102 | JH4: DSC103 | JI4: DSC104 | JJ4: DSC105 | JK4: DSC106 | JL4: DSC107 | JM4: DSC108 | JN4: DSC109 | JO4: DSC110 | JP4: DSC111 | JQ4: DSC112 | JR4: DSC113 | JS4: DSC114 | JT4: DSC115 | JU4: DSC116 | JV4: DSC117 | JW4: DSC118 | JX4: DSC119 | JY4: DSC120 | JZ4: DSC121 | KA4: DSC122 | KB4: DSC123 | KC4: DSC124 | KD4: DSC125 | KE4: DSC126 | KF4: DSC127 | KG4: DSC128 | KH4: DSC129 | KI4: DSC130 | KJ4: DSC131 | KK4: DSC132 | KL4: DSC133 | KM4: DSC134 | KN4: DSC135 | KO4: DSC136 | KP4: DSC137 | KQ4: DSC138 | KR4: DSC139 | KS4: DSC140 | KT4: DSC141 | KU4: DSC142 | KV4: DSC143 | KW4: DSC144 | KX4: DSC145 | KY4: DSC146 | KZ4: DSC147 | LA4: DSC148 | LB4: DSC149 | LC4: DSC150 | LD4: DSC151 | LE4: DSC152 | LF4: DSC153 | LG4: DSC154 | LH4: DSC155 | LI4: DSC156 | LJ4: DSC157 | LK4: DSC158 | LL4: DSC159 | LM4: DSC160 | LN4: DSC161 | LO4: DSC162 | LP4: DSC163 | LQ4: DSC164 | LR4: DSC165 | LS4: DSC166 | LT4: DSC167 | LU4: DSC168 | LV4: DSC169 | LW4: DSC170 | LX4: DSC171 | LY4: DSC172 | LZ4: DSC173 | MA4: DSC174 | MB4: DSC175 | MC4: DSC176 | MD4: DSC177 | ME4: DSC178 | MF4: DSC179 | MG4: DSC180 | MH4: DSC181 | MI4: DSC182 | MJ4: DSC183 | MK4: DSC184 | ML4: DSC185 | MM4: DSC186 | MN4: DSC187 | MO4: DSC188 | MP4: DSC189 | MQ4: DSC190 | MR4: DSC191 | MS4: DSC192 | MT4: DSC193 | MU4: DSC194 | MV4: DSC195 | MW4: DSC196 | MX4: DSC197 | MY4: DSC198 | MZ4: DSC199 | NA4: DSC200 | NB4: DSC201 | NC4: DSC202 | ND4: DSC203 | NE4: DSC204 | NF4: DSC205 | NG4: DSC206 | NH4: DSC207 | NI4: DSC208 | NJ4: DSC209 | NK4: DSC210 | NL4: DSC211 | NM4: DSC212 | NN4: DSC213 | NO4: DSC214 | NP4: DSC215 | NQ4: DSC216 | NR4: DSC217 | NS4: DSC218 | NT4: DSC219 | NU4: DSC220 | NV4: DSC221 | NW4: DSC222 | NX4: DSC223 | NY4: DSC224 | NZ4: DSC225 | OA4: DSC226 | OB4: DSC227 | OC4: DSC228 | OD4: DSC229 | OE4: DSC230 | OF4: DSC231 | OG4: DSC232 | OH4: DSC233 | OI4: DSC234 | OJ4: DSC235 | OK4: DSC236 | OL4: DSC237 | OM4: DSC238 | ON4: DSC239 | OO4: DSC240 | OP4: DSC241 | OQ4: DSC242 | OR4: DSC243 | OS4: DSC244 | OT4: DSC245 | OU4: DSC246 | OV4: DSC247 | OW4: DSC248 | OX4: DSC249 | OY4: DSC250 | OZ4: DSC251 | PA4: DSC252 | PB4: DSC253 | PC4: DSC254 | PD4: DSC255 | PE4: DSC256 | PF4: DSC257 | PG4: DSC258 | PH4: DSC259 | PI4: DSC260 | PJ4: DSC261 | PK4: DSC262 | PL4: DSC263 | PM4: DSC264 | PN4: DSC265 | PO4: DSC266 | PP4: DSC267 | PQ4: DSC268 | PR4: DSC269 | PS4: DSC270 | PT4: DSC271 | PU4: DSC272 | PV4: DSC273 | PW4: DSC274 | PX4: DSC275 | PY4: DSC276 | PZ4: DSC277 | QA4: DSC278 | QB4: DSC279 | QC4: DSC280 | QD4: DSC281 | QE4: DSC282 | QF4: DSC283 | QG4: DSC284 | QH4: DSC285 | QI4: DSC286 | QJ4: DSC287 | QK4: DSC288 | QL4: DSC289 | QM4: DSC290 | QN4: DSC291 | QO4: DSC292 | QP4: DSC293 | QQ4: DSC294 | QR4: DSC295 | QS4: DSC296 | QT4: DSC297 | QU4: DSC298 | QV4: DSC299 | QW4: DSC300 | QX4: DSC301 | QY4: DSC302 | QZ4: DSC303 | RA4: DSC304 | RB4: DSC305 | RC4: DSC306 | RD4: DSC307 | RE4: DSC308 | RF4: DSC309 | RG4: DSC310 | RH4: DSC311 | RI4: DSC312 | RJ4: DSC313 | RK4: DSC314 | RL4: DSC315 | RM4: DSC316 | RN4: DSC317 | RO4: DSC318 | RP4: DSC319 | RQ4: DSC320 | RR4: DSC321 | RS4: DSC322 | RT4: DSC323 | RU4: DSC324 | RV4: DSC325 | RW4: DSC326 | RX4: DSC327 | RY4: DSC328 | RZ4: DSC329 | SA4: DSC330 | SB4: DSC331 | SC4: DSC332 | SD4: DSC333 | SE4: DSC334 | SF4: DSC335 | SG4: DSC336 | SH4: DSC337 | SI4: DSC338 | SJ4: DSC339 | SK4: DSC340 | SL4: DSC341 | SM4: DSC342 | SN4: DSC343 | SO4: DSC344 | SP4: DSC345 | SQ4: DSC346 | SR4: DSC347 | SS4: DSC348 | ST4: DSC349 | SU4: DSC350 | SV4: DSC351 | SW4: DSC352 | SX4: DSC353 | SY4: DSC354 | SZ4: DSC355 | TA4: DSC356 | TB4: DSC357 | TC4: DSC358 | TD4: DSC359 | TE4: DSC360 | TF4: DSC361 | TG4: DSC362 | TH4: DSC363 | TI4: DSC364 | TJ4: DSC365 | TK4: DSC366 | TL4: DSC367 | TM4: DSC368 | TN4: DSC369 | TO4: DSC370 | TP4: DSC371 | TQ4: DSC372 | TR4: DSC373 | TS4: DSC374 | TT4: DSC375 | TU4: DSC376 | TV4: DSC377 | TW4: DSC378 | TX4: DSC379 | TY4: DSC380 | TZ4: DSC381 | UA4: DSC382 | UB4: DSC383 | UC4: DSC384 | UD4: DSC385 | UE4: DSC386 | UF4: DSC387 | UG4: DSC388 | UH4: DSC389 | UI4: DSC390 | UJ4: DSC391 | UK4: DSC392 | UL4: DSC393 | UM4: DSC394 | UN4: DSC395 | UO4: DSC396 | UP4: DSC397 | UQ4: DSC398 | UR4: DSC399 | US4: DSC400 | UT4: DSC401 | UU4: DSC402 | UV4: DSC403 | UW4: DSC404 | UX4: DSC405 | UY4: DSC406 | UZ4: DSC407 | VA4: DSC408 | VB4: DSC409 | VC4: DSC410 | VD4: DSC411 | VE4: DSC412 | VF4: DSC413 | VG4: DSC414 | VH4: DSC415 | VI4: DSC416 | VJ4: DSC417 | VK4: DSC418 | VL4: DSC419 | VM4: DSC420 | VN4: DSC421 | VO4: DSC422 | VP4: DSC423 | VQ4: DSC424 | VR4: DSC425 | VS4: DSC426 | VT4: DSC427 | VU4: DSC428 | VV4: DSC429 | VW4: DSC430 | VX4: DSC431 | VY4: DSC432 | VZ4: DSC433 | WA4: DSC434 | WB4: DSC435 | WC4: DSC436 | WD4: DSC437 | WE4: DSC438 | WF4: DSC439 | WG4: DSC440 | WH4: DSC441 | WI4: DSC442 | WJ4: DSC443 | WK4: DSC444 | WL4: DSC445 | WM4: DSC446 | WN4: DSC447 | WO4: DSC448 | WP4: DSC449 | WQ4: DSC450 | WR4: DSC451 | WS4: DSC452 | WT4: DSC453 | WU4: DSC454 | WV4: DSC455 | WW4: DSC456 | WX4: DSC457 | WY4: DSC458 | WZ4: DSC459 | XA4: DSC460 | XB4: DSC461 | XC4: DSC462 | XD4: DSC463 | XE4: DSC464 | XF4: DSC465 | XG4: DSC466 | XH4: DSC467 | XI4: DSC468 | XJ4: DSC469 | XK4: DSC470 | XL4: DSC471 | XM4: DSC472 | XN4: DSC473 | XO4: DSC474 | XP4: DSC475 | XQ4: DSC476 | XR4: DSC477 | XS4: DSC478 | XT4: DSC479 | XU4: DSC480 | XV4: DSC481 | XW4: DSC482 | XX4: DSC483 | XY4: DSC484 | XZ4: DSC485 | YA4: DSC486 | YB4: DSC487 | YC4: DSC488 | YD4: DSC489 | YE4: DSC490 | YF4: DSC491 | YG4: DSC492 | YH4: DSC493 | YI4: DSC494 | YJ4: DSC495 | YK4: DSC496 | YL4: DSC497 | YM4: DSC498 | YN4: DSC499 | YO4: DSC500 | YP4: DSC501 | YQ4: DSC502 | YR4: DSC503 | YS4: DSC504 | YT4: DSC505 | YU4: DSC506 | YV4: DSC507 | YW4: DSC508 | YX4: DSC509 | YY4: DSC510 | YZ4: DSC511 | ZA4: DSC512 | ZB4: DSC513 | ZC4: DSC514 | ZD4: DSC515 | ZE4: DSC516 | ZF4: DSC517 | ZG4: DSC518 | ZH4: DSC519 | ZI4: DSC520
