Workbook
Name _B001: 'Validation Lists'!$AP$5:$AP$11
Name _B002: 'Validation Lists'!$AQ$5:$AQ$10
Name _B003: 'Validation Lists'!$AR$5:$AR$16
Name _B004: 'Validation Lists'!$AS$5:$AS$9
Name _B005: 'Validation Lists'!$AT$5:$AT$15
Name _B006: 'Validation Lists'!$AU$5:$AU$15
Name _B007: 'Validation Lists'!$AV$5:$AV$11
Name _B008: 'Validation Lists'!$AW$5:$AW$14
Name _B009: 'Validation Lists'!$AX$5:$AX$15
Name _B010: 'Validation Lists'!$AY$5:$AY$15
Name _B011: 'Validation Lists'!$AZ$5:$AZ$12
Name _B012: 'Validation Lists'!$BA$5:$BA$13
Name _B013: 'Validation Lists'!$BB$5:$BB$10
Name _B014: 'Validation Lists'!$BC$5:$BC$8
Name _B015: 'Validation Lists'!$BD$5:$BD$10
Name _B016: 'Validation Lists'!$BE$5:$BE$9
Name _B017: 'Validation Lists'!$BF$5:$BF$8
Name _B018: 'Validation Lists'!$BG$5:$BG$8
Name _B019: 'Validation Lists'!$BH$5:$BH$9
Name _B020: 'Validation Lists'!$BI$5:$BI$8
Name _B021: 'Validation Lists'!$BJ$5:$BJ$18
Name _B022: 'Validation Lists'!$BK$5:$BK$12
Name _B023: 'Validation Lists'!$BL$5:$BL$8
Name _B024: 'Validation Lists'!$BM$5:$BM$9
Name _B025: 'Validation Lists'!$BN$5:$BN$7
Name _B026: 'Validation Lists'!$BO$5:$BO$7
Name _B027: 'Validation Lists'!$BP$5:$BP$6
Name _B028: 'Validation Lists'!$BQ$5:$BQ$8
Name _B029: 'Validation Lists'!$BR$5:$BR$7
Name _B030: 'Validation Lists'!$BS$5:$BS$7
Name _B031: 'Validation Lists'!$BT$5:$BT$6
Name _B032: 'Validation Lists'!$BU$5:$BU$6
Name _B033: 'Validation Lists'!$BV$5:$BV$6
Name _B034: 'Validation Lists'!$BW$5:$BW$6
Name _B035: 'Validation Lists'!$BX$5:$BX$6
Name _B036: 'Validation Lists'!$BY$5:$BY$6
Name _B037: 'Validation Lists'!$BZ$5:$BZ$8
Name _B038: 'Validation Lists'!$CA$5:$CA$8
Name _B039: 'Validation Lists'!$CB$5:$CB$6
Name _B040: 'Validation Lists'!$CC$5:$CC$8
Name _B041: 'Validation Lists'!$CD$5:$CD$6
Name _B042: 'Validation Lists'!$CE$5:$CE$6
Name _B043: 'Validation Lists'!$CF$5:$CF$6
Name _B044: 'Validation Lists'!$CG$5:$CG$7
Name _B045: 'Validation Lists'!$CH$5:$CH$8
Name _B046: 'Validation Lists'!$CI$5:$CI$7
Name _B047: 'Validation Lists'!$CJ$5:$CJ$8
Name _B048: 'Validation Lists'!$CK$5:$CK$8
Name _B049: 'Validation Lists'!$CL$5:$CL$8
Name _B050: 'Validation Lists'!$CM$5:$CM$8
Name _B051: 'Validation Lists'!$CN$5:$CN$6
Name _B052: 'Validation Lists'!$CO$5:$CO$8
Name _B053: 'Validation Lists'!$CP$5:$CP$6
Name _B054: 'Validation Lists'!$CQ$5:$CQ$6
Name _B055: 'Validation Lists'!$CR$5:$CR$7
Name _B056: 'Validation Lists'!$CS$5:$CS$6
Name _B057: 'Validation Lists'!$CT$5:$CT$5
Name _B058: 'Validation Lists'!$CU$5:$CU$6
Name _B059: 'Validation Lists'!$CV$5:$CV$6
Name _B060: 'Validation Lists'!$CW$5:$CW$9

Sheet Element Library
A1: QS ELEMENT LIBRARY — SECTION / SUB SECTION / SUB ELEMENT
A2: Standard coding list for BoQ takeoff — Structure, Architecture, MEP & External Works. Aligned to the project Budget Code framework.
A3: Each Sub Element links to one or more standard Descriptions on the Description Library sheet.
A5: No. | B5: Discipline | C5: Budget Code | D5: Section | E5: Sub Section | F5: Sub Element | G5: Typical Unit | H5: No. of Desc. | I5: Default Description | J5: Key
A6: 1 | B6: Civil and Structure | C6: A.04 | D6: Sub Structure | E6: Site Preparation & Earthwork | F6: Site Clearing | G6: m2 | H6: 1 | I6: Site clearing, grubbing and removal of vegetation and debris off site | J6: Sub Structure|Site Preparation & Earthwork|Site Clearing
A7: 2 | B7: Civil and Structure | C7: A.04 | D7: Sub Structure | E7: Site Preparation & Earthwork | F7: Excavation | G7: m3 | H7: 1 | I7: Bulk excavation by machine incl. trimming and levelling of formation | J7: Sub Structure|Site Preparation & Earthwork|Excavation
A8: 3 | B8: Civil and Structure | C8: A.04 | D8: Sub Structure | E8: Site Preparation & Earthwork | F8: Backfill | G8: m3 | H8: 1 | I8: Backfilling with approved material in 200mm layers incl. compaction to 95% MDD | J8: Sub Structure|Site Preparation & Earthwork|Backfill
A9: 4 | B9: Civil and Structure | C9: A.04 | D9: Sub Structure | E9: Site Preparation & Earthwork | F9: Soil Disposal | G9: m3 | H9: 1 | I9: Cart away surplus excavated material off site incl. tipping fee | J9: Sub Structure|Site Preparation & Earthwork|Soil Disposal
A10: 5 | B10: Civil and Structure | C10: A.04 | D10: Sub Structure | E10: Site Preparation & Earthwork | F10: Compaction | G10: m2 | H10: 1 | I10: Compaction of formation to 95% MDD incl. watering and testing | J10: Sub Structure|Site Preparation & Earthwork|Compaction
A11: 6 | B11: Civil and Structure | C11: A.04 | D11: Sub Structure | E11: Site Preparation & Earthwork | F11: Dewatering | G11: Lot | H11: 1 | I11: Dewatering incl. pumps, sump pits, piping and maintenance during construction | J11: Sub Structure|Site Preparation & Earthwork|Dewatering
A12: 7 | B12: Civil and Structure | C12: A.04 | D12: Sub Structure | E12: Site Preparation & Earthwork | F12: Levelling & Setting Out | G12: m2 | H12: 1 | I12: Setting out, levelling and establishment of benchmarks and grid lines | J12: Sub Structure|Site Preparation & Earthwork|Levelling & Setting Out
A13: 8 | B13: Civil and Structure | C13: B.02 | D13: Sub Structure | E13: Shoring & Sheet Pile | F13: Sheet Pile Supply | G13: m2 | H13: 1 | I13: Supply of steel sheet pile, hot rolled section as per design | J13: Sub Structure|Shoring & Sheet Pile|Sheet Pile Supply
A14: 9 | B14: Civil and Structure | C14: B.02 | D14: Sub Structure | E14: Shoring & Sheet Pile | F14: Sheet Pile Driving | G14: m2 | H14: 1 | I14: Driving of steel sheet pile to required depth incl. plant and equipment | J14: Sub Structure|Shoring & Sheet Pile|Sheet Pile Driving
A15: 10 | B15: Civil and Structure | C15: B.02 | D15: Sub Structure | E15: Shoring & Sheet Pile | F15: Sheet Pile Extraction | G15: m2 | H15: 1 | I15: Extraction of steel sheet pile and making good of voids | J15: Sub Structure|Shoring & Sheet Pile|Sheet Pile Extraction
A16: 11 | B16: Civil and Structure | C16: B.02 | D16: Sub Structure | E16: Shoring & Sheet Pile | F16: Strut & Waler | G16: kg | H16: 1 | I16: Steel strut and waler incl. fabrication, installation and removal | J16: Sub Structure|Shoring & Sheet Pile|Strut & Waler
A17: 12 | B17: Civil and Structure | C17: B.02 | D17: Sub Structure | E17: Shoring & Sheet Pile | F17: Ground Anchor | G17: Nos | H17: 1 | I17: Ground anchor incl. drilling, grouting, stressing and testing | J17: Sub Structure|Shoring & Sheet Pile|Ground Anchor
... A523: 518 | B523: External Works | C523: G.05 | D523: External Work | E523: External fixture | F523: Playground / sport court | G523: Lot | H523: 1 | I523: Playground / sport court incl. surfacing, marking and equipment | J523: External Work|External fixture|Playground / sport court

Sheet Description Library
A1: DESCRIPTION LIBRARY — STANDARD BoQ DESCRIPTIONS (MATERIAL TYPE)
A2: One or more standard descriptions per Sub Element. Units are synchronised with the Price List Library.
A3: Copy the Description into the Material Type column of Raw Data. Edit sizes / grades to match the specification before pricing.
A5: No. | B5: Discipline | C5: Budget Code | D5: Section | E5: Sub Section | F5: Sub Element | G5: Description (Material Type) | H5: Unit | I5: Rate Status | J5: Total Rate ($) | K5: Key
A6: 1 | B6: Civil and Structure | C6: A.04 | D6: Sub Structure | E6: Site Preparation & Earthwork | F6: Site Clearing | G6: Site clearing, grubbing and removal of vegetation and debris off site | H6: m2 | I6: =IFERROR(INDEX('Price List Library'!$P$6:$P$437,MATCH(TRIM($G6)&"|"&TRIM($H6),'Price List Library'!$S$6:$S$437,0)),"") -> Benchmark | J6: =IFERROR(INDEX('Price List Library'!$O$6:$O$437,MATCH(TRIM($G6)&"|"&TRIM($H6),'Price List Library'!$S$6:$S$437,0)),0) -> 0.828 | K6: Sub Structure|Site Preparation & Earthwork|Site Clearing|Site clearing, grubbing and removal of vegetation and debris off site
A7: 2 | B7: Civil and Structure | C7: A.04 | D7: Sub Structure | E7: Site Preparation & Earthwork | F7: Excavation | G7: Bulk excavation by machine incl. trimming and levelling of formation | H7: m3 | I7: =IFERROR(INDEX('Price List Library'!$P$6:$P$437,MATCH(TRIM($G7)&"|"&TRIM($H7),'Price List Library'!$S$6:$S$437,0)),"") -> Benchmark | J7: =IFERROR(INDEX('Price List Library'!$O$6:$O$437,MATCH(TRIM($G7)&"|"&TRIM($H7),'Price List Library'!$S$6:$S$437,0)),0) -> 3.448 | K7: Sub Structure|Site Preparation & Earthwork|Excavation|Bulk excavation by machine incl. trimming and levelling of formation
A8: 3 | B8: Civil and Structure | C8: A.04 | D8: Sub Structure | E8: Site Preparation & Earthwork | F8: Backfill | G8: Backfilling with approved material in 200mm layers incl. compaction to 95% MDD | H8: m3 | I8: =IFERROR(INDEX('Price List Library'!$P$6:$P$437,MATCH(TRIM($G8)&"|"&TRIM($H8),'Price List Library'!$S$6:$S$437,0)),"") -> Benchmark | J8: =IFERROR(INDEX('Price List Library'!$O$6:$O$437,MATCH(TRIM($G8)&"|"&TRIM($H8),'Price List Library'!$S$6:$S$437,0)),0) -> 4.848 | K8: Sub Structure|Site Preparation & Earthwork|Backfill|Backfilling with approved material in 200mm layers incl. compaction to 95% MDD
A9: 4 | B9: Civil and Structure | C9: A.04 | D9: Sub Structure | E9: Site Preparation & Earthwork | F9: Soil Disposal | G9: Cart away surplus excavated material off site incl. tipping fee | H9: m3 | I9: =IFERROR(INDEX('Price List Library'!$P$6:$P$437,MATCH(TRIM($G9)&"|"&TRIM($H9),'Price List Library'!$S$6:$S$437,0)),"") -> Benchmark | J9: =IFERROR(INDEX('Price List Library'!$O$6:$O$437,MATCH(TRIM($G9)&"|"&TRIM($H9),'Price List Library'!$S$6:$S$437,0)),0) -> 4.864 | K9: Sub Structure|Site Preparation & Earthwork|Soil Disposal|Cart away surplus excavated material off site incl. tipping fee
A10: 5 | B10: Civil and Structure | C10: A.04 | D10: Sub Structure | E10: Site Preparation & Earthwork | F10: Compaction | G10: Compaction of formation to 95% MDD incl. watering and testing | H10: m2 | I10: =IFERROR(INDEX('Price List Library'!$P$6:$P$437,MATCH(TRIM($G10)&"|"&TRIM($H10),'Price List Library'!$S$6:$S$437,0)),"") -> Benchmark | J10: =IFERROR(INDEX('Price List Library'!$O$6:$O$437,MATCH(TRIM($G10)&"|"&TRIM($H10),'Price List Library'!$S$6:$S$437,0)),0) -> 1.6 | K10: Sub Structure|Site Preparation & Earthwork|Compaction|Compaction of formation to 95% MDD incl. watering and testing
A11: 6 | B11: Civil and Structure | C11: A.04 | D11: Sub Structure | E11: Site Preparation & Earthwork | F11: Dewatering | G11: Dewatering incl. pumps, sump pits, piping and maintenance during construction | H11: Lot | I11: =IFERROR(INDEX('Price List Library'!$P$6:$P$437,MATCH(TRIM($G11)&"|"&TRIM($H11),'Price List Library'!$S$6:$S$437,0)),"") -> Benchmark | J11: =IFERROR(INDEX('Price List Library'!$O$6:$O$437,MATCH(TRIM($G11)&"|"&TRIM($H11),'Price List Library'!$S$6:$S$437,0)),0) -> 3504 | K11: Sub Structure|Site Preparation & Earthwork|Dewatering|Dewatering incl. pumps, sump pits, piping and maintenance during construction
A12: 7 | B12: Civil and Structure | C12: A.04 | D12: Sub Structure | E12: Site Preparation & Earthwork | F12: Levelling & Setting Out | G12: Setting out, levelling and establishment of benchmarks and grid lines | H12: m2 | I12: =IFERROR(INDEX('Price List Library'!$P$6:$P$437,MATCH(TRIM($G12)&"|"&TRIM($H12),'Price List Library'!$S$6:$S$437,0)),"") -> Benchmark | J12: =IFERROR(INDEX('Price List Library'!$O$6:$O$437,MATCH(TRIM($G12)&"|"&TRIM($H12),'Price List Library'!$S$6:$S$437,0)),0) -> 1.008 | K12: Sub Structure|Site Preparation & Earthwork|Levelling & Setting Out|Setting out, levelling and establishment of benchmarks and grid lines
A13: 8 | B13: Civil and Structure | C13: B.02 | D13: Sub Structure | E13: Shoring & Sheet Pile | F13: Sheet Pile Supply | G13: Supply of steel sheet pile, hot rolled section as per design | H13: m2 | I13: =IFERROR(INDEX('Price List Library'!$P$6:$P$437,MATCH(TRIM($G13)&"|"&TRIM($H13),'Price List Library'!$S$6:$S$437,0)),"") -> Benchmark | J13: =IFERROR(INDEX('Price List Library'!$O$6:$O$437,MATCH(TRIM($G13)&"|"&TRIM($H13),'Price List Library'!$S$6:$S$437,0)),0) -> 64.96 | K13: Sub Structure|Shoring & Sheet Pile|Sheet Pile Supply|Supply of steel sheet pile, hot rolled section as per design
A14: 9 | B14: Civil and Structure | C14: B.02 | D14: Sub Structure | E14: Shoring & Sheet Pile | F14: Sheet Pile Driving | G14: Driving of steel sheet pile to required depth incl. plant and equipment | H14: m2 | I14: =IFERROR(INDEX('Price List Library'!$P$6:$P$437,MATCH(TRIM($G14)&"|"&TRIM($H14),'Price List Library'!$S$6:$S$437,0)),"") -> Benchmark | J14: =IFERROR(INDEX('Price List Library'!$O$6:$O$437,MATCH(TRIM($G14)&"|"&TRIM($H14),'Price List Library'!$S$6:$S$437,0)),0) -> 23.52 | K14: Sub Structure|Shoring & Sheet Pile|Sheet Pile Driving|Driving of steel sheet pile to required depth incl. plant and equipment
A15: 10 | B15: Civil and Structure | C15: B.02 | D15: Sub Structure | E15: Shoring & Sheet Pile | F15: Sheet Pile Extraction | G15: Extraction of steel sheet pile and making good of voids | H15: m2 | I15: =IFERROR(INDEX('Price List Library'!$P$6:$P$437,MATCH(TRIM($G15)&"|"&TRIM($H15),'Price List Library'!$S$6:$S$437,0)),"") -> Benchmark | J15: =IFERROR(INDEX('Price List Library'!$O$6:$O$437,MATCH(TRIM($G15)&"|"&TRIM($H15),'Price List Library'!$S$6:$S$437,0)),0) -> 14.16 | K15: Sub Structure|Shoring & Sheet Pile|Sheet Pile Extraction|Extraction of steel sheet pile and making good of voids
A16: 11 | B16: Civil and Structure | C16: B.02 | D16: Sub Structure | E16: Shoring & Sheet Pile | F16: Strut & Waler | G16: Steel strut and waler incl. fabrication, installation and removal | H16: kg | I16: =IFERROR(INDEX('Price List Library'!$P$6:$P$437,MATCH(TRIM($G16)&"|"&TRIM($H16),'Price List Library'!$S$6:$S$437,0)),"") -> Benchmark | J16: =IFERROR(INDEX('Price List Library'!$O$6:$O$437,MATCH(TRIM($G16)&"|"&TRIM($H16),'Price List Library'!$S$6:$S$437,0)),0) -> 1.648 | K16: Sub Structure|Shoring & Sheet Pile|Strut & Waler|Steel strut and waler incl. fabrication, installation and removal
A17: 12 | B17: Civil and Structure | C17: B.02 | D17: Sub Structure | E17: Shoring & Sheet Pile | F17: Ground Anchor | G17: Ground anchor incl. drilling, grouting, stressing and testing | H17: Nos | I17: =IFERROR(INDEX('Price List Library'!$P$6:$P$437,MATCH(TRIM($G17)&"|"&TRIM($H17),'Price List Library'!$S$6:$S$437,0)),"") -> Benchmark | J17: =IFERROR(INDEX('Price List Library'!$O$6:$O$437,MATCH(TRIM($G17)&"|"&TRIM($H17),'Price List Library'!$S$6:$S$437,0)),0) -> 528 | K17: Sub Structure|Shoring & Sheet Pile|Ground Anchor|Ground anchor incl. drilling, grouting, stressing and testing
... A808: 803 | B808: Architecture | C808: D.01 | D808: Interior Wall Finishes | E808: Toilet Wall tile | F808: Toilet Wall tile | G808: tile size (300x600)mm | H808: m2 | I808: =IFERROR(INDEX('Price List Library'!$P$6:$P$437,MATCH(TRIM($G808)&"|"&TRIM($H808),'Price List Library'!$S$6:$S$437,0)),"") -> Priced | J808: =IFERROR(INDEX('Price List Library'!$O$6:$O$437,MATCH(TRIM($G808)&"|"&TRIM($H808),'Price List Library'!$S$6:$S$437,0)),0) -> 18.4 | K808: Interior Wall Finishes|Toilet Wall tile|Toilet Wall tile|tile size (300x600)mm

Sheet Price List Library
A1: PRICE LIST LIBRARY — LABOR / MATERIAL RATE BUILD-UP
A2: STANDARD LABOR MARGIN | C2: 0.2 | E2: Change these two cells to re-margin the whole library at once. Rate = Net Cost x (1 + Margin %).
A3: STANDARD MATERIAL MARGIN | C3: 0.12 | E3: Status: "Priced" = rate from your project Price List. "Benchmark" = Cambodia market estimate — obtain 3 quotations before submission.
I4: LABOR | L4: MATERIAL / SUPPLY & FIX
A5: Item Code | B5: Discipline | C5: Budget Code | D5: Section | E5: Sub Section | F5: Sub Element | G5: Description (Material Type) | H5: Unit | I5: Labor Net Cost ($) | J5: Labor Margin (%) | K5: Labor Rate ($) | L5: Material Net Cost ($) | M5: Material Margin (%) | N5: Material Rate ($) | O5: Total Rate ($) | P5: Status | Q5: Used in | R5: Basis / Source | S5: MatchKey | T5: src
A6: PL-001 | B6: Civil and Structure | C6: A.04 | D6: Sub Structure | E6: Site Preparation & Earthwork | F6: Site Clearing | G6: Site clearing, grubbing and removal of vegetation and debris off site | H6: m2 | I6: 0.55 | J6: =_STDLAB -> 0.2 | K6: =IFERROR(I6*(1+J6),0) -> 0.66 | L6: 0.15 | M6: =_STDMAT -> 0.12 | N6: =IFERROR(L6*(1+M6),0) -> 0.168 | O6: =K6+N6 -> 0.828 | P6: =IF(N(I6)+N(L6)=0,"To be quoted",IF($T6="P","Priced","Benchmark")) -> Benchmark | Q6: 1 | R6: BENCHMARK (CAM market) — Clear/grub by machine; CAM labour+plant | S6: =TRIM(G6)&"|"&TRIM(H6) -> Site clearing, grubbing and removal of vegetation and debris off site|m2 | T6: B
A7: PL-002 | B7: Civil and Structure | C7: A.04 | D7: Sub Structure | E7: Site Preparation & Earthwork | F7: Excavation | G7: Bulk excavation by machine incl. trimming and levelling of formation | H7: m3 | I7: 2.5 | J7: =_STDLAB -> 0.2 | K7: =IFERROR(I7*(1+J7),0) -> 3 | L7: 0.4 | M7: =_STDMAT -> 0.12 | N7: =IFERROR(L7*(1+M7),0) -> 0.448 | O7: =K7+N7 -> 3.448 | P7: =IF(N(I7)+N(L7)=0,"To be quoted",IF($T7="P","Priced","Benchmark")) -> Benchmark | Q7: 1 | R7: BENCHMARK (CAM market) — Machine excavation; PP plant hire benchmark | S7: =TRIM(G7)&"|"&TRIM(H7) -> Bulk excavation by machine incl. trimming and levelling of formation|m3 | T7: B
A8: PL-003 | B8: Civil and Structure | C8: A.04 | D8: Sub Structure | E8: Site Preparation & Earthwork | F8: Backfill | G8: Backfilling with approved material in 200mm layers incl. compaction to 95% MDD | H8: m3 | I8: 3.2 | J8: =_STDLAB -> 0.2 | K8: =IFERROR(I8*(1+J8),0) -> 3.84 | L8: 0.9 | M8: =_STDMAT -> 0.12 | N8: =IFERROR(L8*(1+M8),0) -> 1.008 | O8: =K8+N8 -> 4.848 | P8: =IF(N(I8)+N(L8)=0,"To be quoted",IF($T8="P","Priced","Benchmark")) -> Benchmark | Q8: 1 | R8: BENCHMARK (CAM market) — Layered fill + compaction | S8: =TRIM(G8)&"|"&TRIM(H8) -> Backfilling with approved material in 200mm layers incl. compaction to 95% MDD|m3 | T8: B
A9: PL-004 | B9: Civil and Structure | C9: A.04 | D9: Sub Structure | E9: Site Preparation & Earthwork | F9: Soil Disposal | G9: Cart away surplus excavated material off site incl. tipping fee | H9: m3 | I9: 3.4 | J9: =_STDLAB -> 0.2 | K9: =IFERROR(I9*(1+J9),0) -> 4.08 | L9: 0.7 | M9: =_STDMAT -> 0.12 | N9: =IFERROR(L9*(1+M9),0) -> 0.784 | O9: =K9+N9 -> 4.864 | P9: =IF(N(I9)+N(L9)=0,"To be quoted",IF($T9="P","Priced","Benchmark")) -> Benchmark | Q9: 1 | R9: BENCHMARK (CAM market) — Haul 15-25km + tipping | S9: =TRIM(G9)&"|"&TRIM(H9) -> Cart away surplus excavated material off site incl. tipping fee|m3 | T9: B
A10: PL-005 | B10: Civil and Structure | C10: A.04 | D10: Sub Structure | E10: Site Preparation & Earthwork | F10: Compaction | G10: Compaction of formation to 95% MDD incl. watering and testing | H10: m2 | I10: 1.1 | J10: =_STDLAB -> 0.2 | K10: =IFERROR(I10*(1+J10),0) -> 1.32 | L10: 0.25 | M10: =_STDMAT -> 0.12 | N10: =IFERROR(L10*(1+M10),0) -> 0.28 | O10: =K10+N10 -> 1.6 | P10: =IF(N(I10)+N(L10)=0,"To be quoted",IF($T10="P","Priced","Benchmark")) -> Benchmark | Q10: 2 | R10: BENCHMARK (CAM market) — Roller compaction to 95% MDD | S10: =TRIM(G10)&"|"&TRIM(H10) -> Compaction of formation to 95% MDD incl. watering and testing|m2 | T10: B
A11: PL-006 | B11: Civil and Structure | C11: A.04 | D11: Sub Structure | E11: Site Preparation & Earthwork | F11: Dewatering | G11: Dewatering incl. pumps, sump pits, piping and maintenance during construction | H11: Lot | I11: 1800 | J11: =_STDLAB -> 0.2 | K11: =IFERROR(I11*(1+J11),0) -> 2160 | L11: 1200 | M11: =_STDMAT -> 0.12 | N11: =IFERROR(L11*(1+M11),0) -> 1344 | O11: =K11+N11 -> 3504 | P11: =IF(N(I11)+N(L11)=0,"To be quoted",IF($T11="P","Priced","Benchmark")) -> Benchmark | Q11: 1 | R11: BENCHMARK (CAM market) — Pump, sump, piping for programme duration | S11: =TRIM(G11)&"|"&TRIM(H11) -> Dewatering incl. pumps, sump pits, piping and maintenance during construction|Lot | T11: B
A12: PL-007 | B12: Civil and Structure | C12: A.04 | D12: Sub Structure | E12: Site Preparation & Earthwork | F12: Levelling & Setting Out | G12: Setting out, levelling and establishment of benchmarks and grid lines | H12: m2 | I12: 0.7 | J12: =_STDLAB -> 0.2 | K12: =IFERROR(I12*(1+J12),0) -> 0.84 | L12: 0.15 | M12: =_STDMAT -> 0.12 | N12: =IFERROR(L12*(1+M12),0) -> 0.168 | O12: =K12+N12 -> 1.008 | P12: =IF(N(I12)+N(L12)=0,"To be quoted",IF($T12="P","Priced","Benchmark")) -> Benchmark | Q12: 1 | R12: BENCHMARK (CAM market) — Survey team + instrument | S12: =TRIM(G12)&"|"&TRIM(H12) -> Setting out, levelling and establishment of benchmarks and grid lines|m2 | T12: B
A13: PL-008 | B13: Civil and Structure | C13: B.02 | D13: Sub Structure | E13: Shoring & Sheet Pile | F13: Sheet Pile Supply | G13: Supply of steel sheet pile, hot rolled section as per design | H13: m2 | I13: 0 | J13: =_STDLAB -> 0.2 | K13: =IFERROR(I13*(1+J13),0) -> 0 | L13: 58 | M13: =_STDMAT -> 0.12 | N13: =IFERROR(L13*(1+M13),0) -> 64.96 | O13: =K13+N13 -> 64.96 | P13: =IF(N(I13)+N(L13)=0,"To be quoted",IF($T13="P","Priced","Benchmark")) -> Benchmark | Q13: 1 | R13: BENCHMARK (CAM market) — Hot rolled sheet pile ~$780/t delivered | S13: =TRIM(G13)&"|"&TRIM(H13) -> Supply of steel sheet pile, hot rolled section as per design|m2 | T13: B
A14: PL-009 | B14: Civil and Structure | C14: B.02 | D14: Sub Structure | E14: Shoring & Sheet Pile | F14: Sheet Pile Driving | G14: Driving of steel sheet pile to required depth incl. plant and equipment | H14: m2 | I14: 14 | J14: =_STDLAB -> 0.2 | K14: =IFERROR(I14*(1+J14),0) -> 16.8 | L14: 6 | M14: =_STDMAT -> 0.12 | N14: =IFERROR(L14*(1+M14),0) -> 6.72 | O14: =K14+N14 -> 23.52 | P14: =IF(N(I14)+N(L14)=0,"To be quoted",IF($T14="P","Priced","Benchmark")) -> Benchmark | Q14: 1 | R14: BENCHMARK (CAM market) — Vibro hammer + crane | S14: =TRIM(G14)&"|"&TRIM(H14) -> Driving of steel sheet pile to required depth incl. plant and equipment|m2 | T14: B
A15: PL-010 | B15: Civil and Structure | C15: B.02 | D15: Sub Structure | E15: Shoring & Sheet Pile | F15: Sheet Pile Extraction | G15: Extraction of steel sheet pile and making good of voids | H15: m2 | I15: 9 | J15: =_STDLAB -> 0.2 | K15: =IFERROR(I15*(1+J15),0) -> 10.8 | L15: 3 | M15: =_STDMAT -> 0.12 | N15: =IFERROR(L15*(1+M15),0) -> 3.36 | O15: =K15+N15 -> 14.16 | P15: =IF(N(I15)+N(L15)=0,"To be quoted",IF($T15="P","Priced","Benchmark")) -> Benchmark | Q15: 1 | R15: BENCHMARK (CAM market) — Extraction + void grouting | S15: =TRIM(G15)&"|"&TRIM(H15) -> Extraction of steel sheet pile and making good of voids|m2 | T15: B
A16: PL-011 | B16: Civil and Structure | C16: B.02 | D16: Sub Structure | E16: Shoring & Sheet Pile | F16: Strut & Waler | G16: Steel strut and waler incl. fabrication, installation and removal | H16: kg | I16: 0.3 | J16: =_STDLAB -> 0.2 | K16: =IFERROR(I16*(1+J16),0) -> 0.36 | L16: 1.15 | M16: =_STDMAT -> 0.12 | N16: =IFERROR(L16*(1+M16),0) -> 1.288 | O16: =K16+N16 -> 1.648 | P16: =IF(N(I16)+N(L16)=0,"To be quoted",IF($T16="P","Priced","Benchmark")) -> Benchmark | Q16: 1 | R16: BENCHMARK (CAM market) — Fabricated section, install + remove | S16: =TRIM(G16)&"|"&TRIM(H16) -> Steel strut and waler incl. fabrication, installation and removal|kg | T16: B
A17: PL-012 | B17: Civil and Structure | C17: B.02 | D17: Sub Structure | E17: Shoring & Sheet Pile | F17: Ground Anchor | G17: Ground anchor incl. drilling, grouting, stressing and testing | H17: Nos | I17: 160 | J17: =_STDLAB -> 0.2 | K17: =IFERROR(I17*(1+J17),0) -> 192 | L17: 300 | M17: =_STDMAT -> 0.12 | N17: =IFERROR(L17*(1+M17),0) -> 336 | O17: =K17+N17 -> 528 | P17: =IF(N(I17)+N(L17)=0,"To be quoted",IF($T17="P","Priced","Benchmark")) -> Benchmark | Q17: 1 | R17: BENCHMARK (CAM market) — Drill, grout, stress, test | S17: =TRIM(G17)&"|"&TRIM(H17) -> Ground anchor incl. drilling, grouting, stressing and testing|Nos | T17: B
... A20: PL-015 | B20: Civil and Structure | C20: B.01 | D20: Sub Structure | E20: Bored Pile | F20: Bored Pile Boring | G20: Bored piling D800mm incl. boring, casing and disposal of spoil | H20: m | I20: 20 | J20: =_STDLAB -> 0.2 | K20: =IFERROR(I20*(1+J20),0) -> 24 | L20: 13 | M20: =_STDMAT -> 0.12 | N20: =IFERROR(L20*(1+M20),0) -> 14.56 | O20: =K20+N20 -> 38.56 | P20: =IF(N(I20)+N(L20)=0,"To be quoted",IF($T20="P","Priced","Benchmark")) -> Benchmark | Q20: 1 | R20: BENCHMARK (CAM market) — Rig, casing, spoil removal D800 | S20: =TRIM(G20)&"|"&TRIM(H20) -> Bored piling D800mm incl. boring, casing and disposal of spoil|m | T20: B
A21: PL-016 | B21: Civil and Structure | C21: B.01 | D21: Sub Structure | E21: Bored Pile | F21: Concrete | G21: Normal Concrete, 35Mpa (Cylinder), Slump 13+-2.5 | H21: m3 | I21: 10 | J21: 0.2 | K21: =IFERROR(I21*(1+J21),0) -> 12 | L21: 98 | M21: 0.12 | N21: =IFERROR(L21*(1+M21),0) -> 109.76 | O21: =K21+N21 -> 121.76 | P21: =IF(N(I21)+N(L21)=0,"To be quoted",IF($T21="P","Priced","Benchmark")) -> Priced | Q21: 17 | R21: Ready-mix C35/30 +pump; CPAC list escalated 2026 | S21: =TRIM(G21)&"|"&TRIM(H21) -> Normal Concrete, 35Mpa (Cylinder), Slump 13+-2.5|m3 | T21: P
A22: PL-017 | B22: Civil and Structure | C22: B.01 | D22: Sub Structure | E22: Bored Pile | F22: Concrete | G22: Normal Concrete, 35Mpa (Cylinder), Slump 15+-2.5 | H22: m3 | I22: 8 | J22: 0.2 | K22: =IFERROR(I22*(1+J22),0) -> 9.6 | L22: 98 | M22: 0.12 | N22: =IFERROR(L22*(1+M22),0) -> 109.76 | O22: =K22+N22 -> 119.36 | P22: =IF(N(I22)+N(L22)=0,"To be quoted",IF($T22="P","Priced","Benchmark")) -> Priced | Q22: 17 | R22: Ready-mix C35/30 +pump; CPAC list escalated 2026 | S22: =TRIM(G22)&"|"&TRIM(H22) -> Normal Concrete, 35Mpa (Cylinder), Slump 15+-2.5|m3 | T22: P
A23: PL-018 | B23: Civil and Structure | C23: B.01 | D23: Sub Structure | E23: Bored Pile | F23: Concrete | G23: Normal Concrete, 25Mpa (Cylinder), Slump 10+-2.5 | H23: m3 | I23: 8 | J23: =_STDLAB -> 0.2 | K23: =IFERROR(I23*(1+J23),0) -> 9.6 | L23: 88 | M23: =_STDMAT -> 0.12 | N23: =IFERROR(L23*(1+M23),0) -> 98.56 | O23: =K23+N23 -> 108.16 | P23: =IF(N(I23)+N(L23)=0,"To be quoted",IF($T23="P","Priced","Benchmark")) -> Benchmark | Q23: 17 | R23: BENCHMARK (CAM market) — Ready-mix C25 PP delivered | S23: =TRIM(G23)&"|"&TRIM(H23) -> Normal Concrete, 25Mpa (Cylinder), Slump 10+-2.5|m3 | T23: B
A24: PL-019 | B24: Civil and Structure | C24: B.01 | D24: Sub Structure | E24: Bored Pile | F24: Concrete | G24: Normal Concrete, 30Mpa (Cylinder), Slump 13+-2.5 | H24: m3 | I24: 9 | J24: =_STDLAB -> 0.2 | K24: =IFERROR(I24*(1+J24),0) -> 10.8 | L24: 93 | M24: =_STDMAT -> 0.12 | N24: =IFERROR(L24*(1+M24),0) -> 104.16 | O24: =K24+N24 -> 114.96 | P24: =IF(N(I24)+N(L24)=0,"To be quoted",IF($T24="P","Priced","Benchmark")) -> Benchmark | Q24: 17 | R24: BENCHMARK (CAM market) — Ready-mix C30 PP delivered | S24: =TRIM(G24)&"|"&TRIM(H24) -> Normal Concrete, 30Mpa (Cylinder), Slump 13+-2.5|m3 | T24: B
A25: PL-020 | B25: Civil and Structure | C25: B.01 | D25: Sub Structure | E25: Bored Pile | F25: Rebar | G25: Deform Bar, DB10(fy=390 Mpa) | H25: kg | I25: 0.12 | J25: 0.2 | K25: =IFERROR(I25*(1+J25),0) -> 0.144 | L25: 0.78 | M25: 0.12 | N25: =IFERROR(L25*(1+M25),0) -> 0.8736 | O25: =K25+N25 -> 1.0176 | P25: =IF(N(I25)+N(L25)=0,"To be quoted",IF($T25="P","Priced","Benchmark")) -> Priced | Q25: 17 | R25: Deformed bar ~$720/t; small dia +labour | S25: =TRIM(G25)&"|"&TRIM(H25) -> Deform Bar, DB10(fy=390 Mpa)|kg | T25: P
A26: PL-021 | B26: Civil and Structure | C26: B.01 | D26: Sub Structure | E26: Bored Pile | F26: Rebar | G26: Deform Bar, DB12(fy=390 Mpa) | H26: kg | I26: 0.11 | J26: 0.2 | K26: =IFERROR(I26*(1+J26),0) -> 0.132 | L26: 0.76 | M26: 0.12 | N26: =IFERROR(L26*(1+M26),0) -> 0.8512 | O26: =K26+N26 -> 0.9832 | P26: =IF(N(I26)+N(L26)=0,"To be quoted",IF($T26="P","Priced","Benchmark")) -> Priced | Q26: 17 | R26: Deformed bar ~$720/t | S26: =TRIM(G26)&"|"&TRIM(H26) -> Deform Bar, DB12(fy=390 Mpa)|kg | T26: P
A27: PL-022 | B27: Civil and Structure | C27: B.01 | D27: Sub Structure | E27: Bored Pile | F27: Rebar | G27: Deform Bar, DB14(fy=390 Mpa) | H27: kg | I27: 0.1 | J27: 0.2 | K27: =IFERROR(I27*(1+J27),0) -> 0.12 | L27: 0.75 | M27: 0.12 | N27: =IFERROR(L27*(1+M27),0) -> 0.84 | O27: =K27+N27 -> 0.96 | P27: =IF(N(I27)+N(L27)=0,"To be quoted",IF($T27="P","Priced","Benchmark")) -> Priced | Q27: 17 | R27: Deformed bar ~$720/t | S27: =TRIM(G27)&"|"&TRIM(H27) -> Deform Bar, DB14(fy=390 Mpa)|kg | T27: P
A28: PL-023 | B28: Civil and Structure | C28: B.01 | D28: Sub Structure | E28: Bored Pile | F28: Rebar | G28: Deform Bar, DB16(fy=390 Mpa) | H28: kg | I28: 0.1 | J28: 0.2 | K28: =IFERROR(I28*(1+J28),0) -> 0.12 | L28: 0.74 | M28: 0.12 | N28: =IFERROR(L28*(1+M28),0) -> 0.8288 | O28: =K28+N28 -> 0.9488 | P28: =IF(N(I28)+N(L28)=0,"To be quoted",IF($T28="P","Priced","Benchmark")) -> Priced | Q28: 17 | R28: Deformed bar ~$720/t | S28: =TRIM(G28)&"|"&TRIM(H28) -> Deform Bar, DB16(fy=390 Mpa)|kg | T28: P
A29: PL-024 | B29: Civil and Structure | C29: B.01 | D29: Sub Structure | E29: Bored Pile | F29: Rebar | G29: Deform Bar, DB20(fy=390 Mpa) | H29: kg | I29: 0.09 | J29: 0.2 | K29: =IFERROR(I29*(1+J29),0) -> 0.108 | L29: 0.73 | M29: 0.12 | N29: =IFERROR(L29*(1+M29),0) -> 0.8176 | O29: =K29+N29 -> 0.9256 | P29: =IF(N(I29)+N(L29)=0,"To be quoted",IF($T29="P","Priced","Benchmark")) -> Priced | Q29: 17 | R29: Deformed bar ~$720/t | S29: =TRIM(G29)&"|"&TRIM(H29) -> Deform Bar, DB20(fy=390 Mpa)|kg | T29: P
A30: PL-025 | B30: Civil and Structure | C30: B.01 | D30: Sub Structure | E30: Bored Pile | F30: Rebar | G30: Deform Bar, DB25(fy=390 Mpa) | H30: kg | I30: 0.08 | J30: 0.2 | K30: =IFERROR(I30*(1+J30),0) -> 0.096 | L30: 0.72 | M30: 0.12 | N30: =IFERROR(L30*(1+M30),0) -> 0.8064 | O30: =K30+N30 -> 0.9024 | P30: =IF(N(I30)+N(L30)=0,"To be quoted",IF($T30="P","Priced","Benchmark")) -> Priced | Q30: 17 | R30: Deformed bar ~$720/t (large dia) | S30: =TRIM(G30)&"|"&TRIM(H30) -> Deform Bar, DB25(fy=390 Mpa)|kg | T30: P
A31: PL-026 | B31: Civil and Structure | C31: B.01 | D31: Sub Structure | E31: Bored Pile | F31: Rebar | G31: Deform Bar, DB32(fy=390 Mpa) | H31: kg | I31: 0.08 | J31: 0.2 | K31: =IFERROR(I31*(1+J31),0) -> 0.096 | L31: 0.71 | M31: 0.12 | N31: =IFERROR(L31*(1+M31),0) -> 0.7952 | O31: =K31+N31 -> 0.8912 | P31: =IF(N(I31)+N(L31)=0,"To be quoted",IF($T31="P","Priced","Benchmark")) -> Priced | Q31: 17 | R31: Deformed bar ~$720/t (large dia) | S31: =TRIM(G31)&"|"&TRIM(H31) -> Deform Bar, DB32(fy=390 Mpa)|kg | T31: P
A32: PL-027 | B32: Civil and Structure | C32: B.01 | D32: Sub Structure | E32: Bored Pile | F32: Rebar | G32: Round Bar, RB8(fy=250 Mpa) | H32: kg | I32: 0.12 | J32: 0.2 | K32: =IFERROR(I32*(1+J32),0) -> 0.144 | L32: 0.77 | M32: 0.12 | N32: =IFERROR(L32*(1+M32),0) -> 0.8624 | O32: =K32+N32 -> 1.0064 | P32: =IF(N(I32)+N(L32)=0,"To be quoted",IF($T32="P","Priced","Benchmark")) -> Priced | Q32: 17 | R32: Round mild bar ~$770/t | S32: =TRIM(G32)&"|"&TRIM(H32) -> Round Bar, RB8(fy=250 Mpa)|kg | T32: P
A33: PL-028 | B33: Civil and Structure | C33: B.01 | D33: Sub Structure | E33: Bored Pile | F33: Rebar | G33: Round Bar, RB6(fy=250 Mpa) | H33: kg | I33: 0.13 | J33: =_STDLAB -> 0.2 | K33: =IFERROR(I33*(1+J33),0) -> 0.156 | L33: 0.78 | M33: =_STDMAT -> 0.12 | N33: =IFERROR(L33*(1+M33),0) -> 0.8736 | O33: =K33+N33 -> 1.0296 | P33: =IF(N(I33)+N(L33)=0,"To be quoted",IF($T33="P","Priced","Benchmark")) -> Benchmark | Q33: 17 | R33: BENCHMARK (CAM market) — Mild round bar ~$780/t | S33: =TRIM(G33)&"|"&TRIM(H33) -> Round Bar, RB6(fy=250 Mpa)|kg | T33: B
A34: PL-029 | B34: Civil and Structure | C34: B.01 | D34: Sub Structure | E34: Bored Pile | F34: Steel Tie Wire | G34: Steel Tie Wire 1mm (Estimated 4% of Total Rebar Weight) | H34: kg | I34: 0.05 | J34: 0.2 | K34: =IFERROR(I34*(1+J34),0) -> 0.06 | L34: 1.2 | M34: 0.12 | N34: =IFERROR(L34*(1+M34),0) -> 1.344 | O34: =K34+N34 -> 1.404 | P34: =IF(N(I34)+N(L34)=0,"To be quoted",IF($T34="P","Priced","Benchmark")) -> Priced | Q34: 17 | R34: Annealed tie wire ~$1.2/kg | S34: =TRIM(G34)&"|"&TRIM(H34) -> Steel Tie Wire 1mm (Estimated 4% of Total Rebar Weight)|kg | T34: P
A35: PL-030 | B35: Civil and Structure | C35: B.01 | D35: Sub Structure | E35: Bored Pile | F35: Bentonite / Slurry | G35: Bentonite / polymer slurry incl. mixing, circulation and disposal | H35: Lot | I35: 2200 | J35: =_STDLAB -> 0.2 | K35: =IFERROR(I35*(1+J35),0) -> 2640 | L35: 4200 | M35: =_STDMAT -> 0.12 | N35: =IFERROR(L35*(1+M35),0) -> 4704 | O35: =K35+N35 -> 7344 | P35: =IF(N(I35)+N(L35)=0,"To be quoted",IF($T35="P","Priced","Benchmark")) -> Benchmark | Q35: 1 | R35: BENCHMARK (CAM market) — Mix, circulate, dispose | S35: =TRIM(G35)&"|"&TRIM(H35) -> Bentonite / polymer slurry incl. mixing, circulation and disposal|Lot | T35: B
A36: PL-031 | B36: Civil and Structure | C36: B.01 | D36: Sub Structure | E36: Bored Pile | F36: Bored Pile Head Cutting | G36: Pile Head Cutting up to required level D1000mm | H36: Nos | I36: 55 | J36: 0.2 | K36: =IFERROR(I36*(1+J36),0) -> 66 | L36: 0 | M36: 0 | N36: =IFERROR(L36*(1+M36),0) -> 0 | O36: =K36+N36 -> 66 | P36: =IF(N(I36)+N(L36)=0,"To be quoted",IF($T36="P","Priced","Benchmark")) -> Priced | Q36: 1 | R36: Pile head breaking D1000 - own labour+breaker, est. | S36: =TRIM(G36)&"|"&TRIM(H36) -> Pile Head Cutting up to required level D1000mm|Nos | T36: P
A37: PL-032 | B37: Civil and Structure | C37: B.01 | D37: Sub Structure | E37: Bored Pile | F37: Bored Pile Head Cutting | G37: Pile Head Cutting up to required level D800mm | H37: Nos | I37: 40 | J37: 0.2 | K37: =IFERROR(I37*(1+J37),0) -> 48 | L37: 0 | M37: 0 | N37: =IFERROR(L37*(1+M37),0) -> 0 | O37: =K37+N37 -> 48 | P37: =IF(N(I37)+N(L37)=0,"To be quoted",IF($T37="P","Priced","Benchmark")) -> Priced | Q37: 1 | R37: Pile head breaking D800 - own labour+breaker, est. | S37: =TRIM(G37)&"|"&TRIM(H37) -> Pile Head Cutting up to required level D800mm|Nos | T37: P
A38: PL-033 | B38: Civil and Structure | C38: B.01 | D38: Sub Structure | E38: Bored Pile | F38: Bored Pile Testing | G38: Sonic Logging Test (SLT) | H38: Nos | I38: 0 | J38: 0 | K38: =IFERROR(I38*(1+J38),0) -> 0 | L38: 50 | M38: 0.1 | N38: =IFERROR(L38*(1+M38),0) -> 55 | O38: =K38+N38 -> 55 | P38: =IF(N(I38)+N(L38)=0,"To be quoted",IF($T38="P","Priced","Benchmark")) -> Priced | Q38: 1 | R38: SLT specialist subcontract per pile, provisional | S38: =TRIM(G38)&"|"&TRIM(H38) -> Sonic Logging Test (SLT)|Nos | T38: P
A39: PL-034 | B39: Civil and Structure | C39: B.01 | D39: Sub Structure | E39: Bored Pile | F39: Bored Pile Testing | G39: Pile Integrity Test (PIT) | H39: Nos | I39: 0 | J39: 0 | K39: =IFERROR(I39*(1+J39),0) -> 0 | L39: 45 | M39: 0.1 | N39: =IFERROR(L39*(1+M39),0) -> 49.5 | O39: =K39+N39 -> 49.5 | P39: =IF(N(I39)+N(L39)=0,"To be quoted",IF($T39="P","Priced","Benchmark")) -> Benchmark | Q39: 1 | R39: SUBCONTRACT benchmark — PIT specialist subcontract | S39: =TRIM(G39)&"|"&TRIM(H39) -> Pile Integrity Test (PIT)|Nos | T39: B
A40: PL-035 | B40: Civil and Structure | C40: B.01 | D40: Sub Structure | E40: Bored Pile | F40: Bored Pile Coring | G40: Soil Coring for Bored Pile D1000mm, Depth 30m | H40: Nos | I40: 0 | J40: 0 | K40: =IFERROR(I40*(1+J40),0) -> 0 | L40: 350 | M40: 0.1 | N40: =IFERROR(L40*(1+M40),0) -> 385 | O40: =K40+N40 -> 385 | P40: =IF(N(I40)+N(L40)=0,"To be quoted",IF($T40="P","Priced","Benchmark")) -> Priced | Q40: 1 | R40: Coring D1000 30m subcontract, provisional | S40: =TRIM(G40)&"|"&TRIM(H40) -> Soil Coring for Bored Pile D1000mm, Depth 30m|Nos | T40: P
A41: PL-036 | B41: Civil and Structure | C41: B.01 | D41: Sub Structure | E41: Bored Pile | F41: Bored Pile Coring | G41: Soil Coring for Bored Pile D800mm, Depth 30m | H41: Nos | I41: 0 | J41: 0 | K41: =IFERROR(I41*(1+J41),0) -> 0 | L41: 300 | M41: 0.1 | N41: =IFERROR(L41*(1+M41),0) -> 330 | O41: =K41+N41 -> 330 | P41: =IF(N(I41)+N(L41)=0,"To be quoted",IF($T41="P","Priced","Benchmark")) -> Priced | Q41: 1 | R41: Coring D800 30m subcontract, provisional | S41: =TRIM(G41)&"|"&TRIM(H41) -> Soil Coring for Bored Pile D800mm, Depth 30m|Nos | T41: P
A42: PL-037 | B42: Civil and Structure | C42: B.01 | D42: Sub Structure | E42: Bored Pile | F42: Pile Load Test | G42: Dynamic pile load test (PDA) | H42: Nos | I42: 0 | J42: 0 | K42: =IFERROR(I42*(1+J42),0) -> 0 | L42: 2400 | M42: 0.1 | N42: =IFERROR(L42*(1+M42),0) -> 2640 | O42: =K42+N42 -> 2640 | P42: =IF(N(I42)+N(L42)=0,"To be quoted",IF($T42="P","Priced","Benchmark")) -> Benchmark | Q42: 2 | R42: SUBCONTRACT benchmark — PDA specialist subcontract | S42: =TRIM(G42)&"|"&TRIM(H42) -> Dynamic pile load test (PDA)|Nos | T42: B
...

Sheet Preliminaries Library
A1: PRELIMINARIES LIBRARY (Z) — TIME-RELATED, FIXED & QUANTITY-RELATED COST
A2: PROGRAMME DURATION (months) | C2: 18 | E2: Change the duration once — every Time-related item re-calculates. This single cell is the biggest driver of preliminaries cost.
A3: STANDARD PRELIM MARGIN | C3: 0 | E3: Margin normally 0% here: preliminaries are carried at cost and overhead / profit is added on the Tender Cover.
A5: Item Code | B5: Budget Code | C5: Section | D5: Sub Section | E5: Sub Element | F5: Description | G5: Unit | H5: Cost Type | I5: Include (Y/N) | J5: Qty | K5: Net Cost ($) | L5: Margin (%) | M5: Rate ($) | N5: Amount ($) | O5: Basis / Source
A6: PR-001 | B6: Z.01.01 | C6: Contractor's Preliminaries / Design / Other | D6: Temporary Works | E6: Site Preparation | F6: Site clearing and grubbing before mobilization | G6: Item | H6: Fixed lump sum | I6: Y | J6: 1 | K6: 3000 | L6: =_STDPRE -> 0 | M6: =IFERROR(K6*(1+L6),0) -> 3000 | N6: =IF($I6="Y",N(J6)*N(M6),0) -> 3000 | O6: Clear site prior to setting up
A7: PR-002 | B7: Z.01.01 | C7: Contractor's Preliminaries / Design / Other | D7: Temporary Works | E7: Site Preparation | F7: Temporary access road and hardstanding | G7: Item | H7: Fixed lump sum | I7: Y | J7: 1 | K7: 7000 | L7: =_STDPRE -> 0 | M7: =IFERROR(K7*(1+L7),0) -> 7000 | N7: =IF($I7="Y",N(J7)*N(M7),0) -> 7000 | O7: Project rate Z.17
A8: PR-003 | B8: Z.01.01 | C8: Contractor's Preliminaries / Design / Other | D8: Temporary Works | E8: Site Preparation | F8: Temporary laydown / stacking area formation | G8: Item | H8: Fixed lump sum | I8: Y | J8: 1 | K8: 3500 | L8: =_STDPRE -> 0 | M8: =IFERROR(K8*(1+L8),0) -> 3500 | N8: =IF($I8="Y",N(J8)*N(M8),0) -> 3500 | O8: Crushed stone laydown area
A9: PR-004 | B9: Z.01.01 | C9: Contractor's Preliminaries / Design / Other | D9: Temporary Works | E9: Site Preparation | F9: Temporary drainage and site dewatering | G9: Month | H9: Time-related | I9: Y | J9: =_MONTHS -> 18 | K9: 250 | L9: =_STDPRE -> 0 | M9: =IFERROR(K9*(1+L9),0) -> 250 | N9: =IF($I9="Y",N(J9)*N(M9),0) -> 4500 | O9: Pump, sump and discharge
A10: PR-005 | B10: Z.01.01 | C10: Contractor's Preliminaries / Design / Other | D10: Temporary Works | E10: Site Preparation | F10: Washing bay / wheel wash for trucks | G10: Item | H10: Fixed lump sum | I10: Y | J10: 1 | K10: 10000 | L10: =_STDPRE -> 0 | M10: =IFERROR(K10*(1+L10),0) -> 10000 | N10: =IF($I10="Y",N(J10)*N(M10),0) -> 10000 | O10: Project rate Z.21
A11: PR-006 | B11: Z.01.01 | C11: Contractor's Preliminaries / Design / Other | D11: Temporary Works | E11: Site Preparation | F11: Temporary sheet pile to site boundary, 6m depth | G11: m | H11: Quantity-related | I11: N | K11: 180 | L11: =_STDPRE -> 0 | M11: =IFERROR(K11*(1+L11),0) -> 180 | N11: =IF($I11="Y",N(J11)*N(M11),0) -> 0 | O11: Project rate Z.22 — only if required
A12: PR-007 | B12: Z.01.01 | C12: Contractor's Preliminaries / Design / Other | D12: Temporary Works | E12: Site Preparation | F12: Setting out, survey and benchmark establishment | G12: Month | H12: Time-related | I12: Y | J12: =_MONTHS -> 18 | K12: 400 | L12: =_STDPRE -> 0 | M12: =IFERROR(K12*(1+L12),0) -> 400 | N12: =IF($I12="Y",N(J12)*N(M12),0) -> 7200 | O12: Project rate Z.09
F13: Subtotal — Z.01.01 Site Preparation | N13: =SUM(N6:N12) -> 35200
A14: PR-008 | B14: Z.01.02 | C14: Contractor's Preliminaries / Design / Other | D14: Temporary Works | E14: General Protection | F14: Temporary fencing and hoarding to site boundary | G14: Item | H14: Fixed lump sum | I14: Y | J14: 1 | K14: 8000 | L14: =_STDPRE -> 0 | M14: =IFERROR(K14*(1+L14),0) -> 8000 | N14: =IF($I14="Y",N(J14)*N(M14),0) -> 8000 | O14: Project rate Z.03
A15: PR-009 | B15: Z.01.02 | C15: Contractor's Preliminaries / Design / Other | D15: Temporary Works | E15: General Protection | F15: Temporary site gate with lock | G15: Nos | H15: Quantity-related | I15: Y | K15: 800 | L15: =_STDPRE -> 0 | M15: =IFERROR(K15*(1+L15),0) -> 800 | N15: =IF($I15="Y",N(J15)*N(M15),0) -> 0 | O15: Main and secondary gate
A16: PR-010 | B16: Z.01.02 | C16: Contractor's Preliminaries / Design / Other | D16: Temporary Works | E16: General Protection | F16: Safety net to building perimeter | G16: Item | H16: Fixed lump sum | I16: Y | J16: 1 | K16: 6000 | L16: =_STDPRE -> 0 | M16: =IFERROR(K16*(1+L16),0) -> 6000 | N16: =IF($I16="Y",N(J16)*N(M16),0) -> 6000 | O16: Project rate Z.20
A17: PR-011 | B17: Z.01.02 | C17: Contractor's Preliminaries / Design / Other | D17: Temporary Works | E17: General Protection | F17: Edge protection and guard rail to slab edge | G17: m | H17: Quantity-related | I17: Y | K17: 12 | L17: =_STDPRE -> 0 | M17: =IFERROR(K17*(1+L17),0) -> 12 | N17: =IF($I17="Y",N(J17)*N(M17),0) -> 0 | O17: Per metre of exposed edge
A18: PR-012 | B18: Z.01.02 | C18: Contractor's Preliminaries / Design / Other | D18: Temporary Works | E18: General Protection | F18: Debris netting and catch fan | G18: Item | H18: Fixed lump sum | I18: Y | J18: 1 | K18: 4500 | L18: =_STDPRE -> 0 | M18: =IFERROR(K18*(1+L18),0) -> 4500 | N18: =IF($I18="Y",N(J18)*N(M18),0) -> 4500 | O18: High-rise debris control
A19: PR-013 | B19: Z.01.02 | C19: Contractor's Preliminaries / Design / Other | D19: Temporary Works | E19: General Protection | F19: Temporary protection to completed finishes | G19: Item | H19: Fixed lump sum | I19: Y | J19: 1 | K19: 3000 | L19: =_STDPRE -> 0 | M19: =IFERROR(K19*(1+L19),0) -> 3000 | N19: =IF($I19="Y",N(J19)*N(M19),0) -> 3000 | O19: Corner guard, floor covering
A20: PR-014 | B20: Z.01.02 | C20: Contractor's Preliminaries / Design / Other | D20: Temporary Works | E20: General Protection | F20: Weather protection and tarpaulin | G20: Item | H20: Fixed lump sum | I20: Y | J20: 1 | K20: 2000 | L20: =_STDPRE -> 0 | M20: =IFERROR(K20*(1+L20),0) -> 2000 | N20: =IF($I20="Y",N(J20)*N(M20),0) -> 2000 | O20: Rainy season protection
F21: Subtotal — Z.01.02 General Protection | N21: =SUM(N14:N20) -> 23500
A22: PR-015 | B22: Z.01.03 | C22: Contractor's Preliminaries / Design / Other | D22: Temporary Works | E22: Temporary Building | F22: Site office - main contractor | G22: Month | H22: Time-related | I22: Y | J22: =_MONTHS -> 18 | K22: 900 | L22: =_STDPRE -> 0 | M22: =IFERROR(K22*(1+L22),0) -> 900 | N22: =IF($I22="Y",N(J22)*N(M22),0) -> 16200 | O22: Container office hire, part of project Z.01
A23: PR-016 | B23: Z.01.03 | C23: Contractor's Preliminaries / Design / Other | D23: Temporary Works | E23: Temporary Building | F23: Site office - consultant / client | G23: Month | H23: Time-related | I23: Y | J23: =_MONTHS -> 18 | K23: 450 | L23: =_STDPRE -> 0 | M23: =IFERROR(K23*(1+L23),0) -> 450 | N23: =IF($I23="Y",N(J23)*N(M23),0) -> 8100 | O23: Client facility if required by contract
A24: PR-017 | B24: Z.01.03 | C24: Contractor's Preliminaries / Design / Other | D24: Temporary Works | E24: Temporary Building | F24: Meeting room | G24: Month | H24: Time-related | I24: Y | J24: =_MONTHS -> 18 | K24: 200 | L24: =_STDPRE -> 0 | M24: =IFERROR(K24*(1+L24),0) -> 200 | N24: =IF($I24="Y",N(J24)*N(M24),0) -> 3600 | O24: Shared meeting facility
A25: PR-018 | B25: Z.01.03 | C25: Contractor's Preliminaries / Design / Other | D25: Temporary Works | E25: Temporary Building | F25: Material store and workshop | G25: Month | H25: Time-related | I25: Y | J25: =_MONTHS -> 18 | K25: 350 | L25: =_STDPRE -> 0 | M25: =IFERROR(K25*(1+L25),0) -> 350 | N25: =IF($I25="Y",N(J25)*N(M25),0) -> 6300 | O25: Secure store
A26: PR-019 | B26: Z.01.03 | C26: Contractor's Preliminaries / Design / Other | D26: Temporary Works | E26: Temporary Building | F26: Worker rest area and canteen | G26: Month | H26: Time-related | I26: Y | J26: =_MONTHS -> 18 | K26: 250 | L26: =_STDPRE -> 0 | M26: =IFERROR(K26*(1+L26),0) -> 250 | N26: =IF($I26="Y",N(J26)*N(M26),0) -> 4500 | O26: Welfare facility
A27: PR-020 | B27: Z.01.03 | C27: Contractor's Preliminaries / Design / Other | D27: Temporary Works | E27: Temporary Building | F27: Site toilet and washing facility | G27: Month | H27: Time-related | I27: Y | J27: =_MONTHS -> 18 | K27: 200 | L27: =_STDPRE -> 0 | M27: =IFERROR(K27*(1+L27),0) -> 200 | N27: =IF($I27="Y",N(J27)*N(M27),0) -> 3600 | O27: Portable toilet hire and servicing
A28: PR-021 | B28: Z.01.03 | C28: Contractor's Preliminaries / Design / Other | D28: Temporary Works | E28: Temporary Building | F28: First aid room | G28: Month | H28: Time-related | I28: Y | J28: =_MONTHS -> 18 | K28: 100 | L28: =_STDPRE -> 0 | M28: =IFERROR(K28*(1+L28),0) -> 100 | N28: =IF($I28="Y",N(J28)*N(M28),0) -> 1800 | O28: Statutory welfare
A29: PR-022 | B29: Z.01.03 | C29: Contractor's Preliminaries / Design / Other | D29: Temporary Works | E29: Temporary Building | F29: Guard house | G29: Item | H29: Fixed lump sum | I29: Y | J29: 1 | K29: 1500 | L29: =_STDPRE -> 0 | M29: =IFERROR(K29*(1+L29),0) -> 1500 | N29: =IF($I29="Y",N(J29)*N(M29),0) -> 1500 | O29: Prefabricated guard post
A30: PR-023 | B30: Z.01.03 | C30: Contractor's Preliminaries / Design / Other | D30: Temporary Works | E30: Temporary Building | F30: Office furniture, equipment and IT | G30: Item | H30: Fixed lump sum | I30: Y | J30: 1 | K30: 4000 | L30: =_STDPRE -> 0 | M30: =IFERROR(K30*(1+L30),0) -> 4000 | N30: =IF($I30="Y",N(J30)*N(M30),0) -> 4000 | O30: Desk, chair, printer, computer
A31: PR-024 | B31: Z.01.03 | C31: Contractor's Preliminaries / Design / Other | D31: Temporary Works | E31: Temporary Building | F31: Project signboard and site branding | G31: Item | H31: Fixed lump sum | I31: Y | J31: 1 | K31: 1500 | L31: =_STDPRE -> 0 | M31: =IFERROR(K31*(1+L31),0) -> 1500 | N31: =IF($I31="Y",N(J31)*N(M31),0) -> 1500 | O31: Authority and client requirement
F32: Subtotal — Z.01.03 Temporary Building | N32: =SUM(N22:N31) -> 51100
A33: PR-025 | B33: Z.01.04 | C33: Contractor's Preliminaries / Design / Other | D33: Temporary Works | E33: Temporary site labor | F33: General site labour / helper gang | G33: Month | H33: Time-related | I33: Y | J33: =_MONTHS -> 18 | K33: 1200 | L33: =_STDPRE -> 0 | M33: =IFERROR(K33*(1+L33),0) -> 1200 | N33: =IF($I33="Y",N(J33)*N(M33),0) -> 21600 | O33: Attendance labour gang
A34: PR-026 | B34: Z.01.04 | C34: Contractor's Preliminaries / Design / Other | D34: Temporary Works | E34: Temporary site labor | F34: Progressive site cleaning labour | G34: Month | H34: Time-related | I34: Y | J34: =_MONTHS -> 18 | K34: 450 | L34: =_STDPRE -> 0 | M34: =IFERROR(K34*(1+L34),0) -> 450 | N34: =IF($I34="Y",N(J34)*N(M34),0) -> 8100 | O34: Part of project Z.08
A35: PR-027 | B35: Z.01.04 | C35: Contractor's Preliminaries / Design / Other | D35: Temporary Works | E35: Temporary site labor | F35: Waste collection, skip hire and disposal | G35: Month | H35: Time-related | I35: Y | J35: =_MONTHS -> 18 | K35: 150 | L35: =_STDPRE -> 0 | M35: =IFERROR(K35*(1+L35),0) -> 150 | N35: =IF($I35="Y",N(J35)*N(M35),0) -> 2700 | O35: Tipping and cart away
A36: PR-028 | B36: Z.01.04 | C36: Contractor's Preliminaries / Design / Other | D36: Temporary Works | E36: Temporary site labor | F36: Final cleaning before handover | G36: Item | H36: Fixed lump sum | I36: Y | J36: 1 | K36: 4500 | L36: =_STDPRE -> 0 | M36: =IFERROR(K36*(1+L36),0) -> 4500 | N36: =IF($I36="Y",N(J36)*N(M36),0) -> 4500 | O36: Builders clean at completion
A37: PR-029 | B37: Z.01.04 | C37: Contractor's Preliminaries / Design / Other | D37: Temporary Works | E37: Temporary site labor | F37: Traffic marshal / banksman | G37: Month | H37: Time-related | I37: Y | J37: =_MONTHS -> 18 | K37: 350 | L37: =_STDPRE -> 0 | M37: =IFERROR(K37*(1+L37),0) -> 350 | N37: =IF($I37="Y",N(J37)*N(M37),0) -> 6300 | O37: Vehicle and crane movement control
A38: PR-030 | B38: Z.01.04 | C38: Contractor's Preliminaries / Design / Other | D38: Temporary Works | E38: Temporary site labor | F38: Rigger and signalman for lifting | G38: Month | H38: Time-related | I38: Y | J38: =_MONTHS -> 18 | K38: 400 | L38: =_STDPRE -> 0 | M38: =IFERROR(K38*(1+L38),0) -> 400 | N38: =IF($I38="Y",N(J38)*N(M38),0) -> 7200 | O38: Crane lifting support
F39: Subtotal — Z.01.04 Temporary site labor | N39: =SUM(N33:N38) -> 50400
A40: PR-031 | B40: Z.01.05 | C40: Contractor's Preliminaries / Design / Other | D40: Temporary Works | E40: Machinery | F40: Tower crane - erection, foundation and dismantling | G40: Item | H40: Fixed lump sum | I40: Y | J40: 1 | K40: 18000 | L40: =_STDPRE -> 0 | M40: =IFERROR(K40*(1+L40),0) -> 18000 | N40: =IF($I40="Y",N(J40)*N(M40),0) -> 18000 | O40: One-off; separate from monthly hire
A41: PR-032 | B41: Z.01.05 | C41: Contractor's Preliminaries / Design / Other | D41: Temporary Works | E41: Machinery | F41: Tower crane - monthly hire | G41: Month | H41: Time-related | I41: Y | J41: =_MONTHS -> 18 | K41: 3200 | L41: =_STDPRE -> 0 | M41: =IFERROR(K41*(1+L41),0) -> 3200 | N41: =IF($I41="Y",N(J41)*N(M41),0) -> 57600 | O41: Part of project Z.19
...

Sheet Entry Template
A1: BoQ TAKE-OFF ENTRY TEMPLATE
A2: Pick in order: Building → Level → Section → Sub Section → Sub Element → Description. Code, Unit and all rates fill in automatically from the Price List Library.
A3: Yellow = your input. If a drop-down looks empty, the cell to its left is still blank.
N4: TOTAL → | O4: =SUM(O6:O305) -> 0
A5: No. | B5: Building | C5: Level | D5: Discipline | E5: Section | F5: Sub Section | G5: Sub Element | H5: Description (Material Type) | I5: Budget Code | J5: Unit | K5: Quantity | L5: Labor Rate ($) | M5: Material Rate ($) | N5: Total Rate ($) | O5: Amount ($) | P5: Status | Q5: Remark | R5: h1 | S5: h2 | T5: h3
A6: =IF($E6="","",ROW()-5) | I6: =IFERROR(INDEX('Description Library'!$C$6:$C$808,MATCH($E6&"|"&$F6&"|"&$G6&"|"&$H6,'Description Library'!$K$6:$K$808,0)),"") | J6: =IFERROR(INDEX('Description Library'!$H$6:$H$808,MATCH($E6&"|"&$F6&"|"&$G6&"|"&$H6,'Description Library'!$K$6:$K$808,0)),"") | L6: =IFERROR(INDEX('Price List Library'!$K$6:$K$437,MATCH(TRIM($H6)&"|"&TRIM($J6),'Price List Library'!$S$6:$S$437,0)),0) -> 0 | M6: =IFERROR(INDEX('Price List Library'!$N$6:$N$437,MATCH(TRIM($H6)&"|"&TRIM($J6),'Price List Library'!$S$6:$S$437,0)),0) -> 0 | N6: =L6+M6 -> 0 | O6: =IF($K6="","",$K6*$N6) | P6: =IFERROR(INDEX('Price List Library'!$P$6:$P$437,MATCH(TRIM($H6)&"|"&TRIM($J6),'Price List Library'!$S$6:$S$437,0)),"") | R6: =IFERROR(VLOOKUP($E6,_MAPSEC,2,0),"_NONE") -> _NONE | S6: =IFERROR(VLOOKUP($E6&"|"&$F6,_MAPSUB,2,0),"_NONE") -> _NONE | T6: =IFERROR(VLOOKUP($E6&"|"&$F6&"|"&$G6,_MAPSE,2,0),"_NONE") -> _NONE
A7: =IF($E7="","",ROW()-5) | I7: =IFERROR(INDEX('Description Library'!$C$6:$C$808,MATCH($E7&"|"&$F7&"|"&$G7&"|"&$H7,'Description Library'!$K$6:$K$808,0)),"") | J7: =IFERROR(INDEX('Description Library'!$H$6:$H$808,MATCH($E7&"|"&$F7&"|"&$G7&"|"&$H7,'Description Library'!$K$6:$K$808,0)),"") | L7: =IFERROR(INDEX('Price List Library'!$K$6:$K$437,MATCH(TRIM($H7)&"|"&TRIM($J7),'Price List Library'!$S$6:$S$437,0)),0) -> 0 | M7: =IFERROR(INDEX('Price List Library'!$N$6:$N$437,MATCH(TRIM($H7)&"|"&TRIM($J7),'Price List Library'!$S$6:$S$437,0)),0) -> 0 | N7: =L7+M7 -> 0 | O7: =IF($K7="","",$K7*$N7) | P7: =IFERROR(INDEX('Price List Library'!$P$6:$P$437,MATCH(TRIM($H7)&"|"&TRIM($J7),'Price List Library'!$S$6:$S$437,0)),"") | R7: =IFERROR(VLOOKUP($E7,_MAPSEC,2,0),"_NONE") -> _NONE | S7: =IFERROR(VLOOKUP($E7&"|"&$F7,_MAPSUB,2,0),"_NONE") -> _NONE | T7: =IFERROR(VLOOKUP($E7&"|"&$F7&"|"&$G7,_MAPSE,2,0),"_NONE") -> _NONE
A8: =IF($E8="","",ROW()-5) | I8: =IFERROR(INDEX('Description Library'!$C$6:$C$808,MATCH($E8&"|"&$F8&"|"&$G8&"|"&$H8,'Description Library'!$K$6:$K$808,0)),"") | J8: =IFERROR(INDEX('Description Library'!$H$6:$H$808,MATCH($E8&"|"&$F8&"|"&$G8&"|"&$H8,'Description Library'!$K$6:$K$808,0)),"") | L8: =IFERROR(INDEX('Price List Library'!$K$6:$K$437,MATCH(TRIM($H8)&"|"&TRIM($J8),'Price List Library'!$S$6:$S$437,0)),0) -> 0 | M8: =IFERROR(INDEX('Price List Library'!$N$6:$N$437,MATCH(TRIM($H8)&"|"&TRIM($J8),'Price List Library'!$S$6:$S$437,0)),0) -> 0 | N8: =L8+M8 -> 0 | O8: =IF($K8="","",$K8*$N8) | P8: =IFERROR(INDEX('Price List Library'!$P$6:$P$437,MATCH(TRIM($H8)&"|"&TRIM($J8),'Price List Library'!$S$6:$S$437,0)),"") | R8: =IFERROR(VLOOKUP($E8,_MAPSEC,2,0),"_NONE") -> _NONE | S8: =IFERROR(VLOOKUP($E8&"|"&$F8,_MAPSUB,2,0),"_NONE") -> _NONE | T8: =IFERROR(VLOOKUP($E8&"|"&$F8&"|"&$G8,_MAPSE,2,0),"_NONE") -> _NONE
A9: =IF($E9="","",ROW()-5) | I9: =IFERROR(INDEX('Description Library'!$C$6:$C$808,MATCH($E9&"|"&$F9&"|"&$G9&"|"&$H9,'Description Library'!$K$6:$K$808,0)),"") | J9: =IFERROR(INDEX('Description Library'!$H$6:$H$808,MATCH($E9&"|"&$F9&"|"&$G9&"|"&$H9,'Description Library'!$K$6:$K$808,0)),"") | L9: =IFERROR(INDEX('Price List Library'!$K$6:$K$437,MATCH(TRIM($H9)&"|"&TRIM($J9),'Price List Library'!$S$6:$S$437,0)),0) -> 0 | M9: =IFERROR(INDEX('Price List Library'!$N$6:$N$437,MATCH(TRIM($H9)&"|"&TRIM($J9),'Price List Library'!$S$6:$S$437,0)),0) -> 0 | N9: =L9+M9 -> 0 | O9: =IF($K9="","",$K9*$N9) | P9: =IFERROR(INDEX('Price List Library'!$P$6:$P$437,MATCH(TRIM($H9)&"|"&TRIM($J9),'Price List Library'!$S$6:$S$437,0)),"") | R9: =IFERROR(VLOOKUP($E9,_MAPSEC,2,0),"_NONE") -> _NONE | S9: =IFERROR(VLOOKUP($E9&"|"&$F9,_MAPSUB,2,0),"_NONE") -> _NONE | T9: =IFERROR(VLOOKUP($E9&"|"&$F9&"|"&$G9,_MAPSE,2,0),"_NONE") -> _NONE
A10: =IF($E10="","",ROW()-5) | I10: =IFERROR(INDEX('Description Library'!$C$6:$C$808,MATCH($E10&"|"&$F10&"|"&$G10&"|"&$H10,'Description Library'!$K$6:$K$808,0)),"") | J10: =IFERROR(INDEX('Description Library'!$H$6:$H$808,MATCH($E10&"|"&$F10&"|"&$G10&"|"&$H10,'Description Library'!$K$6:$K$808,0)),"") | L10: =IFERROR(INDEX('Price List Library'!$K$6:$K$437,MATCH(TRIM($H10)&"|"&TRIM($J10),'Price List Library'!$S$6:$S$437,0)),0) -> 0 | M10: =IFERROR(INDEX('Price List Library'!$N$6:$N$437,MATCH(TRIM($H10)&"|"&TRIM($J10),'Price List Library'!$S$6:$S$437,0)),0) -> 0 | N10: =L10+M10 -> 0 | O10: =IF($K10="","",$K10*$N10) | P10: =IFERROR(INDEX('Price List Library'!$P$6:$P$437,MATCH(TRIM($H10)&"|"&TRIM($J10),'Price List Library'!$S$6:$S$437,0)),"") | R10: =IFERROR(VLOOKUP($E10,_MAPSEC,2,0),"_NONE") -> _NONE | S10: =IFERROR(VLOOKUP($E10&"|"&$F10,_MAPSUB,2,0),"_NONE") -> _NONE | T10: =IFERROR(VLOOKUP($E10&"|"&$F10&"|"&$G10,_MAPSE,2,0),"_NONE") -> _NONE
A11: =IF($E11="","",ROW()-5) | I11: =IFERROR(INDEX('Description Library'!$C$6:$C$808,MATCH($E11&"|"&$F11&"|"&$G11&"|"&$H11,'Description Library'!$K$6:$K$808,0)),"") | J11: =IFERROR(INDEX('Description Library'!$H$6:$H$808,MATCH($E11&"|"&$F11&"|"&$G11&"|"&$H11,'Description Library'!$K$6:$K$808,0)),"") | L11: =IFERROR(INDEX('Price List Library'!$K$6:$K$437,MATCH(TRIM($H11)&"|"&TRIM($J11),'Price List Library'!$S$6:$S$437,0)),0) -> 0 | M11: =IFERROR(INDEX('Price List Library'!$N$6:$N$437,MATCH(TRIM($H11)&"|"&TRIM($J11),'Price List Library'!$S$6:$S$437,0)),0) -> 0 | N11: =L11+M11 -> 0 | O11: =IF($K11="","",$K11*$N11) | P11: =IFERROR(INDEX('Price List Library'!$P$6:$P$437,MATCH(TRIM($H11)&"|"&TRIM($J11),'Price List Library'!$S$6:$S$437,0)),"") | R11: =IFERROR(VLOOKUP($E11,_MAPSEC,2,0),"_NONE") -> _NONE | S11: =IFERROR(VLOOKUP($E11&"|"&$F11,_MAPSUB,2,0),"_NONE") -> _NONE | T11: =IFERROR(VLOOKUP($E11&"|"&$F11&"|"&$G11,_MAPSE,2,0),"_NONE") -> _NONE
A12: =IF($E12="","",ROW()-5) | I12: =IFERROR(INDEX('Description Library'!$C$6:$C$808,MATCH($E12&"|"&$F12&"|"&$G12&"|"&$H12,'Description Library'!$K$6:$K$808,0)),"") | J12: =IFERROR(INDEX('Description Library'!$H$6:$H$808,MATCH($E12&"|"&$F12&"|"&$G12&"|"&$H12,'Description Library'!$K$6:$K$808,0)),"") | L12: =IFERROR(INDEX('Price List Library'!$K$6:$K$437,MATCH(TRIM($H12)&"|"&TRIM($J12),'Price List Library'!$S$6:$S$437,0)),0) -> 0 | M12: =IFERROR(INDEX('Price List Library'!$N$6:$N$437,MATCH(TRIM($H12)&"|"&TRIM($J12),'Price List Library'!$S$6:$S$437,0)),0) -> 0 | N12: =L12+M12 -> 0 | O12: =IF($K12="","",$K12*$N12) | P12: =IFERROR(INDEX('Price List Library'!$P$6:$P$437,MATCH(TRIM($H12)&"|"&TRIM($J12),'Price List Library'!$S$6:$S$437,0)),"") | R12: =IFERROR(VLOOKUP($E12,_MAPSEC,2,0),"_NONE") -> _NONE | S12: =IFERROR(VLOOKUP($E12&"|"&$F12,_MAPSUB,2,0),"_NONE") -> _NONE | T12: =IFERROR(VLOOKUP($E12&"|"&$F12&"|"&$G12,_MAPSE,2,0),"_NONE") -> _NONE
A13: =IF($E13="","",ROW()-5) | I13: =IFERROR(INDEX('Description Library'!$C$6:$C$808,MATCH($E13&"|"&$F13&"|"&$G13&"|"&$H13,'Description Library'!$K$6:$K$808,0)),"") | J13: =IFERROR(INDEX('Description Library'!$H$6:$H$808,MATCH($E13&"|"&$F13&"|"&$G13&"|"&$H13,'Description Library'!$K$6:$K$808,0)),"") | L13: =IFERROR(INDEX('Price List Library'!$K$6:$K$437,MATCH(TRIM($H13)&"|"&TRIM($J13),'Price List Library'!$S$6:$S$437,0)),0) -> 0 | M13: =IFERROR(INDEX('Price List Library'!$N$6:$N$437,MATCH(TRIM($H13)&"|"&TRIM($J13),'Price List Library'!$S$6:$S$437,0)),0) -> 0 | N13: =L13+M13 -> 0 | O13: =IF($K13="","",$K13*$N13) | P13: =IFERROR(INDEX('Price List Library'!$P$6:$P$437,MATCH(TRIM($H13)&"|"&TRIM($J13),'Price List Library'!$S$6:$S$437,0)),"") | R13: =IFERROR(VLOOKUP($E13,_MAPSEC,2,0),"_NONE") -> _NONE | S13: =IFERROR(VLOOKUP($E13&"|"&$F13,_MAPSUB,2,0),"_NONE") -> _NONE | T13: =IFERROR(VLOOKUP($E13&"|"&$F13&"|"&$G13,_MAPSE,2,0),"_NONE") -> _NONE
A14: =IF($E14="","",ROW()-5) | I14: =IFERROR(INDEX('Description Library'!$C$6:$C$808,MATCH($E14&"|"&$F14&"|"&$G14&"|"&$H14,'Description Library'!$K$6:$K$808,0)),"") | J14: =IFERROR(INDEX('Description Library'!$H$6:$H$808,MATCH($E14&"|"&$F14&"|"&$G14&"|"&$H14,'Description Library'!$K$6:$K$808,0)),"") | L14: =IFERROR(INDEX('Price List Library'!$K$6:$K$437,MATCH(TRIM($H14)&"|"&TRIM($J14),'Price List Library'!$S$6:$S$437,0)),0) -> 0 | M14: =IFERROR(INDEX('Price List Library'!$N$6:$N$437,MATCH(TRIM($H14)&"|"&TRIM($J14),'Price List Library'!$S$6:$S$437,0)),0) -> 0 | N14: =L14+M14 -> 0 | O14: =IF($K14="","",$K14*$N14) | P14: =IFERROR(INDEX('Price List Library'!$P$6:$P$437,MATCH(TRIM($H14)&"|"&TRIM($J14),'Price List Library'!$S$6:$S$437,0)),"") | R14: =IFERROR(VLOOKUP($E14,_MAPSEC,2,0),"_NONE") -> _NONE | S14: =IFERROR(VLOOKUP($E14&"|"&$F14,_MAPSUB,2,0),"_NONE") -> _NONE | T14: =IFERROR(VLOOKUP($E14&"|"&$F14&"|"&$G14,_MAPSE,2,0),"_NONE") -> _NONE
A15: =IF($E15="","",ROW()-5) | I15: =IFERROR(INDEX('Description Library'!$C$6:$C$808,MATCH($E15&"|"&$F15&"|"&$G15&"|"&$H15,'Description Library'!$K$6:$K$808,0)),"") | J15: =IFERROR(INDEX('Description Library'!$H$6:$H$808,MATCH($E15&"|"&$F15&"|"&$G15&"|"&$H15,'Description Library'!$K$6:$K$808,0)),"") | L15: =IFERROR(INDEX('Price List Library'!$K$6:$K$437,MATCH(TRIM($H15)&"|"&TRIM($J15),'Price List Library'!$S$6:$S$437,0)),0) -> 0 | M15: =IFERROR(INDEX('Price List Library'!$N$6:$N$437,MATCH(TRIM($H15)&"|"&TRIM($J15),'Price List Library'!$S$6:$S$437,0)),0) -> 0 | N15: =L15+M15 -> 0 | O15: =IF($K15="","",$K15*$N15) | P15: =IFERROR(INDEX('Price List Library'!$P$6:$P$437,MATCH(TRIM($H15)&"|"&TRIM($J15),'Price List Library'!$S$6:$S$437,0)),"") | R15: =IFERROR(VLOOKUP($E15,_MAPSEC,2,0),"_NONE") -> _NONE | S15: =IFERROR(VLOOKUP($E15&"|"&$F15,_MAPSUB,2,0),"_NONE") -> _NONE | T15: =IFERROR(VLOOKUP($E15&"|"&$F15&"|"&$G15,_MAPSE,2,0),"_NONE") -> _NONE
