Workbook

Sheet Element Library
A1: QS ELEMENT LIBRARY — SECTION / SUB SECTION / SUB ELEMENT
A2: Standard coding list for BoQ takeoff — Structure, Architecture, MEP & External Works. Aligned to the project Budget Code framework.
A3: Use with the Entry Template sheet (dependent drop-downs). Typical Unit is a guide — confirm against drawings and specification.
A5: No. | B5: Discipline | C5: Budget Code | D5: Section | E5: Sub Section | F5: Sub Element | G5: Typical Unit | H5: Key
A6: 1 | B6: Civil and Structure | C6: A.04 | D6: Sub Structure | E6: Site Preparation & Earthwork | F6: Site Clearing | G6: m2 | H6: Sub Structure|Site Preparation & Earthwork|Site Clearing
A7: 2 | B7: Civil and Structure | C7: A.04 | D7: Sub Structure | E7: Site Preparation & Earthwork | F7: Excavation | G7: m3 | H7: Sub Structure|Site Preparation & Earthwork|Excavation
A8: 3 | B8: Civil and Structure | C8: A.04 | D8: Sub Structure | E8: Site Preparation & Earthwork | F8: Backfill | G8: m3 | H8: Sub Structure|Site Preparation & Earthwork|Backfill
A9: 4 | B9: Civil and Structure | C9: A.04 | D9: Sub Structure | E9: Site Preparation & Earthwork | F9: Soil Disposal | G9: m3 | H9: Sub Structure|Site Preparation & Earthwork|Soil Disposal
A10: 5 | B10: Civil and Structure | C10: A.04 | D10: Sub Structure | E10: Site Preparation & Earthwork | F10: Compaction | G10: m2 | H10: Sub Structure|Site Preparation & Earthwork|Compaction
A11: 6 | B11: Civil and Structure | C11: A.04 | D11: Sub Structure | E11: Site Preparation & Earthwork | F11: Dewatering | G11: Lot | H11: Sub Structure|Site Preparation & Earthwork|Dewatering
A12: 7 | B12: Civil and Structure | C12: A.04 | D12: Sub Structure | E12: Site Preparation & Earthwork | F12: Levelling & Setting Out | G12: m2 | H12: Sub Structure|Site Preparation & Earthwork|Levelling & Setting Out
A13: 8 | B13: Civil and Structure | C13: B.02 | D13: Sub Structure | E13: Shoring & Sheet Pile | F13: Sheet Pile Supply | G13: m2 | H13: Sub Structure|Shoring & Sheet Pile|Sheet Pile Supply
A14: 9 | B14: Civil and Structure | C14: B.02 | D14: Sub Structure | E14: Shoring & Sheet Pile | F14: Sheet Pile Driving | G14: m2 | H14: Sub Structure|Shoring & Sheet Pile|Sheet Pile Driving
A15: 10 | B15: Civil and Structure | C15: B.02 | D15: Sub Structure | E15: Shoring & Sheet Pile | F15: Sheet Pile Extraction | G15: m2 | H15: Sub Structure|Shoring & Sheet Pile|Sheet Pile Extraction
A16: 11 | B16: Civil and Structure | C16: B.02 | D16: Sub Structure | E16: Shoring & Sheet Pile | F16: Strut & Waler | G16: kg | H16: Sub Structure|Shoring & Sheet Pile|Strut & Waler
A17: 12 | B17: Civil and Structure | C17: B.02 | D17: Sub Structure | E17: Shoring & Sheet Pile | F17: Ground Anchor | G17: Nos | H17: Sub Structure|Shoring & Sheet Pile|Ground Anchor
... A523: 518 | B523: External Works | C523: G.05 | D523: External Work | E523: External fixture | F523: Playground / sport court | G523: Lot | H523: External Work|External fixture|Playground / sport court

Sheet Validation Lists
A1: VALIDATION SOURCE LISTS — do not delete (drives the drop-downs on Entry Template)
A2: Rows/columns here are referenced by defined names. Add new items to Element Library, then extend these lists.
A4: Section | C4: Section | D4: Range | F4: Section|SubSection | G4: Range | J4: SEC01 | K4: SEC02 | L4: SEC03 | M4: SEC04 | N4: SEC05 | O4: SEC06 | P4: SEC07 | Q4: SEC08 | R4: SEC09 | S4: SEC10 | T4: SEC11 | U4: SEC12 | V4: SEC13 | W4: SEC14 | X4: SEC15 | Y4: SEC16 | Z4: SEC17 | AA4: SEC18 | AB4: SEC19 | AC4: SEC20 | AD4: SEC21 | AE4: SEC22 | AF4: SEC23 | AG4: SEC24 | AH4: SEC25 | AI4: SEC26 | AJ4: SEC27 | AK4: SEC28 | AL4: SEC29 | AM4: SUB001 | AN4: SUB002 | AO4: SUB003 | AP4: SUB004 | AQ4: SUB005 | AR4: SUB006 | AS4: SUB007 | AT4: SUB008 | AU4: SUB009 | AV4: SUB010 | AW4: SUB011 | AX4: SUB012 | AY4: SUB013 | AZ4: SUB014 | BA4: SUB015 | BB4: SUB016 | BC4: SUB017 | BD4: SUB018 | BE4: SUB019 | BF4: SUB020 | BG4: SUB021 | BH4: SUB022 | BI4: SUB023 | BJ4: SUB024 | BK4: SUB025 | BL4: SUB026 | BM4: SUB027 | BN4: SUB028 | BO4: SUB029 | BP4: SUB030 | BQ4: SUB031 | BR4: SUB032 | BS4: SUB033 | BT4: SUB034 | BU4: SUB035 | BV4: SUB036 | BW4: SUB037 | BX4: SUB038 | BY4: SUB039 | BZ4: SUB040 | CA4: SUB041 | CB4: SUB042 | CC4: SUB043 | CD4: SUB044 | CE4: SUB045 | CF4: SUB046 | CG4: SUB047 | CH4: SUB048 | CI4: SUB049 | CJ4: SUB050 | CK4: SUB051 | CL4: SUB052 | CM4: SUB053 | CN4: SUB054 | CO4: SUB055 | CP4: SUB056 | CQ4: SUB057 | CR4: SUB058 | CS4: SUB059 | CT4: SUB060 | CU4: SUB061 | CV4: SUB062 | CW4: SUB063 | CX4: SUB064 | CY4: SUB065 | CZ4: SUB066 | DA4: SUB067 | DB4: SUB068 | DC4: SUB069 | DD4: SUB070 | DE4: SUB071 | DF4: SUB072 | DG4: SUB073 | DH4: SUB074 | DI4: SUB075 | DJ4: SUB076 | DK4: SUB077 | DL4: SUB078 | DM4: SUB079 | DN4: SUB080 | DO4: SUB081 | DP4: SUB082 | DQ4: SUB083 | DR4: SUB084 | DS4: SUB085 | DT4: SUB086 | DU4: SUB087 | DV4: SUB088 | DW4: SUB089 | DX4: SUB090 | DY4: SUB091 | DZ4: SUB092 | EA4: SUB093 | EB4: SUB094 | EC4: SUB095 | ED4: SUB096 | EE4: SUB097 | EF4: SUB098 | EG4: SUB099 | EH4: SUB100 | EI4: SUB101 | EJ4: SUB102 | EK4: SUB103 | EL4: SUB104 | EM4: SUB105 | EN4: SUB106 | EO4: SUB107 | EP4: SUB108 | EQ4: SUB109 | ER4: SUB110 | ES4: SUB111 | ET4: SUB112 | EU4: SUB113 | EV4: SUB114 | EW4: SUB115 | EX4: SUB116 | EY4: SUB117 | EZ4: SUB118 | FA4: SUB119 | FB4: SUB120 | FC4: SUB121 | FD4: SUB122
A5: Sub Structure | C5: Sub Structure | D5: SEC01 | F5: Sub Structure|Site Preparation & Earthwork | G5: SUB001 | J5: Site Preparation & Earthwork | K5: Structural Column | L5: Hollow clay brick | M5: Plastering | N5: Steel Door | O5: Glass Window | P5: Screeding | Q5: Soffit finishes | R5: Stair & Ramp finishes | S5: Roof covering | T5: Hollow clay brick | U5: Wood door | V5: Gas installation | W5: Plastering | X5: Screeding | Y5: Suspended ceiling | Z5: General Fitting | AA5: Sanitary ware | AB5: Split unit system | AC5: Ventilation fan | AD5: Ductwork | AE5: Main distribution | AF5: Fire alarm system | AG5: Water supply | AH5: Hydrant & hose reel | AI5: Renewable & specialist | AJ5: Lift | AK5: Testing & Commissioning | AL5: Site preparation | AM5: Site Clearing | AN5: Sheet Pile Supply | AO5: Bored Pile Boring | AP5: Pile Supply | AQ5: Earthwork | AR5: Earthwork | AS5: Earthwork | AT5: Base Preparation | AU5: Earthwork | AV5: Earthwork | AW5: Earthwork | AX5: Earthwork | AY5: Concrete | AZ5: Concrete | BA5: Concrete | BB5: Concrete | BC5: Concrete | BD5: Concrete | BE5: Concrete | BF5: Concrete | BG5: Steel Section / Beam | BH5: Truss | BI5: Concrete Testing | BJ5: Hollow clay brick 100mm Thk. | BK5: Concrete block 100mm Thk. | BL5: AAC block 100mm Thk. | BM5: Precast wall panel | BN5: External façade | BO5: Plastering | BP5: Painting | BQ5: Wall tiling | BR5: Expansion joint | BS5: Steel Door | BT5: Aluminium door | BU5: Frameless glass door | BV5: Rolling shutter | BW5: Lockset | BX5: Glass Window | BY5: Aluminium louver | BZ5: Window fence / grille | CA5: Screeding | CB5: Floor tiling | CC5: Waterproofing | CD5: Plastering | CE5: Stair tread & riser finish | CF5: Handrail | CG5: Metal roof sheet | CH5: Waterproofing membrane | CI5: Gutter | CJ5: Skylight | CK5: Hollow clay brick 100mm Thk. | CL5: Gypsum board partition | CM5: Frameless glass partition | CN5: Toilet cubicle | CO5: Handrail | CP5: Wood door | CQ5: PVC door | CR5: Steel Door | CS5: Aluminium door | CT5: Lockset | CU5: Interior glass window | CV5: LPG gas system | CW5: Plastering | CX5: Painting | CY5: Wall tiling | CZ5: Wall cladding | DA5: Skirting | DB5: Screeding | DC5: Floor tiling | DD5: Marble on staircase | DE5: Vinyl flooring | DF5: Waterproofing | DG5: Skirting | DH5: Suspended ceiling | DI5: Acoustic ceiling tile | DJ5: Aluminium strip ceiling | DK5: Ceiling access panel | DL5: Toilet accessories | DM5: Kitchen cabinet | DN5: Laboratory bench | DO5: Signage | DP5: Water closet | DQ5: Tap / faucet | DR5: Toilet paper holder | DS5: Wall mounted split unit | DT5: VRF indoor unit | DU5: Chiller | DV5: Refrigerant piping | DW5: Toilet exhaust fan | DX5: Kitchen hood | DY5: GI ductwork | DZ5: Supply air diffuser | EA5: Volume control damper | EB5: Main switchboard (MSB) | EC5: Power cable | ED5: Socket outlet | EE5: Interior luminaire | EF5: Earthing system | EG5: Generator set | EH5: Fire alarm control panel | EI5: CCTV camera | EJ5: Structured cabling outlet | EK5: Public address (PA) system | EL5: BMS control panel | EM5: Cold water piping | EN5: Water tank | EO5: Soil pipe | EP5: Septic tank (precast) | EQ5: Fire hydrant | ER5: Sprinkler head | ES5: Fire pump set | ET5: Fire extinguisher | EU5: Solar PV system | EV5: Passenger lift | EW5: Escalator | EX5: Lift shaft ladder | EY5: Testing & commissioning | EZ5: Site clearing | FA5: Concrete paving | FB5: Top soil | FC5: Boundary fence | FD5: Flag pole
A6: Super Structure | C6: Super Structure | D6: SEC02 | F6: Sub Structure|Shoring & Sheet Pile | G6: SUB002 | J6: Shoring & Sheet Pile | K6: Structural Beam | L6: Concrete block | M6: Painting | N6: Aluminium door | O6: Aluminium louver | P6: Floor tiling | R6: Handrail & Balustrade | S6: Roof waterproofing & insulation | T6: Dry wall partition | U6: PVC door | W6: Painting | X6: Floor tiling | Y6: Acoustic ceiling | Z6: Kitchen Fitting | AA6: Sanitary fitting | AB6: VRF / VRV system | AC6: Specialist ventilation | AD6: Air terminal | AE6: Cable & containment | AF6: Security system | AG6: Water storage & pump | AH6: Sprinkler system | AJ6: Escalator | AL6: Roads, path, paving | AM6: Excavation | AN6: Sheet Pile Driving | AO6: Concrete | AP6: Pile Driving | AQ6: Base Preparation | AR6: Base Preparation | AS6: Lean Concrete | AT6: Crush Stone | AU6: Base Preparation | AV6: Base Preparation | AW6: Lean Concrete | AX6: Concrete | AY6: Formwork | AZ6: Formwork | BA6: Formwork | BB6: Formwork | BC6: Formwork | BD6: Formwork | BE6: Formwork | BF6: Formwork | BG6: U steel | BH6: Purlin | BI6: Rebar Testing | BJ6: Hollow clay brick 200mm Thk. | BK6: Concrete block 150mm Thk. | BL6: AAC block 150mm Thk. | BM6: Panel jointing & sealant | BN6: Curtain wall | BO6: Skim coat | BP6: Primer coat | BQ6: Stone cladding | BR6: Sealant | BS6: Fire rated steel door | BT6: Aluminium sliding door | BU6: Framed glass door | BV6: Motor & control | BW6: Door closer | BX6: Fixed glass window | BY6: Steel louver | BZ6: Mosquito screen | CA6: Floor hardener | CB6: Anti-slip tile | CC6: Protection screed | CD6: Painting | CE6: Ramp finish | CF6: Balustrade | CG6: Roof tile | CH6: Thermal insulation | CI6: Downpipe | CJ6: Roof access hatch | CK6: Hollow clay brick 200mm Thk. | CL6: Cement board partition | CM6: Framed glass partition | CN6: Urinal divider | CO6: Handrail on staircase | CP6: Solid core wood door | CR6: Fire rated door | CS6: Glass door | CT6: Door closer | CU6: Interior louver | CV6: Laboratory gas outlet | CW6: Skim coat | CX6: Primer coat | CY6: Toilet Wall tile | CZ6: Acoustic panel | DB6: Self-levelling screed | DC6: Toilet Floor tile | DD6: Marble flooring | DE6: Epoxy flooring | DF6: anti termite | DG6: Stair nosing | DH6: Gypsum board ceiling | DI6: Mineral fibre ceiling | DJ6: Metal grid ceiling | DK6: Cornice | DL6: Mirror | DM6: Counter top | DN6: Library shelving | DO6: External round logo | DP6: Wash basin | DQ6: Flush valve | DR6: Soap dispenser | DS6: Cassette type unit | DT6: VRF outdoor unit | DU6: Air handling unit (AHU) | DV6: Chilled water piping | DW6: Kitchen exhaust fan | DX6: Smoke extraction fan | DY6: Flexible duct | DZ6: Return air grille | EA6: Fire damper | EB6: Sub-distribution board (DB) | EC6: Control cable | ED6: Switch | EE6: Exterior luminaire | EF6: Earth rod & pit | EG6: Automatic transfer switch (ATS) | EH6: Smoke / heat detector | EI6: NVR / recorder | EJ6: Network switch / rack | EK6: Speaker | EL6: Field device & sensor | EM6: Hot water piping | EN6: Transfer pump | EO6: Waste pipe | EP6: Sewage treatment plant (STP) | EQ6: Hose reel | ER6: Sprinkler piping | ES6: Jockey pump | ET6: Fire blanket | EU6: Water treatment plant | EV6: Service / goods lift | EX6: Shaft lighting & socket | EY6: As-built drawing | EZ6: Cut & fill | FA6: Asphalt paving | FB6: Turfing | FC6: Main gate | FD6: Bollard
A7: Exterior Wall and Partition | C7: Exterior Wall and Partition | D7: SEC03 | F7: Sub Structure|Bored Pile | G7: SUB003 | J7: Bored Pile | K7: Structural Slab | L7: AAC block | M7: Wall tiling | N7: Glass door | O7: Window accessories | P7: Waterproofing | S7: Roof drainage | T7: Glass partition | U7: Steel Door | W7: Wall tiling | X7: Stone flooring | Y7: Metal ceiling | Z7: Special purpose Fitting | AA7: Sanitary accessories | AB7: Chilled water system | AD7: Damper & control | AE7: Power & wiring accessories | AF7: Communication system | AG7: Drainage | AH7: Fire pump & tank | AJ7: Lift shaft equipment | AL7: Landscape | AM7: Backfill | AN7: Sheet Pile Extraction | AO7: Rebar | AP7: Pile Splicing | AQ7: Crush Stone | AR7: Crush Stone | AS7: Concrete | AT7: Anti-Termite | AU7: Crush Stone | AV7: Crush Stone | AW7: Concrete | AX7: Formwork | AY7: Rebar | AZ7: Rebar | BA7: Rebar | BB7: Rebar | BC7: Rebar | BD7: Rebar | BE7: Rebar | BF7: Rebar | BG7: Hollow steel tube | BH7: Sag rod | BI7: Non-Destructive Test | BJ7: Hollow clay brick 400mm Thk. | BK7: Concrete block 200mm Thk. | BL7: AAC block 200mm Thk. | BN7: Aluminium composite panel | BO7: Molding / Cornice | BP7: Weather-shield coating | BW7: Hinge | BX7: Sliding glass window | BZ7: Sealant | CD7: Soffit cladding | CE7: Stair nosing | CF7: Guard rail | CG7: Translucent sheet | CH7: Vapour barrier | CI7: Roof drain | CJ7: Roof ladder | CL7: Metal stud framing | CO7: Wall guard rail | CT7: Hinge | CZ7: Wallpaper | DC7: Homogeneous tile | DD7: Granite flooring | DE7: Wooden flooring | DG7: Floor trim / divider | DH7: Cement board ceiling | DK7: Bulkhead | DL7: Counter top | DM7: Sink | DN7: Sport / gym equipment | DO7: Khmer and Chinese text | DP7: Urinal | DQ7: Angle valve | DR7: Grab bar | DS7: Outdoor condensing unit | DT7: Refnet joint | DU7: Fan coil unit (FCU) | DV7: Condensate drain piping | DW7: Car park ventilation fan | DX7: Laboratory fume hood | DY7: Duct insulation | DZ7: Exhaust grille | EA7: Motorized damper | EB7: Busduct / Busway | EC7: Cable tray | ED7: Isolator | EE7: Emergency light | EF7: Lightning air terminal | EG7: UPS | EH7: Manual call point | EI7: Access control door | EJ7: Telephone system | EK7: Bell / clock system | EM7: Pipe insulation | EN7: Booster pump | EO7: Vent pipe | EP7: Sewer connection | EQ7: Landing valve | ER7: Alarm valve set | ES7: Fire water tank | ET7: FM200 / CO2 system | EU7: Swimming pool system | EV7: Firefighting lift | EX7: Machine room equipment | EY7: O&M manual | EZ7: Compaction | FA7: Interlocking paver | FB7: Tree & shrub | FC7: Guard rail | FD7: Bicycle rack
A8: Exterior Wall Finishes | C8: Exterior Wall Finishes | D8: SEC04 | F8: Sub Structure|Driven Pile / Micro Pile | G8: SUB004 | J8: Driven Pile / Micro Pile | K8: Structural Wall | L8: Precast concrete panel | M8: Expansion joint | N8: Rolling shutter | S8: Roof accessories | T8: Toilet cubicle | U8: Aluminium / Glass door | W8: Wall cladding | X8: Resilient flooring | Y8: Ceiling accessories | Z8: Signage | AB8: AC piping & accessories | AE8: Lighting | AF8: Audio visual & school system | AG8: Sewage treatment | AH8: Portable & special suppression | AL8: Fence, railing & wall | AM8: Soil Disposal | AN8: Strut & Waler | AO8: Steel Tie Wire | AP8: Pile Head Cutting | AQ8: Lean Concrete | AR8: Lean Concrete | AS8: Formwork | AT8: Vapour Barrier | AU8: Lean Concrete | AV8: Lean Concrete | AW8: Formwork | AX8: Rebar | AY8: Steel Tie Wire | AZ8: Steel Tie Wire | BA8: Steel Tie Wire | BB8: Steel Tie Wire | BC8: Steel Tie Wire | BD8: Steel Tie Wire | BE8: Steel Tie Wire | BF8: Steel Tie Wire | BG8: Purlin | BH8: Bracing | BI8: Survey & As-Built | BJ8: Hollow clay brick 500mm Thk. | BN8: Louver screen | BW8: Door stopper | BX8: Casement window | BZ8: Window sill | CE8: Tactile paving | CG8: Ridge cap | CH8: Protection screed | CI8: Flashing | CJ8: Lightning terminal base | CL8: Acoustic infill | CT8: Door stopper | CZ8: Mirror | DE8: Carpet | DK8: Ceiling painting | DL8: Locker | DO8: Wayfinding sign | DP8: Shower set | DQ8: Floor drain | DR8: Hand dryer | DU8: Chilled water pump | DV8: Pipe insulation | DW8: Fresh air fan | DY8: Duct support | DZ8: Louver | EA8: Testing & balancing | EB8: Transformer | EC8: Cable trunking | ED8: Wiring point | EE8: Exit sign | EF8: Down conductor | EG8: Fuel tank & piping | EH8: Alarm bell / sounder | EI8: Intercom | EJ8: MATV / TV outlet | EK8: Projector & screen | EM8: Valve & fitting | EN8: Water heater | EO8: Rainwater downpipe | EQ8: Fire riser piping | ER8: Flow switch | ET8: Kitchen suppression system | EU8: Kitchen equipment | EV8: Platform / accessibility lift | EY8: Training | FA8: Kerb | FB8: Planter | FC8: Boundary wall | FD8: Covered walkway
A9: Exterior Door | C9: Exterior Door | D9: SEC05 | F9: Sub Structure|Pile Cap & Stump | G9: SUB005 | J9: Pile Cap & Stump | K9: Structural Staircase | L9: External façade | N9: Door ironmongery | T9: Handrail | U9: Door ironmongery | W9: Skirting | X9: Waterproofing | AE9: Earthing & lightning protection | AF9: Building management | AL9: External fixture | AM9: Compaction | AN9: Ground Anchor | AO9: Steel Round Pipe | AP9: Pile Load Test | AQ9: Concrete | AR9: Concrete | AS9: Rebar | AT9: Lean Concrete | AU9: Concrete | AV9: Concrete | AW9: Rebar | AX9: Steel Tie Wire | AY9: Column Starter Bar | BA9: Post-Tension Strand | BB9: Water Stop | BE9: Water Stop | BG9: Sag rod | BH9: Zinc sheet | BJ9: Hollow clay brick 800mm Thk. | CT9: Panic bar | DE9: Raised floor | DK9: Curtain box | DL9: Shelving | DO9: Room sign | DP9: Squat pan | DQ9: Floor trap | DU9: Cooling tower | DV9: Thermostat / control | DW9: Staircase pressurization fan | EB9: Capacitor bank | EC9: Conduit | EE9: Lighting control / sensor | EJ9: WiFi access point | EK9: Classroom AV system | EM9: Water meter | EN9: Level control | EO9: Manhole / inspection chamber | EY9: Spare parts | FA9: Road marking | FB9: Irrigation system | FD9: Guard house
A10: Exterior Window and Louver | C10: Exterior Window and Louver | D10: SEC06 | F10: Sub Structure|Footing / Raft Foundation | G10: SUB006 | J10: Footing / Raft Foundation | K10: Parapet wall & Stiffener Column | U10: Interior window / louver | X10: Floor accessories | AE10: Standby power | AM10: Dewatering | AN10: Guide Wall | AO10: Bentonite / Slurry | AQ10: Formwork | AR10: Formwork | AS10: Steel Tie Wire | AT10: Concrete | AU10: Formwork | AV10: Formwork | AW10: Steel Tie Wire | AX10: Water Stop | AY10: Grouting | BA10: Steel Deck | BG10: Bracing | BH10: Flashing | DL10: Blind & curtain | DO10: Statutory / safety sign | DP10: Sink | DQ10: Clean out | EB10: Metering panel | EC10: Cable ladder | EO10: Grease trap | FA10: Car park | FD10: Playground / sport court
A11: Exterior floor | C11: Exterior floor | D11: SEC07 | F11: Sub Structure|Ground Beam / Tie Beam | G11: SUB007 | J11: Ground Beam / Tie Beam | K11: Lift Core / Shear Core | AM11: Levelling & Setting Out | AO11: Bored Pile Head Cutting | AQ11: Rebar | AR11: Rebar | AS11: Waterproofing | AT11: Formwork | AU11: Rebar | AV11: Rebar | AW11: Water Stop | AX11: Waterproofing | BG11: Base Plate | BH11: Anchor Bolt | DL11: White board
A12: Exterior soffit | C12: Exterior soffit | D12: SEC08 | F12: Sub Structure|Slab on Grade / Ground Slab | G12: SUB008 | J12: Slab on Grade / Ground Slab | K12: Ramp | AO12: Bored Pile Testing | AQ12: Steel Tie Wire | AR12: Steel Tie Wire | AT12: Rebar | AU12: Steel Tie Wire | AV12: Steel Tie Wire | AW12: Waterproofing | AX12: Protection Board | BG12: Steel plate | BH12: Painting / Galvanizing
A13: Exterior Stair Ramp | C13: Exterior Stair Ramp | D13: SEC09 | F13: Sub Structure|Septic tank | G13: SUB009 | J13: Septic tank | K13: Structural Steel | AO13: Bored Pile Coring | AQ13: Water Stop | AR13: Water Stop | AT13: Steel Tie Wire | AU13: Water Stop | AV13: Water Stop | AX13: Drainage Board | BG13: J bolt
A14: Roofing | C14: Roofing | D14: SEC10 | F14: Sub Structure|Water Tank / Sump Pit | G14: SUB010 | J14: Water Tank / Sump Pit | K14: Roof Structure / Truss | AO14: Pile Load Test | AQ14: Waterproofing | AR14: Waterproofing | AT14: Waterproofing | AU14: Waterproofing | AV14: Waterproofing | BG14: Anchor Bolt
A15: Interior Wall and Partition | C15: Interior Wall and Partition | D15: SEC11 | F15: Sub Structure|Lift Pit | G15: SUB011 | J15: Lift Pit | K15: Testing & Quality Control | AO15: Rebar Testing | AQ15: Anti-Termite | AR15: Anti-Termite | AU15: Anti-Termite | AV15: Anti-Termite | BG15: Bolt & Nut
A16: Interior Doors | C16: Interior Doors | D16: SEC12 | F16: Sub Structure|Basement / Retaining Wall | G16: SUB012 | J16: Basement / Retaining Wall | AO16: Concrete Testing | BG16: Welding
A17: Special installation | C17: Special installation | D17: SEC13 | F17: Super Structure|Structural Column | G17: SUB013 | BG17: Painting / Galvanizing
A18: Interior Wall Finishes | C18: Interior Wall Finishes | D18: SEC14 | F18: Super Structure|Structural Beam | G18: SUB014 | BG18: Fire Proofing
A19: Interior Floor Finishes | C19: Interior Floor Finishes | D19: SEC15 | F19: Super Structure|Structural Slab | G19: SUB015
A20: Ceiling Finishes | C20: Ceiling Finishes | D20: SEC16 | F20: Super Structure|Structural Wall | G20: SUB016
A21: Fittings, furnishings and equipment | C21: Fittings, furnishings and equipment | D21: SEC17 | F21: Super Structure|Structural Staircase | G21: SUB017
A22: Sanitary Installations | C22: Sanitary Installations | D22: SEC18 | F22: Super Structure|Parapet wall & Stiffener Column | G22: SUB018
A23: AIR-CONDITIONAL SYSTEM | C23: AIR-CONDITIONAL SYSTEM | D23: SEC19 | F23: Super Structure|Lift Core / Shear Core | G23: SUB019
A24: MECHANICAL VENTILATION SYSTEM | C24: MECHANICAL VENTILATION SYSTEM | D24: SEC20 | F24: Super Structure|Ramp | G24: SUB020
A25: MV DISTRIBUTION SYSTEM | C25: MV DISTRIBUTION SYSTEM | D25: SEC21 | F25: Super Structure|Structural Steel | G25: SUB021
A26: ELECTRICAL SYSTEM | C26: ELECTRICAL SYSTEM | D26: SEC22 | F26: Super Structure|Roof Structure / Truss | G26: SUB022
A27: ELV INSTALLATION | C27: ELV INSTALLATION | D27: SEC23 | F27: Super Structure|Testing & Quality Control | G27: SUB023
A28: PLUMBING SYSTEM | C28: PLUMBING SYSTEM | D28: SEC24 | F28: Exterior Wall and Partition|Hollow clay brick | G28: SUB024
A29: FIRE FIGHTING SYSTEM | C29: FIRE FIGHTING SYSTEM | D29: SEC25 | F29: Exterior Wall and Partition|Concrete block | G29: SUB025
A30: Specialist Installations | C30: Specialist Installations | D30: SEC26 | F30: Exterior Wall and Partition|AAC block | G30: SUB026
... A33: External Work | C33: External Work | D33: SEC29 | F33: Exterior Wall Finishes|Plastering | G33: SUB029
F34: Exterior Wall Finishes|Painting | G34: SUB030
F35: Exterior Wall Finishes|Wall tiling | G35: SUB031
F36: Exterior Wall Finishes|Expansion joint | G36: SUB032
F37: Exterior Door|Steel Door | G37: SUB033
F38: Exterior Door|Aluminium door | G38: SUB034
F39: Exterior Door|Glass door | G39: SUB035
F40: Exterior Door|Rolling shutter | G40: SUB036
F41: Exterior Door|Door ironmongery | G41: SUB037
F42: Exterior Window and Louver|Glass Window | G42: SUB038
F43: Exterior Window and Louver|Aluminium louver | G43: SUB039
...

Sheet Entry Template
A1: BoQ TAKE-OFF ENTRY TEMPLATE — with dependent drop-downs
A2: Pick Section → Sub Section → Sub Element in order. Budget Code and Unit fill automatically from the Element Library.
A4: No. | B4: Discipline | C4: Section | D4: Sub Section | E4: Sub Element | F4: Budget Code | G4: Unit | H4: Material Type / Description | I4: Quantity | J4: Remark | K4: h1 | L4: h2
A5: =IF($C5="","",ROW()-4) | F5: =IFERROR(INDEX('Element Library'!$C:$C,MATCH($C5&"|"&$D5&"|"&$E5,'Element Library'!$H:$H,0)),"") | G5: =IFERROR(INDEX('Element Library'!$G:$G,MATCH($C5&"|"&$D5&"|"&$E5,'Element Library'!$H:$H,0)),"") | K5: =IFERROR(VLOOKUP($C5,MAP_SEC,2,0),"L_SECTION") -> L_SECTION | L5: =IFERROR(VLOOKUP($C5&"|"&$D5,MAP_SUB,2,0),"L_SECTION") -> L_SECTION
A6: =IF($C6="","",ROW()-4) | F6: =IFERROR(INDEX('Element Library'!$C:$C,MATCH($C6&"|"&$D6&"|"&$E6,'Element Library'!$H:$H,0)),"") | G6: =IFERROR(INDEX('Element Library'!$G:$G,MATCH($C6&"|"&$D6&"|"&$E6,'Element Library'!$H:$H,0)),"") | K6: =IFERROR(VLOOKUP($C6,MAP_SEC,2,0),"L_SECTION") -> L_SECTION | L6: =IFERROR(VLOOKUP($C6&"|"&$D6,MAP_SUB,2,0),"L_SECTION") -> L_SECTION
A7: =IF($C7="","",ROW()-4) | F7: =IFERROR(INDEX('Element Library'!$C:$C,MATCH($C7&"|"&$D7&"|"&$E7,'Element Library'!$H:$H,0)),"") | G7: =IFERROR(INDEX('Element Library'!$G:$G,MATCH($C7&"|"&$D7&"|"&$E7,'Element Library'!$H:$H,0)),"") | K7: =IFERROR(VLOOKUP($C7,MAP_SEC,2,0),"L_SECTION") -> L_SECTION | L7: =IFERROR(VLOOKUP($C7&"|"&$D7,MAP_SUB,2,0),"L_SECTION") -> L_SECTION
A8: =IF($C8="","",ROW()-4) | F8: =IFERROR(INDEX('Element Library'!$C:$C,MATCH($C8&"|"&$D8&"|"&$E8,'Element Library'!$H:$H,0)),"") | G8: =IFERROR(INDEX('Element Library'!$G:$G,MATCH($C8&"|"&$D8&"|"&$E8,'Element Library'!$H:$H,0)),"") | K8: =IFERROR(VLOOKUP($C8,MAP_SEC,2,0),"L_SECTION") -> L_SECTION | L8: =IFERROR(VLOOKUP($C8&"|"&$D8,MAP_SUB,2,0),"L_SECTION") -> L_SECTION
A9: =IF($C9="","",ROW()-4) | F9: =IFERROR(INDEX('Element Library'!$C:$C,MATCH($C9&"|"&$D9&"|"&$E9,'Element Library'!$H:$H,0)),"") | G9: =IFERROR(INDEX('Element Library'!$G:$G,MATCH($C9&"|"&$D9&"|"&$E9,'Element Library'!$H:$H,0)),"") | K9: =IFERROR(VLOOKUP($C9,MAP_SEC,2,0),"L_SECTION") -> L_SECTION | L9: =IFERROR(VLOOKUP($C9&"|"&$D9,MAP_SUB,2,0),"L_SECTION") -> L_SECTION
A10: =IF($C10="","",ROW()-4) | F10: =IFERROR(INDEX('Element Library'!$C:$C,MATCH($C10&"|"&$D10&"|"&$E10,'Element Library'!$H:$H,0)),"") | G10: =IFERROR(INDEX('Element Library'!$G:$G,MATCH($C10&"|"&$D10&"|"&$E10,'Element Library'!$H:$H,0)),"") | K10: =IFERROR(VLOOKUP($C10,MAP_SEC,2,0),"L_SECTION") -> L_SECTION | L10: =IFERROR(VLOOKUP($C10&"|"&$D10,MAP_SUB,2,0),"L_SECTION") -> L_SECTION
A11: =IF($C11="","",ROW()-4) | F11: =IFERROR(INDEX('Element Library'!$C:$C,MATCH($C11&"|"&$D11&"|"&$E11,'Element Library'!$H:$H,0)),"") | G11: =IFERROR(INDEX('Element Library'!$G:$G,MATCH($C11&"|"&$D11&"|"&$E11,'Element Library'!$H:$H,0)),"") | K11: =IFERROR(VLOOKUP($C11,MAP_SEC,2,0),"L_SECTION") -> L_SECTION | L11: =IFERROR(VLOOKUP($C11&"|"&$D11,MAP_SUB,2,0),"L_SECTION") -> L_SECTION
A12: =IF($C12="","",ROW()-4) | F12: =IFERROR(INDEX('Element Library'!$C:$C,MATCH($C12&"|"&$D12&"|"&$E12,'Element Library'!$H:$H,0)),"") | G12: =IFERROR(INDEX('Element Library'!$G:$G,MATCH($C12&"|"&$D12&"|"&$E12,'Element Library'!$H:$H,0)),"") | K12: =IFERROR(VLOOKUP($C12,MAP_SEC,2,0),"L_SECTION") -> L_SECTION | L12: =IFERROR(VLOOKUP($C12&"|"&$D12,MAP_SUB,2,0),"L_SECTION") -> L_SECTION
A13: =IF($C13="","",ROW()-4) | F13: =IFERROR(INDEX('Element Library'!$C:$C,MATCH($C13&"|"&$D13&"|"&$E13,'Element Library'!$H:$H,0)),"") | G13: =IFERROR(INDEX('Element Library'!$G:$G,MATCH($C13&"|"&$D13&"|"&$E13,'Element Library'!$H:$H,0)),"") | K13: =IFERROR(VLOOKUP($C13,MAP_SEC,2,0),"L_SECTION") -> L_SECTION | L13: =IFERROR(VLOOKUP($C13&"|"&$D13,MAP_SUB,2,0),"L_SECTION") -> L_SECTION
A14: =IF($C14="","",ROW()-4) | F14: =IFERROR(INDEX('Element Library'!$C:$C,MATCH($C14&"|"&$D14&"|"&$E14,'Element Library'!$H:$H,0)),"") | G14: =IFERROR(INDEX('Element Library'!$G:$G,MATCH($C14&"|"&$D14&"|"&$E14,'Element Library'!$H:$H,0)),"") | K14: =IFERROR(VLOOKUP($C14,MAP_SEC,2,0),"L_SECTION") -> L_SECTION | L14: =IFERROR(VLOOKUP($C14&"|"&$D14,MAP_SUB,2,0),"L_SECTION") -> L_SECTION
A15: =IF($C15="","",ROW()-4) | F15: =IFERROR(INDEX('Element Library'!$C:$C,MATCH($C15&"|"&$D15&"|"&$E15,'Element Library'!$H:$H,0)),"") | G15: =IFERROR(INDEX('Element Library'!$G:$G,MATCH($C15&"|"&$D15&"|"&$E15,'Element Library'!$H:$H,0)),"") | K15: =IFERROR(VLOOKUP($C15,MAP_SEC,2,0),"L_SECTION") -> L_SECTION | L15: =IFERROR(VLOOKUP($C15&"|"&$D15,MAP_SUB,2,0),"L_SECTION") -> L_SECTION
A16: =IF($C16="","",ROW()-4) | F16: =IFERROR(INDEX('Element Library'!$C:$C,MATCH($C16&"|"&$D16&"|"&$E16,'Element Library'!$H:$H,0)),"") | G16: =IFERROR(INDEX('Element Library'!$G:$G,MATCH($C16&"|"&$D16&"|"&$E16,'Element Library'!$H:$H,0)),"") | K16: =IFERROR(VLOOKUP($C16,MAP_SEC,2,0),"L_SECTION") -> L_SECTION | L16: =IFERROR(VLOOKUP($C16&"|"&$D16,MAP_SUB,2,0),"L_SECTION") -> L_SECTION
... A204: =IF($C204="","",ROW()-4) | F204: =IFERROR(INDEX('Element Library'!$C:$C,MATCH($C204&"|"&$D204&"|"&$E204,'Element Library'!$H:$H,0)),"") | G204: =IFERROR(INDEX('Element Library'!$G:$G,MATCH($C204&"|"&$D204&"|"&$E204,'Element Library'!$H:$H,0)),"") | K204: =IFERROR(VLOOKUP($C204,MAP_SEC,2,0),"L_SECTION") -> L_SECTION | L204: =IFERROR(VLOOKUP($C204&"|"&$D204,MAP_SUB,2,0),"L_SECTION") -> L_SECTION

Sheet Naming Standard
A1: NAMING STANDARD & DUPLICATE WARNING
A2: Inconsistent spelling splits your SUMIFS roll-ups. These variants were found in the current project file — standardise on the left column.
A4: Use this (standard) | B4: Do NOT use (variant found) | C4: Why it matters
A5: Interior Wall Finishes | B5: Internal Wall Finishes | C5: Two spellings = two separate D.01 groups in the BoQ
A6: Interior Floor Finishes | B6: Internal Floor Finishes | C6: Two spellings = two separate D.02 groups
A7: Ceiling Finishes | B7: Ceiling Finshes | C7: Typo in current file — breaks lookup against Budget Code list
A8: Exterior Wall and Partition | B8: External Wall and Partition | C8: Budget Code C.01 uses "Exterior"
A9: Exterior Window and Louver | B9: External Windows and Louvers | C9: Budget Code C.04 wording
A10: Interior Doors | B10: Interior Door | C10: Budget Code C.10 wording
A11: Handrail | B11: Handrail on staircase | C11: Keep Sub Section = Handrail; put location in Sub Element
A12: (no trailing spaces) | B12: "Formwork " / "Marble on staircase " | C12: Trailing spaces silently zero-out SUMIFS — always TRIM
A14: RULES OF USE
A15: 1. Section = the Budget Code element (e.g. Interior Wall Finishes). One Section maps to exactly one Budget Code.
A16: 2. Sub Section = the work type / trade package (e.g. Plastering, Hollow clay brick, Glass Window, Fire alarm system).
A17: 3. Sub Element = the priced specification detail (e.g. Hollow clay brick 200mm Thk., Smoke detector). This is what carries the rate.
A18: 4. Structure follows a different pattern: Sub Section = structural element (Structural Beam), Sub Element = work type (Concrete, Formwork, Rebar).
A19: 5. Never invent a new Section — if it is missing, add it to the Budget Code master first, then to this library.
A20: 6. Keep one spelling forever. Copy from this library; do not retype.
A21: 7. Typical Unit is a default, not a rule — a door may be Nos or m2 depending on the specification.
